2025-07-05 14:51:52,926 INFO    MainThread:36952 [wandb_setup.py:_flush():80] Current SDK version is 0.21.0
2025-07-05 14:51:52,926 INFO    MainThread:36952 [wandb_setup.py:_flush():80] Configure stats pid to 36952
2025-07-05 14:51:52,926 INFO    MainThread:36952 [wandb_setup.py:_flush():80] Loading settings from C:\Users\Alex\.config\wandb\settings
2025-07-05 14:51:52,926 INFO    MainThread:36952 [wandb_setup.py:_flush():80] Loading settings from C:\Users\Alex\PycharmProjects\dish_detect\wandb\settings
2025-07-05 14:51:52,926 INFO    MainThread:36952 [wandb_setup.py:_flush():80] Loading settings from environment variables
2025-07-05 14:51:52,926 INFO    MainThread:36952 [wandb_init.py:setup_run_log_directory():703] Logging user logs to C:\Users\Alex\PycharmProjects\dish_detect\wandb\run-20250705_145152-x7n7o4t8\logs\debug.log
2025-07-05 14:51:52,928 INFO    MainThread:36952 [wandb_init.py:setup_run_log_directory():704] Logging internal logs to C:\Users\Alex\PycharmProjects\dish_detect\wandb\run-20250705_145152-x7n7o4t8\logs\debug-internal.log
2025-07-05 14:51:52,928 INFO    MainThread:36952 [wandb_init.py:init():830] calling init triggers
2025-07-05 14:51:52,928 INFO    MainThread:36952 [wandb_init.py:init():835] wandb.init called with sweep_config: {}
config: {'epochs': 2, 'batch_size': 16, 'img_size': 640, 'learning_rate': 0.01, 'lr_final': 0.01, 'momentum': 0.937, 'weight_decay': 0.0005, 'warmup_epochs': 3, 'warmup_momentum': 0.8, 'warmup_bias_lr': 0.1, 'box_loss_gain': 7.5, 'cls_loss_gain': 0.5, 'dfl_loss_gain': 1.5, 'optimizer': 'SGD', 'multi_scale': True, 'dropout': 0.0, 'cos_lr': False, 'close_mosaic': 10, 'copy_paste': 0.0, 'auto_augment': 'randaugment', 'erasing': 0.4, '_wandb': {}}
2025-07-05 14:51:52,929 INFO    MainThread:36952 [wandb_init.py:init():871] starting backend
2025-07-05 14:51:54,025 INFO    MainThread:36952 [wandb_init.py:init():874] sending inform_init request
2025-07-05 14:51:54,125 INFO    MainThread:36952 [wandb_init.py:init():882] backend started and connected
2025-07-05 14:51:54,127 INFO    MainThread:36952 [wandb_init.py:init():953] updated telemetry
2025-07-05 14:51:54,129 INFO    MainThread:36952 [wandb_init.py:init():977] communicating run to backend with 90.0 second timeout
2025-07-05 14:51:56,255 INFO    MainThread:36952 [wandb_init.py:init():1029] starting run threads in backend
2025-07-05 14:51:56,444 INFO    MainThread:36952 [wandb_run.py:_console_start():2458] atexit reg
2025-07-05 14:51:56,444 INFO    MainThread:36952 [wandb_run.py:_redirect():2306] redirect: wrap_raw
2025-07-05 14:51:56,444 INFO    MainThread:36952 [wandb_run.py:_redirect():2375] Wrapping output streams.
2025-07-05 14:51:56,444 INFO    MainThread:36952 [wandb_run.py:_redirect():2398] Redirects installed.
2025-07-05 14:51:56,447 INFO    MainThread:36952 [wandb_init.py:init():1075] run started, returning control to user process
2025-07-05 14:54:21,309 WARNING MsgRouterThr:36952 [router.py:message_loop():63] [no run ID] message_loop has been closed
Traceback (most recent call last):
  File "C:\Users\Alex\anaconda3\envs\fd_env\lib\site-packages\wandb\sdk\lib\sock_client.py", line 204, in _read_packet_bytes
    data = self._sock.recv(self._bufsize)
ConnectionResetError: [WinError 10054] Удаленный хост принудительно разорвал существующее подключение

The above exception was the direct cause of the following exception:

Traceback (most recent call last):
  File "C:\Users\Alex\anaconda3\envs\fd_env\lib\site-packages\wandb\sdk\interface\router_sock.py", line 27, in _read_message
    return self._sock_client.read_server_response(timeout=1)
  File "C:\Users\Alex\anaconda3\envs\fd_env\lib\site-packages\wandb\sdk\lib\sock_client.py", line 231, in read_server_response
    data = self._read_packet_bytes(timeout=timeout)
  File "C:\Users\Alex\anaconda3\envs\fd_env\lib\site-packages\wandb\sdk\lib\sock_client.py", line 208, in _read_packet_bytes
    raise SockClientClosedError from e
wandb.sdk.lib.sock_client.SockClientClosedError

The above exception was the direct cause of the following exception:

Traceback (most recent call last):
  File "C:\Users\Alex\anaconda3\envs\fd_env\lib\site-packages\wandb\sdk\interface\router.py", line 56, in message_loop
    msg = self._read_message()
  File "C:\Users\Alex\anaconda3\envs\fd_env\lib\site-packages\wandb\sdk\interface\router_sock.py", line 29, in _read_message
    raise MessageRouterClosedError from e
wandb.sdk.interface.router.MessageRouterClosedError
2025-07-05 14:54:21,405 INFO    MsgRouterThr:36952 [mailbox.py:close():129] [no run ID] Closing mailbox, abandoning 1 handles.
2025-07-05 14:54:25,448 ERROR   MainThread:36952 [redirect.py:_on_write():664] [all runs] error in stdout callback
Traceback (most recent call last):
  File "C:\Users\Alex\anaconda3\envs\fd_env\lib\site-packages\wandb\sdk\lib\redirect.py", line 662, in _on_write
    cb(written_data)
  File "C:\Users\Alex\anaconda3\envs\fd_env\lib\site-packages\wandb\sdk\wandb_run.py", line 2379, in <lambda>
    lambda data: self._console_raw_callback("stdout", data),
  File "C:\Users\Alex\anaconda3\envs\fd_env\lib\site-packages\wandb\sdk\wandb_run.py", line 398, in wrapper
    return func(self, *args, **kwargs)
  File "C:\Users\Alex\anaconda3\envs\fd_env\lib\site-packages\wandb\sdk\wandb_run.py", line 456, in wrapper_fn
    return func(self, *args, **kwargs)
  File "C:\Users\Alex\anaconda3\envs\fd_env\lib\site-packages\wandb\sdk\wandb_run.py", line 1566, in _console_raw_callback
    self._backend.interface.publish_output_raw(name, data)
  File "C:\Users\Alex\anaconda3\envs\fd_env\lib\site-packages\wandb\sdk\interface\interface.py", line 771, in publish_output_raw
    self._publish_output_raw(o)
  File "C:\Users\Alex\anaconda3\envs\fd_env\lib\site-packages\wandb\sdk\interface\interface_shared.py", line 38, in _publish_output_raw
    self._publish(rec)
  File "C:\Users\Alex\anaconda3\envs\fd_env\lib\site-packages\wandb\sdk\interface\interface_sock.py", line 39, in _publish
    self._sock_client.send_record_publish(record)
  File "C:\Users\Alex\anaconda3\envs\fd_env\lib\site-packages\wandb\sdk\lib\sock_client.py", line 170, in send_record_publish
    self.send_server_request(server_req)
  File "C:\Users\Alex\anaconda3\envs\fd_env\lib\site-packages\wandb\sdk\lib\sock_client.py", line 150, in send_server_request
    self._send_message(msg)
  File "C:\Users\Alex\anaconda3\envs\fd_env\lib\site-packages\wandb\sdk\lib\sock_client.py", line 147, in _send_message
    self._sendall_with_error_handle(header + data)
  File "C:\Users\Alex\anaconda3\envs\fd_env\lib\site-packages\wandb\sdk\lib\sock_client.py", line 126, in _sendall_with_error_handle
    sent = self._sock.send(data)
ConnectionResetError: [WinError 10054] Удаленный хост принудительно разорвал существующее подключение
2025-07-05 14:54:26,934 ERROR   MainThread:36952 [redirect.py:_on_write():664] [all runs] error in stdout callback
Traceback (most recent call last):
  File "C:\Users\Alex\anaconda3\envs\fd_env\lib\site-packages\wandb\sdk\lib\redirect.py", line 662, in _on_write
    cb(written_data)
  File "C:\Users\Alex\anaconda3\envs\fd_env\lib\site-packages\wandb\sdk\wandb_run.py", line 2379, in <lambda>
    lambda data: self._console_raw_callback("stdout", data),
  File "C:\Users\Alex\anaconda3\envs\fd_env\lib\site-packages\wandb\sdk\wandb_run.py", line 398, in wrapper
    return func(self, *args, **kwargs)
  File "C:\Users\Alex\anaconda3\envs\fd_env\lib\site-packages\wandb\sdk\wandb_run.py", line 456, in wrapper_fn
    return func(self, *args, **kwargs)
  File "C:\Users\Alex\anaconda3\envs\fd_env\lib\site-packages\wandb\sdk\wandb_run.py", line 1566, in _console_raw_callback
    self._backend.interface.publish_output_raw(name, data)
  File "C:\Users\Alex\anaconda3\envs\fd_env\lib\site-packages\wandb\sdk\interface\interface.py", line 771, in publish_output_raw
    self._publish_output_raw(o)
  File "C:\Users\Alex\anaconda3\envs\fd_env\lib\site-packages\wandb\sdk\interface\interface_shared.py", line 38, in _publish_output_raw
    self._publish(rec)
  File "C:\Users\Alex\anaconda3\envs\fd_env\lib\site-packages\wandb\sdk\interface\interface_sock.py", line 39, in _publish
    self._sock_client.send_record_publish(record)
  File "C:\Users\Alex\anaconda3\envs\fd_env\lib\site-packages\wandb\sdk\lib\sock_client.py", line 170, in send_record_publish
    self.send_server_request(server_req)
  File "C:\Users\Alex\anaconda3\envs\fd_env\lib\site-packages\wandb\sdk\lib\sock_client.py", line 150, in send_server_request
    self._send_message(msg)
  File "C:\Users\Alex\anaconda3\envs\fd_env\lib\site-packages\wandb\sdk\lib\sock_client.py", line 147, in _send_message
    self._sendall_with_error_handle(header + data)
  File "C:\Users\Alex\anaconda3\envs\fd_env\lib\site-packages\wandb\sdk\lib\sock_client.py", line 126, in _sendall_with_error_handle
    sent = self._sock.send(data)
ConnectionResetError: [WinError 10054] Удаленный хост принудительно разорвал существующее подключение
2025-07-05 14:54:26,938 ERROR   MainThread:36952 [redirect.py:_on_write():664] [all runs] error in stdout callback
Traceback (most recent call last):
  File "C:\Users\Alex\anaconda3\envs\fd_env\lib\site-packages\wandb\sdk\lib\redirect.py", line 662, in _on_write
    cb(written_data)
  File "C:\Users\Alex\anaconda3\envs\fd_env\lib\site-packages\wandb\sdk\wandb_run.py", line 2379, in <lambda>
    lambda data: self._console_raw_callback("stdout", data),
  File "C:\Users\Alex\anaconda3\envs\fd_env\lib\site-packages\wandb\sdk\wandb_run.py", line 398, in wrapper
    return func(self, *args, **kwargs)
  File "C:\Users\Alex\anaconda3\envs\fd_env\lib\site-packages\wandb\sdk\wandb_run.py", line 456, in wrapper_fn
    return func(self, *args, **kwargs)
  File "C:\Users\Alex\anaconda3\envs\fd_env\lib\site-packages\wandb\sdk\wandb_run.py", line 1566, in _console_raw_callback
    self._backend.interface.publish_output_raw(name, data)
  File "C:\Users\Alex\anaconda3\envs\fd_env\lib\site-packages\wandb\sdk\interface\interface.py", line 771, in publish_output_raw
    self._publish_output_raw(o)
  File "C:\Users\Alex\anaconda3\envs\fd_env\lib\site-packages\wandb\sdk\interface\interface_shared.py", line 38, in _publish_output_raw
    self._publish(rec)
  File "C:\Users\Alex\anaconda3\envs\fd_env\lib\site-packages\wandb\sdk\interface\interface_sock.py", line 39, in _publish
    self._sock_client.send_record_publish(record)
  File "C:\Users\Alex\anaconda3\envs\fd_env\lib\site-packages\wandb\sdk\lib\sock_client.py", line 170, in send_record_publish
    self.send_server_request(server_req)
  File "C:\Users\Alex\anaconda3\envs\fd_env\lib\site-packages\wandb\sdk\lib\sock_client.py", line 150, in send_server_request
    self._send_message(msg)
  File "C:\Users\Alex\anaconda3\envs\fd_env\lib\site-packages\wandb\sdk\lib\sock_client.py", line 147, in _send_message
    self._sendall_with_error_handle(header + data)
  File "C:\Users\Alex\anaconda3\envs\fd_env\lib\site-packages\wandb\sdk\lib\sock_client.py", line 126, in _sendall_with_error_handle
    sent = self._sock.send(data)
ConnectionResetError: [WinError 10054] Удаленный хост принудительно разорвал существующее подключение
2025-07-05 14:54:26,960 ERROR   MainThread:36952 [redirect.py:_on_write():664] [all runs] error in stdout callback
Traceback (most recent call last):
  File "C:\Users\Alex\anaconda3\envs\fd_env\lib\site-packages\wandb\sdk\lib\redirect.py", line 662, in _on_write
    cb(written_data)
  File "C:\Users\Alex\anaconda3\envs\fd_env\lib\site-packages\wandb\sdk\wandb_run.py", line 2379, in <lambda>
    lambda data: self._console_raw_callback("stdout", data),
  File "C:\Users\Alex\anaconda3\envs\fd_env\lib\site-packages\wandb\sdk\wandb_run.py", line 398, in wrapper
    return func(self, *args, **kwargs)
  File "C:\Users\Alex\anaconda3\envs\fd_env\lib\site-packages\wandb\sdk\wandb_run.py", line 456, in wrapper_fn
    return func(self, *args, **kwargs)
  File "C:\Users\Alex\anaconda3\envs\fd_env\lib\site-packages\wandb\sdk\wandb_run.py", line 1566, in _console_raw_callback
    self._backend.interface.publish_output_raw(name, data)
  File "C:\Users\Alex\anaconda3\envs\fd_env\lib\site-packages\wandb\sdk\interface\interface.py", line 771, in publish_output_raw
    self._publish_output_raw(o)
  File "C:\Users\Alex\anaconda3\envs\fd_env\lib\site-packages\wandb\sdk\interface\interface_shared.py", line 38, in _publish_output_raw
    self._publish(rec)
  File "C:\Users\Alex\anaconda3\envs\fd_env\lib\site-packages\wandb\sdk\interface\interface_sock.py", line 39, in _publish
    self._sock_client.send_record_publish(record)
  File "C:\Users\Alex\anaconda3\envs\fd_env\lib\site-packages\wandb\sdk\lib\sock_client.py", line 170, in send_record_publish
    self.send_server_request(server_req)
  File "C:\Users\Alex\anaconda3\envs\fd_env\lib\site-packages\wandb\sdk\lib\sock_client.py", line 150, in send_server_request
    self._send_message(msg)
  File "C:\Users\Alex\anaconda3\envs\fd_env\lib\site-packages\wandb\sdk\lib\sock_client.py", line 147, in _send_message
    self._sendall_with_error_handle(header + data)
  File "C:\Users\Alex\anaconda3\envs\fd_env\lib\site-packages\wandb\sdk\lib\sock_client.py", line 126, in _sendall_with_error_handle
    sent = self._sock.send(data)
ConnectionResetError: [WinError 10054] Удаленный хост принудительно разорвал существующее подключение
2025-07-05 14:54:26,963 ERROR   MainThread:36952 [redirect.py:_on_write():664] [all runs] error in stderr callback
Traceback (most recent call last):
  File "C:\Users\Alex\anaconda3\envs\fd_env\lib\site-packages\wandb\sdk\lib\redirect.py", line 662, in _on_write
    cb(written_data)
  File "C:\Users\Alex\anaconda3\envs\fd_env\lib\site-packages\wandb\sdk\wandb_run.py", line 2385, in <lambda>
    lambda data: self._console_raw_callback("stderr", data),
  File "C:\Users\Alex\anaconda3\envs\fd_env\lib\site-packages\wandb\sdk\wandb_run.py", line 398, in wrapper
    return func(self, *args, **kwargs)
  File "C:\Users\Alex\anaconda3\envs\fd_env\lib\site-packages\wandb\sdk\wandb_run.py", line 456, in wrapper_fn
    return func(self, *args, **kwargs)
  File "C:\Users\Alex\anaconda3\envs\fd_env\lib\site-packages\wandb\sdk\wandb_run.py", line 1566, in _console_raw_callback
    self._backend.interface.publish_output_raw(name, data)
  File "C:\Users\Alex\anaconda3\envs\fd_env\lib\site-packages\wandb\sdk\interface\interface.py", line 771, in publish_output_raw
    self._publish_output_raw(o)
  File "C:\Users\Alex\anaconda3\envs\fd_env\lib\site-packages\wandb\sdk\interface\interface_shared.py", line 38, in _publish_output_raw
    self._publish(rec)
  File "C:\Users\Alex\anaconda3\envs\fd_env\lib\site-packages\wandb\sdk\interface\interface_sock.py", line 39, in _publish
    self._sock_client.send_record_publish(record)
  File "C:\Users\Alex\anaconda3\envs\fd_env\lib\site-packages\wandb\sdk\lib\sock_client.py", line 170, in send_record_publish
    self.send_server_request(server_req)
  File "C:\Users\Alex\anaconda3\envs\fd_env\lib\site-packages\wandb\sdk\lib\sock_client.py", line 150, in send_server_request
    self._send_message(msg)
  File "C:\Users\Alex\anaconda3\envs\fd_env\lib\site-packages\wandb\sdk\lib\sock_client.py", line 147, in _send_message
    self._sendall_with_error_handle(header + data)
  File "C:\Users\Alex\anaconda3\envs\fd_env\lib\site-packages\wandb\sdk\lib\sock_client.py", line 126, in _sendall_with_error_handle
    sent = self._sock.send(data)
ConnectionResetError: [WinError 10054] Удаленный хост принудительно разорвал существующее подключение
2025-07-05 14:54:50,821 ERROR   MainThread:36952 [redirect.py:_on_write():664] [all runs] error in stderr callback
Traceback (most recent call last):
  File "C:\Users\Alex\anaconda3\envs\fd_env\lib\site-packages\wandb\sdk\lib\redirect.py", line 662, in _on_write
    cb(written_data)
  File "C:\Users\Alex\anaconda3\envs\fd_env\lib\site-packages\wandb\sdk\wandb_run.py", line 2385, in <lambda>
    lambda data: self._console_raw_callback("stderr", data),
  File "C:\Users\Alex\anaconda3\envs\fd_env\lib\site-packages\wandb\sdk\wandb_run.py", line 398, in wrapper
    return func(self, *args, **kwargs)
  File "C:\Users\Alex\anaconda3\envs\fd_env\lib\site-packages\wandb\sdk\wandb_run.py", line 456, in wrapper_fn
    return func(self, *args, **kwargs)
  File "C:\Users\Alex\anaconda3\envs\fd_env\lib\site-packages\wandb\sdk\wandb_run.py", line 1566, in _console_raw_callback
    self._backend.interface.publish_output_raw(name, data)
  File "C:\Users\Alex\anaconda3\envs\fd_env\lib\site-packages\wandb\sdk\interface\interface.py", line 771, in publish_output_raw
    self._publish_output_raw(o)
  File "C:\Users\Alex\anaconda3\envs\fd_env\lib\site-packages\wandb\sdk\interface\interface_shared.py", line 38, in _publish_output_raw
    self._publish(rec)
  File "C:\Users\Alex\anaconda3\envs\fd_env\lib\site-packages\wandb\sdk\interface\interface_sock.py", line 39, in _publish
    self._sock_client.send_record_publish(record)
  File "C:\Users\Alex\anaconda3\envs\fd_env\lib\site-packages\wandb\sdk\lib\sock_client.py", line 170, in send_record_publish
    self.send_server_request(server_req)
  File "C:\Users\Alex\anaconda3\envs\fd_env\lib\site-packages\wandb\sdk\lib\sock_client.py", line 150, in send_server_request
    self._send_message(msg)
  File "C:\Users\Alex\anaconda3\envs\fd_env\lib\site-packages\wandb\sdk\lib\sock_client.py", line 147, in _send_message
    self._sendall_with_error_handle(header + data)
  File "C:\Users\Alex\anaconda3\envs\fd_env\lib\site-packages\wandb\sdk\lib\sock_client.py", line 126, in _sendall_with_error_handle
    sent = self._sock.send(data)
ConnectionResetError: [WinError 10054] Удаленный хост принудительно разорвал существующее подключение
2025-07-05 14:54:50,824 ERROR   MainThread:36952 [redirect.py:_on_write():664] [all runs] error in stderr callback
Traceback (most recent call last):
  File "C:\Users\Alex\anaconda3\envs\fd_env\lib\site-packages\wandb\sdk\lib\redirect.py", line 662, in _on_write
    cb(written_data)
  File "C:\Users\Alex\anaconda3\envs\fd_env\lib\site-packages\wandb\sdk\wandb_run.py", line 2385, in <lambda>
    lambda data: self._console_raw_callback("stderr", data),
  File "C:\Users\Alex\anaconda3\envs\fd_env\lib\site-packages\wandb\sdk\wandb_run.py", line 398, in wrapper
    return func(self, *args, **kwargs)
  File "C:\Users\Alex\anaconda3\envs\fd_env\lib\site-packages\wandb\sdk\wandb_run.py", line 456, in wrapper_fn
    return func(self, *args, **kwargs)
  File "C:\Users\Alex\anaconda3\envs\fd_env\lib\site-packages\wandb\sdk\wandb_run.py", line 1566, in _console_raw_callback
    self._backend.interface.publish_output_raw(name, data)
  File "C:\Users\Alex\anaconda3\envs\fd_env\lib\site-packages\wandb\sdk\interface\interface.py", line 771, in publish_output_raw
    self._publish_output_raw(o)
  File "C:\Users\Alex\anaconda3\envs\fd_env\lib\site-packages\wandb\sdk\interface\interface_shared.py", line 38, in _publish_output_raw
    self._publish(rec)
  File "C:\Users\Alex\anaconda3\envs\fd_env\lib\site-packages\wandb\sdk\interface\interface_sock.py", line 39, in _publish
    self._sock_client.send_record_publish(record)
  File "C:\Users\Alex\anaconda3\envs\fd_env\lib\site-packages\wandb\sdk\lib\sock_client.py", line 170, in send_record_publish
    self.send_server_request(server_req)
  File "C:\Users\Alex\anaconda3\envs\fd_env\lib\site-packages\wandb\sdk\lib\sock_client.py", line 150, in send_server_request
    self._send_message(msg)
  File "C:\Users\Alex\anaconda3\envs\fd_env\lib\site-packages\wandb\sdk\lib\sock_client.py", line 147, in _send_message
    self._sendall_with_error_handle(header + data)
  File "C:\Users\Alex\anaconda3\envs\fd_env\lib\site-packages\wandb\sdk\lib\sock_client.py", line 126, in _sendall_with_error_handle
    sent = self._sock.send(data)
ConnectionResetError: [WinError 10054] Удаленный хост принудительно разорвал существующее подключение
2025-07-05 14:55:11,610 ERROR   MainThread:36952 [redirect.py:_on_write():664] [all runs] error in stderr callback
Traceback (most recent call last):
  File "C:\Users\Alex\anaconda3\envs\fd_env\lib\site-packages\wandb\sdk\lib\redirect.py", line 662, in _on_write
    cb(written_data)
  File "C:\Users\Alex\anaconda3\envs\fd_env\lib\site-packages\wandb\sdk\wandb_run.py", line 2385, in <lambda>
    lambda data: self._console_raw_callback("stderr", data),
  File "C:\Users\Alex\anaconda3\envs\fd_env\lib\site-packages\wandb\sdk\wandb_run.py", line 398, in wrapper
    return func(self, *args, **kwargs)
  File "C:\Users\Alex\anaconda3\envs\fd_env\lib\site-packages\wandb\sdk\wandb_run.py", line 456, in wrapper_fn
    return func(self, *args, **kwargs)
  File "C:\Users\Alex\anaconda3\envs\fd_env\lib\site-packages\wandb\sdk\wandb_run.py", line 1566, in _console_raw_callback
    self._backend.interface.publish_output_raw(name, data)
  File "C:\Users\Alex\anaconda3\envs\fd_env\lib\site-packages\wandb\sdk\interface\interface.py", line 771, in publish_output_raw
    self._publish_output_raw(o)
  File "C:\Users\Alex\anaconda3\envs\fd_env\lib\site-packages\wandb\sdk\interface\interface_shared.py", line 38, in _publish_output_raw
    self._publish(rec)
  File "C:\Users\Alex\anaconda3\envs\fd_env\lib\site-packages\wandb\sdk\interface\interface_sock.py", line 39, in _publish
    self._sock_client.send_record_publish(record)
  File "C:\Users\Alex\anaconda3\envs\fd_env\lib\site-packages\wandb\sdk\lib\sock_client.py", line 170, in send_record_publish
    self.send_server_request(server_req)
  File "C:\Users\Alex\anaconda3\envs\fd_env\lib\site-packages\wandb\sdk\lib\sock_client.py", line 150, in send_server_request
    self._send_message(msg)
  File "C:\Users\Alex\anaconda3\envs\fd_env\lib\site-packages\wandb\sdk\lib\sock_client.py", line 147, in _send_message
    self._sendall_with_error_handle(header + data)
  File "C:\Users\Alex\anaconda3\envs\fd_env\lib\site-packages\wandb\sdk\lib\sock_client.py", line 126, in _sendall_with_error_handle
    sent = self._sock.send(data)
ConnectionResetError: [WinError 10054] Удаленный хост принудительно разорвал существующее подключение
2025-07-05 14:55:11,612 ERROR   MainThread:36952 [redirect.py:_on_write():664] [all runs] error in stderr callback
Traceback (most recent call last):
  File "C:\Users\Alex\anaconda3\envs\fd_env\lib\site-packages\wandb\sdk\lib\redirect.py", line 662, in _on_write
    cb(written_data)
  File "C:\Users\Alex\anaconda3\envs\fd_env\lib\site-packages\wandb\sdk\wandb_run.py", line 2385, in <lambda>
    lambda data: self._console_raw_callback("stderr", data),
  File "C:\Users\Alex\anaconda3\envs\fd_env\lib\site-packages\wandb\sdk\wandb_run.py", line 398, in wrapper
    return func(self, *args, **kwargs)
  File "C:\Users\Alex\anaconda3\envs\fd_env\lib\site-packages\wandb\sdk\wandb_run.py", line 456, in wrapper_fn
    return func(self, *args, **kwargs)
  File "C:\Users\Alex\anaconda3\envs\fd_env\lib\site-packages\wandb\sdk\wandb_run.py", line 1566, in _console_raw_callback
    self._backend.interface.publish_output_raw(name, data)
  File "C:\Users\Alex\anaconda3\envs\fd_env\lib\site-packages\wandb\sdk\interface\interface.py", line 771, in publish_output_raw
    self._publish_output_raw(o)
  File "C:\Users\Alex\anaconda3\envs\fd_env\lib\site-packages\wandb\sdk\interface\interface_shared.py", line 38, in _publish_output_raw
    self._publish(rec)
  File "C:\Users\Alex\anaconda3\envs\fd_env\lib\site-packages\wandb\sdk\interface\interface_sock.py", line 39, in _publish
    self._sock_client.send_record_publish(record)
  File "C:\Users\Alex\anaconda3\envs\fd_env\lib\site-packages\wandb\sdk\lib\sock_client.py", line 170, in send_record_publish
    self.send_server_request(server_req)
  File "C:\Users\Alex\anaconda3\envs\fd_env\lib\site-packages\wandb\sdk\lib\sock_client.py", line 150, in send_server_request
    self._send_message(msg)
  File "C:\Users\Alex\anaconda3\envs\fd_env\lib\site-packages\wandb\sdk\lib\sock_client.py", line 147, in _send_message
    self._sendall_with_error_handle(header + data)
  File "C:\Users\Alex\anaconda3\envs\fd_env\lib\site-packages\wandb\sdk\lib\sock_client.py", line 126, in _sendall_with_error_handle
    sent = self._sock.send(data)
ConnectionResetError: [WinError 10054] Удаленный хост принудительно разорвал существующее подключение
2025-07-05 14:55:29,764 ERROR   MainThread:36952 [redirect.py:_on_write():664] [all runs] error in stderr callback
Traceback (most recent call last):
  File "C:\Users\Alex\anaconda3\envs\fd_env\lib\site-packages\wandb\sdk\lib\redirect.py", line 662, in _on_write
    cb(written_data)
  File "C:\Users\Alex\anaconda3\envs\fd_env\lib\site-packages\wandb\sdk\wandb_run.py", line 2385, in <lambda>
    lambda data: self._console_raw_callback("stderr", data),
  File "C:\Users\Alex\anaconda3\envs\fd_env\lib\site-packages\wandb\sdk\wandb_run.py", line 398, in wrapper
    return func(self, *args, **kwargs)
  File "C:\Users\Alex\anaconda3\envs\fd_env\lib\site-packages\wandb\sdk\wandb_run.py", line 456, in wrapper_fn
    return func(self, *args, **kwargs)
  File "C:\Users\Alex\anaconda3\envs\fd_env\lib\site-packages\wandb\sdk\wandb_run.py", line 1566, in _console_raw_callback
    self._backend.interface.publish_output_raw(name, data)
  File "C:\Users\Alex\anaconda3\envs\fd_env\lib\site-packages\wandb\sdk\interface\interface.py", line 771, in publish_output_raw
    self._publish_output_raw(o)
  File "C:\Users\Alex\anaconda3\envs\fd_env\lib\site-packages\wandb\sdk\interface\interface_shared.py", line 38, in _publish_output_raw
    self._publish(rec)
  File "C:\Users\Alex\anaconda3\envs\fd_env\lib\site-packages\wandb\sdk\interface\interface_sock.py", line 39, in _publish
    self._sock_client.send_record_publish(record)
  File "C:\Users\Alex\anaconda3\envs\fd_env\lib\site-packages\wandb\sdk\lib\sock_client.py", line 170, in send_record_publish
    self.send_server_request(server_req)
  File "C:\Users\Alex\anaconda3\envs\fd_env\lib\site-packages\wandb\sdk\lib\sock_client.py", line 150, in send_server_request
    self._send_message(msg)
  File "C:\Users\Alex\anaconda3\envs\fd_env\lib\site-packages\wandb\sdk\lib\sock_client.py", line 147, in _send_message
    self._sendall_with_error_handle(header + data)
  File "C:\Users\Alex\anaconda3\envs\fd_env\lib\site-packages\wandb\sdk\lib\sock_client.py", line 126, in _sendall_with_error_handle
    sent = self._sock.send(data)
ConnectionResetError: [WinError 10054] Удаленный хост принудительно разорвал существующее подключение
2025-07-05 14:55:29,767 ERROR   MainThread:36952 [redirect.py:_on_write():664] [all runs] error in stderr callback
Traceback (most recent call last):
  File "C:\Users\Alex\anaconda3\envs\fd_env\lib\site-packages\wandb\sdk\lib\redirect.py", line 662, in _on_write
    cb(written_data)
  File "C:\Users\Alex\anaconda3\envs\fd_env\lib\site-packages\wandb\sdk\wandb_run.py", line 2385, in <lambda>
    lambda data: self._console_raw_callback("stderr", data),
  File "C:\Users\Alex\anaconda3\envs\fd_env\lib\site-packages\wandb\sdk\wandb_run.py", line 398, in wrapper
    return func(self, *args, **kwargs)
  File "C:\Users\Alex\anaconda3\envs\fd_env\lib\site-packages\wandb\sdk\wandb_run.py", line 456, in wrapper_fn
    return func(self, *args, **kwargs)
  File "C:\Users\Alex\anaconda3\envs\fd_env\lib\site-packages\wandb\sdk\wandb_run.py", line 1566, in _console_raw_callback
    self._backend.interface.publish_output_raw(name, data)
  File "C:\Users\Alex\anaconda3\envs\fd_env\lib\site-packages\wandb\sdk\interface\interface.py", line 771, in publish_output_raw
    self._publish_output_raw(o)
  File "C:\Users\Alex\anaconda3\envs\fd_env\lib\site-packages\wandb\sdk\interface\interface_shared.py", line 38, in _publish_output_raw
    self._publish(rec)
  File "C:\Users\Alex\anaconda3\envs\fd_env\lib\site-packages\wandb\sdk\interface\interface_sock.py", line 39, in _publish
    self._sock_client.send_record_publish(record)
  File "C:\Users\Alex\anaconda3\envs\fd_env\lib\site-packages\wandb\sdk\lib\sock_client.py", line 170, in send_record_publish
    self.send_server_request(server_req)
  File "C:\Users\Alex\anaconda3\envs\fd_env\lib\site-packages\wandb\sdk\lib\sock_client.py", line 150, in send_server_request
    self._send_message(msg)
  File "C:\Users\Alex\anaconda3\envs\fd_env\lib\site-packages\wandb\sdk\lib\sock_client.py", line 147, in _send_message
    self._sendall_with_error_handle(header + data)
  File "C:\Users\Alex\anaconda3\envs\fd_env\lib\site-packages\wandb\sdk\lib\sock_client.py", line 126, in _sendall_with_error_handle
    sent = self._sock.send(data)
ConnectionResetError: [WinError 10054] Удаленный хост принудительно разорвал существующее подключение
2025-07-05 14:55:47,466 ERROR   MainThread:36952 [redirect.py:_on_write():664] [all runs] error in stderr callback
Traceback (most recent call last):
  File "C:\Users\Alex\anaconda3\envs\fd_env\lib\site-packages\tqdm\std.py", line 1182, in __iter__
    yield obj
GeneratorExit

During handling of the above exception, another exception occurred:

Traceback (most recent call last):
  File "C:\Users\Alex\anaconda3\envs\fd_env\lib\site-packages\wandb\sdk\lib\redirect.py", line 662, in _on_write
    cb(written_data)
  File "C:\Users\Alex\anaconda3\envs\fd_env\lib\site-packages\wandb\sdk\wandb_run.py", line 2385, in <lambda>
    lambda data: self._console_raw_callback("stderr", data),
  File "C:\Users\Alex\anaconda3\envs\fd_env\lib\site-packages\wandb\sdk\wandb_run.py", line 398, in wrapper
    return func(self, *args, **kwargs)
  File "C:\Users\Alex\anaconda3\envs\fd_env\lib\site-packages\wandb\sdk\wandb_run.py", line 456, in wrapper_fn
    return func(self, *args, **kwargs)
  File "C:\Users\Alex\anaconda3\envs\fd_env\lib\site-packages\wandb\sdk\wandb_run.py", line 1566, in _console_raw_callback
    self._backend.interface.publish_output_raw(name, data)
  File "C:\Users\Alex\anaconda3\envs\fd_env\lib\site-packages\wandb\sdk\interface\interface.py", line 771, in publish_output_raw
    self._publish_output_raw(o)
  File "C:\Users\Alex\anaconda3\envs\fd_env\lib\site-packages\wandb\sdk\interface\interface_shared.py", line 38, in _publish_output_raw
    self._publish(rec)
  File "C:\Users\Alex\anaconda3\envs\fd_env\lib\site-packages\wandb\sdk\interface\interface_sock.py", line 39, in _publish
    self._sock_client.send_record_publish(record)
  File "C:\Users\Alex\anaconda3\envs\fd_env\lib\site-packages\wandb\sdk\lib\sock_client.py", line 170, in send_record_publish
    self.send_server_request(server_req)
  File "C:\Users\Alex\anaconda3\envs\fd_env\lib\site-packages\wandb\sdk\lib\sock_client.py", line 150, in send_server_request
    self._send_message(msg)
  File "C:\Users\Alex\anaconda3\envs\fd_env\lib\site-packages\wandb\sdk\lib\sock_client.py", line 147, in _send_message
    self._sendall_with_error_handle(header + data)
  File "C:\Users\Alex\anaconda3\envs\fd_env\lib\site-packages\wandb\sdk\lib\sock_client.py", line 126, in _sendall_with_error_handle
    sent = self._sock.send(data)
ConnectionResetError: [WinError 10054] Удаленный хост принудительно разорвал существующее подключение
2025-07-05 14:55:47,469 ERROR   MainThread:36952 [redirect.py:_on_write():664] [all runs] error in stderr callback
Traceback (most recent call last):
  File "C:\Users\Alex\anaconda3\envs\fd_env\lib\site-packages\tqdm\std.py", line 1182, in __iter__
    yield obj
GeneratorExit

During handling of the above exception, another exception occurred:

Traceback (most recent call last):
  File "C:\Users\Alex\anaconda3\envs\fd_env\lib\site-packages\wandb\sdk\lib\redirect.py", line 662, in _on_write
    cb(written_data)
  File "C:\Users\Alex\anaconda3\envs\fd_env\lib\site-packages\wandb\sdk\wandb_run.py", line 2385, in <lambda>
    lambda data: self._console_raw_callback("stderr", data),
  File "C:\Users\Alex\anaconda3\envs\fd_env\lib\site-packages\wandb\sdk\wandb_run.py", line 398, in wrapper
    return func(self, *args, **kwargs)
  File "C:\Users\Alex\anaconda3\envs\fd_env\lib\site-packages\wandb\sdk\wandb_run.py", line 456, in wrapper_fn
    return func(self, *args, **kwargs)
  File "C:\Users\Alex\anaconda3\envs\fd_env\lib\site-packages\wandb\sdk\wandb_run.py", line 1566, in _console_raw_callback
    self._backend.interface.publish_output_raw(name, data)
  File "C:\Users\Alex\anaconda3\envs\fd_env\lib\site-packages\wandb\sdk\interface\interface.py", line 771, in publish_output_raw
    self._publish_output_raw(o)
  File "C:\Users\Alex\anaconda3\envs\fd_env\lib\site-packages\wandb\sdk\interface\interface_shared.py", line 38, in _publish_output_raw
    self._publish(rec)
  File "C:\Users\Alex\anaconda3\envs\fd_env\lib\site-packages\wandb\sdk\interface\interface_sock.py", line 39, in _publish
    self._sock_client.send_record_publish(record)
  File "C:\Users\Alex\anaconda3\envs\fd_env\lib\site-packages\wandb\sdk\lib\sock_client.py", line 170, in send_record_publish
    self.send_server_request(server_req)
  File "C:\Users\Alex\anaconda3\envs\fd_env\lib\site-packages\wandb\sdk\lib\sock_client.py", line 150, in send_server_request
    self._send_message(msg)
  File "C:\Users\Alex\anaconda3\envs\fd_env\lib\site-packages\wandb\sdk\lib\sock_client.py", line 147, in _send_message
    self._sendall_with_error_handle(header + data)
  File "C:\Users\Alex\anaconda3\envs\fd_env\lib\site-packages\wandb\sdk\lib\sock_client.py", line 126, in _sendall_with_error_handle
    sent = self._sock.send(data)
ConnectionResetError: [WinError 10054] Удаленный хост принудительно разорвал существующее подключение
2025-07-05 14:55:47,471 ERROR   MainThread:36952 [redirect.py:_on_write():664] [all runs] error in stderr callback
Traceback (most recent call last):
  File "C:\Users\Alex\anaconda3\envs\fd_env\lib\site-packages\tqdm\std.py", line 1182, in __iter__
    yield obj
GeneratorExit

During handling of the above exception, another exception occurred:

Traceback (most recent call last):
  File "C:\Users\Alex\anaconda3\envs\fd_env\lib\site-packages\wandb\sdk\lib\redirect.py", line 662, in _on_write
    cb(written_data)
  File "C:\Users\Alex\anaconda3\envs\fd_env\lib\site-packages\wandb\sdk\wandb_run.py", line 2385, in <lambda>
    lambda data: self._console_raw_callback("stderr", data),
  File "C:\Users\Alex\anaconda3\envs\fd_env\lib\site-packages\wandb\sdk\wandb_run.py", line 398, in wrapper
    return func(self, *args, **kwargs)
  File "C:\Users\Alex\anaconda3\envs\fd_env\lib\site-packages\wandb\sdk\wandb_run.py", line 456, in wrapper_fn
    return func(self, *args, **kwargs)
  File "C:\Users\Alex\anaconda3\envs\fd_env\lib\site-packages\wandb\sdk\wandb_run.py", line 1566, in _console_raw_callback
    self._backend.interface.publish_output_raw(name, data)
  File "C:\Users\Alex\anaconda3\envs\fd_env\lib\site-packages\wandb\sdk\interface\interface.py", line 771, in publish_output_raw
    self._publish_output_raw(o)
  File "C:\Users\Alex\anaconda3\envs\fd_env\lib\site-packages\wandb\sdk\interface\interface_shared.py", line 38, in _publish_output_raw
    self._publish(rec)
  File "C:\Users\Alex\anaconda3\envs\fd_env\lib\site-packages\wandb\sdk\interface\interface_sock.py", line 39, in _publish
    self._sock_client.send_record_publish(record)
  File "C:\Users\Alex\anaconda3\envs\fd_env\lib\site-packages\wandb\sdk\lib\sock_client.py", line 170, in send_record_publish
    self.send_server_request(server_req)
  File "C:\Users\Alex\anaconda3\envs\fd_env\lib\site-packages\wandb\sdk\lib\sock_client.py", line 150, in send_server_request
    self._send_message(msg)
  File "C:\Users\Alex\anaconda3\envs\fd_env\lib\site-packages\wandb\sdk\lib\sock_client.py", line 147, in _send_message
    self._sendall_with_error_handle(header + data)
  File "C:\Users\Alex\anaconda3\envs\fd_env\lib\site-packages\wandb\sdk\lib\sock_client.py", line 126, in _sendall_with_error_handle
    sent = self._sock.send(data)
ConnectionResetError: [WinError 10054] Удаленный хост принудительно разорвал существующее подключение
2025-07-05 14:55:47,472 ERROR   MainThread:36952 [redirect.py:_on_write():664] [all runs] error in stdout callback
Traceback (most recent call last):
  File "C:\Users\Alex\PycharmProjects\dish_detect\train_yolo_wandb.py", line 60, in train_yolo_with_wandb
    results = model.train(**train_args)
  File "C:\Users\Alex\anaconda3\envs\fd_env\lib\site-packages\ultralytics\engine\model.py", line 799, in train
    self.trainer.train()
  File "C:\Users\Alex\anaconda3\envs\fd_env\lib\site-packages\ultralytics\engine\trainer.py", line 227, in train
    self._do_train(world_size)
  File "C:\Users\Alex\anaconda3\envs\fd_env\lib\site-packages\ultralytics\engine\trainer.py", line 415, in _do_train
    self.scaler.scale(self.loss).backward()
  File "C:\Users\Alex\anaconda3\envs\fd_env\lib\site-packages\torch\_tensor.py", line 653, in backward
    torch.autograd.backward(
  File "C:\Users\Alex\anaconda3\envs\fd_env\lib\site-packages\torch\autograd\__init__.py", line 354, in backward
    _engine_run_backward(
  File "C:\Users\Alex\anaconda3\envs\fd_env\lib\site-packages\torch\autograd\graph.py", line 829, in _engine_run_backward
    return Variable._execution_engine.run_backward(  # Calls into the C++ engine to run the backward pass
RuntimeError: bad allocation

During handling of the above exception, another exception occurred:

Traceback (most recent call last):
  File "C:\Users\Alex\anaconda3\envs\fd_env\lib\site-packages\wandb\sdk\lib\redirect.py", line 662, in _on_write
    cb(written_data)
  File "C:\Users\Alex\anaconda3\envs\fd_env\lib\site-packages\wandb\sdk\wandb_run.py", line 2379, in <lambda>
    lambda data: self._console_raw_callback("stdout", data),
  File "C:\Users\Alex\anaconda3\envs\fd_env\lib\site-packages\wandb\sdk\wandb_run.py", line 398, in wrapper
    return func(self, *args, **kwargs)
  File "C:\Users\Alex\anaconda3\envs\fd_env\lib\site-packages\wandb\sdk\wandb_run.py", line 456, in wrapper_fn
    return func(self, *args, **kwargs)
  File "C:\Users\Alex\anaconda3\envs\fd_env\lib\site-packages\wandb\sdk\wandb_run.py", line 1566, in _console_raw_callback
    self._backend.interface.publish_output_raw(name, data)
  File "C:\Users\Alex\anaconda3\envs\fd_env\lib\site-packages\wandb\sdk\interface\interface.py", line 771, in publish_output_raw
    self._publish_output_raw(o)
  File "C:\Users\Alex\anaconda3\envs\fd_env\lib\site-packages\wandb\sdk\interface\interface_shared.py", line 38, in _publish_output_raw
    self._publish(rec)
  File "C:\Users\Alex\anaconda3\envs\fd_env\lib\site-packages\wandb\sdk\interface\interface_sock.py", line 39, in _publish
    self._sock_client.send_record_publish(record)
  File "C:\Users\Alex\anaconda3\envs\fd_env\lib\site-packages\wandb\sdk\lib\sock_client.py", line 170, in send_record_publish
    self.send_server_request(server_req)
  File "C:\Users\Alex\anaconda3\envs\fd_env\lib\site-packages\wandb\sdk\lib\sock_client.py", line 150, in send_server_request
    self._send_message(msg)
  File "C:\Users\Alex\anaconda3\envs\fd_env\lib\site-packages\wandb\sdk\lib\sock_client.py", line 147, in _send_message
    self._sendall_with_error_handle(header + data)
  File "C:\Users\Alex\anaconda3\envs\fd_env\lib\site-packages\wandb\sdk\lib\sock_client.py", line 126, in _sendall_with_error_handle
    sent = self._sock.send(data)
ConnectionResetError: [WinError 10054] Удаленный хост принудительно разорвал существующее подключение
2025-07-05 14:55:47,478 ERROR   MainThread:36952 [redirect.py:_on_write():664] [all runs] error in stdout callback
Traceback (most recent call last):
  File "C:\Users\Alex\PycharmProjects\dish_detect\train_yolo_wandb.py", line 60, in train_yolo_with_wandb
    results = model.train(**train_args)
  File "C:\Users\Alex\anaconda3\envs\fd_env\lib\site-packages\ultralytics\engine\model.py", line 799, in train
    self.trainer.train()
  File "C:\Users\Alex\anaconda3\envs\fd_env\lib\site-packages\ultralytics\engine\trainer.py", line 227, in train
    self._do_train(world_size)
  File "C:\Users\Alex\anaconda3\envs\fd_env\lib\site-packages\ultralytics\engine\trainer.py", line 415, in _do_train
    self.scaler.scale(self.loss).backward()
  File "C:\Users\Alex\anaconda3\envs\fd_env\lib\site-packages\torch\_tensor.py", line 653, in backward
    torch.autograd.backward(
  File "C:\Users\Alex\anaconda3\envs\fd_env\lib\site-packages\torch\autograd\__init__.py", line 354, in backward
    _engine_run_backward(
  File "C:\Users\Alex\anaconda3\envs\fd_env\lib\site-packages\torch\autograd\graph.py", line 829, in _engine_run_backward
    return Variable._execution_engine.run_backward(  # Calls into the C++ engine to run the backward pass
RuntimeError: bad allocation

During handling of the above exception, another exception occurred:

Traceback (most recent call last):
  File "C:\Users\Alex\anaconda3\envs\fd_env\lib\site-packages\wandb\sdk\lib\redirect.py", line 662, in _on_write
    cb(written_data)
  File "C:\Users\Alex\anaconda3\envs\fd_env\lib\site-packages\wandb\sdk\wandb_run.py", line 2379, in <lambda>
    lambda data: self._console_raw_callback("stdout", data),
  File "C:\Users\Alex\anaconda3\envs\fd_env\lib\site-packages\wandb\sdk\wandb_run.py", line 398, in wrapper
    return func(self, *args, **kwargs)
  File "C:\Users\Alex\anaconda3\envs\fd_env\lib\site-packages\wandb\sdk\wandb_run.py", line 456, in wrapper_fn
    return func(self, *args, **kwargs)
  File "C:\Users\Alex\anaconda3\envs\fd_env\lib\site-packages\wandb\sdk\wandb_run.py", line 1566, in _console_raw_callback
    self._backend.interface.publish_output_raw(name, data)
  File "C:\Users\Alex\anaconda3\envs\fd_env\lib\site-packages\wandb\sdk\interface\interface.py", line 771, in publish_output_raw
    self._publish_output_raw(o)
  File "C:\Users\Alex\anaconda3\envs\fd_env\lib\site-packages\wandb\sdk\interface\interface_shared.py", line 38, in _publish_output_raw
    self._publish(rec)
  File "C:\Users\Alex\anaconda3\envs\fd_env\lib\site-packages\wandb\sdk\interface\interface_sock.py", line 39, in _publish
    self._sock_client.send_record_publish(record)
  File "C:\Users\Alex\anaconda3\envs\fd_env\lib\site-packages\wandb\sdk\lib\sock_client.py", line 170, in send_record_publish
    self.send_server_request(server_req)
  File "C:\Users\Alex\anaconda3\envs\fd_env\lib\site-packages\wandb\sdk\lib\sock_client.py", line 150, in send_server_request
    self._send_message(msg)
  File "C:\Users\Alex\anaconda3\envs\fd_env\lib\site-packages\wandb\sdk\lib\sock_client.py", line 147, in _send_message
    self._sendall_with_error_handle(header + data)
  File "C:\Users\Alex\anaconda3\envs\fd_env\lib\site-packages\wandb\sdk\lib\sock_client.py", line 126, in _sendall_with_error_handle
    sent = self._sock.send(data)
ConnectionResetError: [WinError 10054] Удаленный хост принудительно разорвал существующее подключение
2025-07-05 14:55:47,483 ERROR   MainThread:36952 [redirect.py:_on_write():664] [all runs] error in stderr callback
Traceback (most recent call last):
  File "C:\Users\Alex\anaconda3\envs\fd_env\lib\site-packages\wandb\sdk\lib\redirect.py", line 662, in _on_write
    cb(written_data)
  File "C:\Users\Alex\anaconda3\envs\fd_env\lib\site-packages\wandb\sdk\wandb_run.py", line 2385, in <lambda>
    lambda data: self._console_raw_callback("stderr", data),
  File "C:\Users\Alex\anaconda3\envs\fd_env\lib\site-packages\wandb\sdk\wandb_run.py", line 398, in wrapper
    return func(self, *args, **kwargs)
  File "C:\Users\Alex\anaconda3\envs\fd_env\lib\site-packages\wandb\sdk\wandb_run.py", line 456, in wrapper_fn
    return func(self, *args, **kwargs)
  File "C:\Users\Alex\anaconda3\envs\fd_env\lib\site-packages\wandb\sdk\wandb_run.py", line 1566, in _console_raw_callback
    self._backend.interface.publish_output_raw(name, data)
  File "C:\Users\Alex\anaconda3\envs\fd_env\lib\site-packages\wandb\sdk\interface\interface.py", line 771, in publish_output_raw
    self._publish_output_raw(o)
  File "C:\Users\Alex\anaconda3\envs\fd_env\lib\site-packages\wandb\sdk\interface\interface_shared.py", line 38, in _publish_output_raw
    self._publish(rec)
  File "C:\Users\Alex\anaconda3\envs\fd_env\lib\site-packages\wandb\sdk\interface\interface_sock.py", line 39, in _publish
    self._sock_client.send_record_publish(record)
  File "C:\Users\Alex\anaconda3\envs\fd_env\lib\site-packages\wandb\sdk\lib\sock_client.py", line 170, in send_record_publish
    self.send_server_request(server_req)
  File "C:\Users\Alex\anaconda3\envs\fd_env\lib\site-packages\wandb\sdk\lib\sock_client.py", line 150, in send_server_request
    self._send_message(msg)
  File "C:\Users\Alex\anaconda3\envs\fd_env\lib\site-packages\wandb\sdk\lib\sock_client.py", line 147, in _send_message
    self._sendall_with_error_handle(header + data)
  File "C:\Users\Alex\anaconda3\envs\fd_env\lib\site-packages\wandb\sdk\lib\sock_client.py", line 126, in _sendall_with_error_handle
    sent = self._sock.send(data)
ConnectionResetError: [WinError 10054] Удаленный хост принудительно разорвал существующее подключение
2025-07-05 14:55:47,484 ERROR   MainThread:36952 [redirect.py:_on_write():664] [all runs] error in stderr callback
Traceback (most recent call last):
  File "C:\Users\Alex\anaconda3\envs\fd_env\lib\site-packages\wandb\sdk\lib\redirect.py", line 662, in _on_write
    cb(written_data)
  File "C:\Users\Alex\anaconda3\envs\fd_env\lib\site-packages\wandb\sdk\wandb_run.py", line 2385, in <lambda>
    lambda data: self._console_raw_callback("stderr", data),
  File "C:\Users\Alex\anaconda3\envs\fd_env\lib\site-packages\wandb\sdk\wandb_run.py", line 398, in wrapper
    return func(self, *args, **kwargs)
  File "C:\Users\Alex\anaconda3\envs\fd_env\lib\site-packages\wandb\sdk\wandb_run.py", line 456, in wrapper_fn
    return func(self, *args, **kwargs)
  File "C:\Users\Alex\anaconda3\envs\fd_env\lib\site-packages\wandb\sdk\wandb_run.py", line 1566, in _console_raw_callback
    self._backend.interface.publish_output_raw(name, data)
  File "C:\Users\Alex\anaconda3\envs\fd_env\lib\site-packages\wandb\sdk\interface\interface.py", line 771, in publish_output_raw
    self._publish_output_raw(o)
  File "C:\Users\Alex\anaconda3\envs\fd_env\lib\site-packages\wandb\sdk\interface\interface_shared.py", line 38, in _publish_output_raw
    self._publish(rec)
  File "C:\Users\Alex\anaconda3\envs\fd_env\lib\site-packages\wandb\sdk\interface\interface_sock.py", line 39, in _publish
    self._sock_client.send_record_publish(record)
  File "C:\Users\Alex\anaconda3\envs\fd_env\lib\site-packages\wandb\sdk\lib\sock_client.py", line 170, in send_record_publish
    self.send_server_request(server_req)
  File "C:\Users\Alex\anaconda3\envs\fd_env\lib\site-packages\wandb\sdk\lib\sock_client.py", line 150, in send_server_request
    self._send_message(msg)
  File "C:\Users\Alex\anaconda3\envs\fd_env\lib\site-packages\wandb\sdk\lib\sock_client.py", line 147, in _send_message
    self._sendall_with_error_handle(header + data)
  File "C:\Users\Alex\anaconda3\envs\fd_env\lib\site-packages\wandb\sdk\lib\sock_client.py", line 126, in _sendall_with_error_handle
    sent = self._sock.send(data)
ConnectionResetError: [WinError 10054] Удаленный хост принудительно разорвал существующее подключение
2025-07-05 14:55:47,485 ERROR   MainThread:36952 [redirect.py:_on_write():664] [all runs] error in stderr callback
Traceback (most recent call last):
  File "C:\Users\Alex\anaconda3\envs\fd_env\lib\site-packages\wandb\sdk\lib\redirect.py", line 662, in _on_write
    cb(written_data)
  File "C:\Users\Alex\anaconda3\envs\fd_env\lib\site-packages\wandb\sdk\wandb_run.py", line 2385, in <lambda>
    lambda data: self._console_raw_callback("stderr", data),
  File "C:\Users\Alex\anaconda3\envs\fd_env\lib\site-packages\wandb\sdk\wandb_run.py", line 398, in wrapper
    return func(self, *args, **kwargs)
  File "C:\Users\Alex\anaconda3\envs\fd_env\lib\site-packages\wandb\sdk\wandb_run.py", line 456, in wrapper_fn
    return func(self, *args, **kwargs)
  File "C:\Users\Alex\anaconda3\envs\fd_env\lib\site-packages\wandb\sdk\wandb_run.py", line 1566, in _console_raw_callback
    self._backend.interface.publish_output_raw(name, data)
  File "C:\Users\Alex\anaconda3\envs\fd_env\lib\site-packages\wandb\sdk\interface\interface.py", line 771, in publish_output_raw
    self._publish_output_raw(o)
  File "C:\Users\Alex\anaconda3\envs\fd_env\lib\site-packages\wandb\sdk\interface\interface_shared.py", line 38, in _publish_output_raw
    self._publish(rec)
  File "C:\Users\Alex\anaconda3\envs\fd_env\lib\site-packages\wandb\sdk\interface\interface_sock.py", line 39, in _publish
    self._sock_client.send_record_publish(record)
  File "C:\Users\Alex\anaconda3\envs\fd_env\lib\site-packages\wandb\sdk\lib\sock_client.py", line 170, in send_record_publish
    self.send_server_request(server_req)
  File "C:\Users\Alex\anaconda3\envs\fd_env\lib\site-packages\wandb\sdk\lib\sock_client.py", line 150, in send_server_request
    self._send_message(msg)
  File "C:\Users\Alex\anaconda3\envs\fd_env\lib\site-packages\wandb\sdk\lib\sock_client.py", line 147, in _send_message
    self._sendall_with_error_handle(header + data)
  File "C:\Users\Alex\anaconda3\envs\fd_env\lib\site-packages\wandb\sdk\lib\sock_client.py", line 126, in _sendall_with_error_handle
    sent = self._sock.send(data)
ConnectionResetError: [WinError 10054] Удаленный хост принудительно разорвал существующее подключение
2025-07-05 14:55:47,486 ERROR   MainThread:36952 [redirect.py:_on_write():664] [all runs] error in stderr callback
Traceback (most recent call last):
  File "C:\Users\Alex\anaconda3\envs\fd_env\lib\site-packages\wandb\sdk\lib\redirect.py", line 662, in _on_write
    cb(written_data)
  File "C:\Users\Alex\anaconda3\envs\fd_env\lib\site-packages\wandb\sdk\wandb_run.py", line 2385, in <lambda>
    lambda data: self._console_raw_callback("stderr", data),
  File "C:\Users\Alex\anaconda3\envs\fd_env\lib\site-packages\wandb\sdk\wandb_run.py", line 398, in wrapper
    return func(self, *args, **kwargs)
  File "C:\Users\Alex\anaconda3\envs\fd_env\lib\site-packages\wandb\sdk\wandb_run.py", line 456, in wrapper_fn
    return func(self, *args, **kwargs)
  File "C:\Users\Alex\anaconda3\envs\fd_env\lib\site-packages\wandb\sdk\wandb_run.py", line 1566, in _console_raw_callback
    self._backend.interface.publish_output_raw(name, data)
  File "C:\Users\Alex\anaconda3\envs\fd_env\lib\site-packages\wandb\sdk\interface\interface.py", line 771, in publish_output_raw
    self._publish_output_raw(o)
  File "C:\Users\Alex\anaconda3\envs\fd_env\lib\site-packages\wandb\sdk\interface\interface_shared.py", line 38, in _publish_output_raw
    self._publish(rec)
  File "C:\Users\Alex\anaconda3\envs\fd_env\lib\site-packages\wandb\sdk\interface\interface_sock.py", line 39, in _publish
    self._sock_client.send_record_publish(record)
  File "C:\Users\Alex\anaconda3\envs\fd_env\lib\site-packages\wandb\sdk\lib\sock_client.py", line 170, in send_record_publish
    self.send_server_request(server_req)
  File "C:\Users\Alex\anaconda3\envs\fd_env\lib\site-packages\wandb\sdk\lib\sock_client.py", line 150, in send_server_request
    self._send_message(msg)
  File "C:\Users\Alex\anaconda3\envs\fd_env\lib\site-packages\wandb\sdk\lib\sock_client.py", line 147, in _send_message
    self._sendall_with_error_handle(header + data)
  File "C:\Users\Alex\anaconda3\envs\fd_env\lib\site-packages\wandb\sdk\lib\sock_client.py", line 126, in _sendall_with_error_handle
    sent = self._sock.send(data)
ConnectionResetError: [WinError 10054] Удаленный хост принудительно разорвал существующее подключение
2025-07-05 14:55:47,487 ERROR   MainThread:36952 [redirect.py:_on_write():664] [all runs] error in stderr callback
Traceback (most recent call last):
  File "C:\Users\Alex\anaconda3\envs\fd_env\lib\site-packages\wandb\sdk\lib\redirect.py", line 662, in _on_write
    cb(written_data)
  File "C:\Users\Alex\anaconda3\envs\fd_env\lib\site-packages\wandb\sdk\wandb_run.py", line 2385, in <lambda>
    lambda data: self._console_raw_callback("stderr", data),
  File "C:\Users\Alex\anaconda3\envs\fd_env\lib\site-packages\wandb\sdk\wandb_run.py", line 398, in wrapper
    return func(self, *args, **kwargs)
  File "C:\Users\Alex\anaconda3\envs\fd_env\lib\site-packages\wandb\sdk\wandb_run.py", line 456, in wrapper_fn
    return func(self, *args, **kwargs)
  File "C:\Users\Alex\anaconda3\envs\fd_env\lib\site-packages\wandb\sdk\wandb_run.py", line 1566, in _console_raw_callback
    self._backend.interface.publish_output_raw(name, data)
  File "C:\Users\Alex\anaconda3\envs\fd_env\lib\site-packages\wandb\sdk\interface\interface.py", line 771, in publish_output_raw
    self._publish_output_raw(o)
  File "C:\Users\Alex\anaconda3\envs\fd_env\lib\site-packages\wandb\sdk\interface\interface_shared.py", line 38, in _publish_output_raw
    self._publish(rec)
  File "C:\Users\Alex\anaconda3\envs\fd_env\lib\site-packages\wandb\sdk\interface\interface_sock.py", line 39, in _publish
    self._sock_client.send_record_publish(record)
  File "C:\Users\Alex\anaconda3\envs\fd_env\lib\site-packages\wandb\sdk\lib\sock_client.py", line 170, in send_record_publish
    self.send_server_request(server_req)
  File "C:\Users\Alex\anaconda3\envs\fd_env\lib\site-packages\wandb\sdk\lib\sock_client.py", line 150, in send_server_request
    self._send_message(msg)
  File "C:\Users\Alex\anaconda3\envs\fd_env\lib\site-packages\wandb\sdk\lib\sock_client.py", line 147, in _send_message
    self._sendall_with_error_handle(header + data)
  File "C:\Users\Alex\anaconda3\envs\fd_env\lib\site-packages\wandb\sdk\lib\sock_client.py", line 126, in _sendall_with_error_handle
    sent = self._sock.send(data)
ConnectionResetError: [WinError 10054] Удаленный хост принудительно разорвал существующее подключение
2025-07-05 14:55:47,489 ERROR   MainThread:36952 [redirect.py:_on_write():664] [all runs] error in stderr callback
Traceback (most recent call last):
  File "C:\Users\Alex\anaconda3\envs\fd_env\lib\site-packages\wandb\sdk\lib\redirect.py", line 662, in _on_write
    cb(written_data)
  File "C:\Users\Alex\anaconda3\envs\fd_env\lib\site-packages\wandb\sdk\wandb_run.py", line 2385, in <lambda>
    lambda data: self._console_raw_callback("stderr", data),
  File "C:\Users\Alex\anaconda3\envs\fd_env\lib\site-packages\wandb\sdk\wandb_run.py", line 398, in wrapper
    return func(self, *args, **kwargs)
  File "C:\Users\Alex\anaconda3\envs\fd_env\lib\site-packages\wandb\sdk\wandb_run.py", line 456, in wrapper_fn
    return func(self, *args, **kwargs)
  File "C:\Users\Alex\anaconda3\envs\fd_env\lib\site-packages\wandb\sdk\wandb_run.py", line 1566, in _console_raw_callback
    self._backend.interface.publish_output_raw(name, data)
  File "C:\Users\Alex\anaconda3\envs\fd_env\lib\site-packages\wandb\sdk\interface\interface.py", line 771, in publish_output_raw
    self._publish_output_raw(o)
  File "C:\Users\Alex\anaconda3\envs\fd_env\lib\site-packages\wandb\sdk\interface\interface_shared.py", line 38, in _publish_output_raw
    self._publish(rec)
  File "C:\Users\Alex\anaconda3\envs\fd_env\lib\site-packages\wandb\sdk\interface\interface_sock.py", line 39, in _publish
    self._sock_client.send_record_publish(record)
  File "C:\Users\Alex\anaconda3\envs\fd_env\lib\site-packages\wandb\sdk\lib\sock_client.py", line 170, in send_record_publish
    self.send_server_request(server_req)
  File "C:\Users\Alex\anaconda3\envs\fd_env\lib\site-packages\wandb\sdk\lib\sock_client.py", line 150, in send_server_request
    self._send_message(msg)
  File "C:\Users\Alex\anaconda3\envs\fd_env\lib\site-packages\wandb\sdk\lib\sock_client.py", line 147, in _send_message
    self._sendall_with_error_handle(header + data)
  File "C:\Users\Alex\anaconda3\envs\fd_env\lib\site-packages\wandb\sdk\lib\sock_client.py", line 126, in _sendall_with_error_handle
    sent = self._sock.send(data)
ConnectionResetError: [WinError 10054] Удаленный хост принудительно разорвал существующее подключение
2025-07-05 14:55:47,490 ERROR   MainThread:36952 [redirect.py:_on_write():664] [all runs] error in stderr callback
Traceback (most recent call last):
  File "C:\Users\Alex\anaconda3\envs\fd_env\lib\site-packages\wandb\sdk\lib\redirect.py", line 662, in _on_write
    cb(written_data)
  File "C:\Users\Alex\anaconda3\envs\fd_env\lib\site-packages\wandb\sdk\wandb_run.py", line 2385, in <lambda>
    lambda data: self._console_raw_callback("stderr", data),
  File "C:\Users\Alex\anaconda3\envs\fd_env\lib\site-packages\wandb\sdk\wandb_run.py", line 398, in wrapper
    return func(self, *args, **kwargs)
  File "C:\Users\Alex\anaconda3\envs\fd_env\lib\site-packages\wandb\sdk\wandb_run.py", line 456, in wrapper_fn
    return func(self, *args, **kwargs)
  File "C:\Users\Alex\anaconda3\envs\fd_env\lib\site-packages\wandb\sdk\wandb_run.py", line 1566, in _console_raw_callback
    self._backend.interface.publish_output_raw(name, data)
  File "C:\Users\Alex\anaconda3\envs\fd_env\lib\site-packages\wandb\sdk\interface\interface.py", line 771, in publish_output_raw
    self._publish_output_raw(o)
  File "C:\Users\Alex\anaconda3\envs\fd_env\lib\site-packages\wandb\sdk\interface\interface_shared.py", line 38, in _publish_output_raw
    self._publish(rec)
  File "C:\Users\Alex\anaconda3\envs\fd_env\lib\site-packages\wandb\sdk\interface\interface_sock.py", line 39, in _publish
    self._sock_client.send_record_publish(record)
  File "C:\Users\Alex\anaconda3\envs\fd_env\lib\site-packages\wandb\sdk\lib\sock_client.py", line 170, in send_record_publish
    self.send_server_request(server_req)
  File "C:\Users\Alex\anaconda3\envs\fd_env\lib\site-packages\wandb\sdk\lib\sock_client.py", line 150, in send_server_request
    self._send_message(msg)
  File "C:\Users\Alex\anaconda3\envs\fd_env\lib\site-packages\wandb\sdk\lib\sock_client.py", line 147, in _send_message
    self._sendall_with_error_handle(header + data)
  File "C:\Users\Alex\anaconda3\envs\fd_env\lib\site-packages\wandb\sdk\lib\sock_client.py", line 126, in _sendall_with_error_handle
    sent = self._sock.send(data)
ConnectionResetError: [WinError 10054] Удаленный хост принудительно разорвал существующее подключение
2025-07-05 14:55:47,491 ERROR   MainThread:36952 [redirect.py:_on_write():664] [all runs] error in stderr callback
Traceback (most recent call last):
  File "C:\Users\Alex\anaconda3\envs\fd_env\lib\site-packages\wandb\sdk\lib\redirect.py", line 662, in _on_write
    cb(written_data)
  File "C:\Users\Alex\anaconda3\envs\fd_env\lib\site-packages\wandb\sdk\wandb_run.py", line 2385, in <lambda>
    lambda data: self._console_raw_callback("stderr", data),
  File "C:\Users\Alex\anaconda3\envs\fd_env\lib\site-packages\wandb\sdk\wandb_run.py", line 398, in wrapper
    return func(self, *args, **kwargs)
  File "C:\Users\Alex\anaconda3\envs\fd_env\lib\site-packages\wandb\sdk\wandb_run.py", line 456, in wrapper_fn
    return func(self, *args, **kwargs)
  File "C:\Users\Alex\anaconda3\envs\fd_env\lib\site-packages\wandb\sdk\wandb_run.py", line 1566, in _console_raw_callback
    self._backend.interface.publish_output_raw(name, data)
  File "C:\Users\Alex\anaconda3\envs\fd_env\lib\site-packages\wandb\sdk\interface\interface.py", line 771, in publish_output_raw
    self._publish_output_raw(o)
  File "C:\Users\Alex\anaconda3\envs\fd_env\lib\site-packages\wandb\sdk\interface\interface_shared.py", line 38, in _publish_output_raw
    self._publish(rec)
  File "C:\Users\Alex\anaconda3\envs\fd_env\lib\site-packages\wandb\sdk\interface\interface_sock.py", line 39, in _publish
    self._sock_client.send_record_publish(record)
  File "C:\Users\Alex\anaconda3\envs\fd_env\lib\site-packages\wandb\sdk\lib\sock_client.py", line 170, in send_record_publish
    self.send_server_request(server_req)
  File "C:\Users\Alex\anaconda3\envs\fd_env\lib\site-packages\wandb\sdk\lib\sock_client.py", line 150, in send_server_request
    self._send_message(msg)
  File "C:\Users\Alex\anaconda3\envs\fd_env\lib\site-packages\wandb\sdk\lib\sock_client.py", line 147, in _send_message
    self._sendall_with_error_handle(header + data)
  File "C:\Users\Alex\anaconda3\envs\fd_env\lib\site-packages\wandb\sdk\lib\sock_client.py", line 126, in _sendall_with_error_handle
    sent = self._sock.send(data)
ConnectionResetError: [WinError 10054] Удаленный хост принудительно разорвал существующее подключение
2025-07-05 14:55:47,492 ERROR   MainThread:36952 [redirect.py:_on_write():664] [all runs] error in stderr callback
Traceback (most recent call last):
  File "C:\Users\Alex\anaconda3\envs\fd_env\lib\site-packages\wandb\sdk\lib\redirect.py", line 662, in _on_write
    cb(written_data)
  File "C:\Users\Alex\anaconda3\envs\fd_env\lib\site-packages\wandb\sdk\wandb_run.py", line 2385, in <lambda>
    lambda data: self._console_raw_callback("stderr", data),
  File "C:\Users\Alex\anaconda3\envs\fd_env\lib\site-packages\wandb\sdk\wandb_run.py", line 398, in wrapper
    return func(self, *args, **kwargs)
  File "C:\Users\Alex\anaconda3\envs\fd_env\lib\site-packages\wandb\sdk\wandb_run.py", line 456, in wrapper_fn
    return func(self, *args, **kwargs)
  File "C:\Users\Alex\anaconda3\envs\fd_env\lib\site-packages\wandb\sdk\wandb_run.py", line 1566, in _console_raw_callback
    self._backend.interface.publish_output_raw(name, data)
  File "C:\Users\Alex\anaconda3\envs\fd_env\lib\site-packages\wandb\sdk\interface\interface.py", line 771, in publish_output_raw
    self._publish_output_raw(o)
  File "C:\Users\Alex\anaconda3\envs\fd_env\lib\site-packages\wandb\sdk\interface\interface_shared.py", line 38, in _publish_output_raw
    self._publish(rec)
  File "C:\Users\Alex\anaconda3\envs\fd_env\lib\site-packages\wandb\sdk\interface\interface_sock.py", line 39, in _publish
    self._sock_client.send_record_publish(record)
  File "C:\Users\Alex\anaconda3\envs\fd_env\lib\site-packages\wandb\sdk\lib\sock_client.py", line 170, in send_record_publish
    self.send_server_request(server_req)
  File "C:\Users\Alex\anaconda3\envs\fd_env\lib\site-packages\wandb\sdk\lib\sock_client.py", line 150, in send_server_request
    self._send_message(msg)
  File "C:\Users\Alex\anaconda3\envs\fd_env\lib\site-packages\wandb\sdk\lib\sock_client.py", line 147, in _send_message
    self._sendall_with_error_handle(header + data)
  File "C:\Users\Alex\anaconda3\envs\fd_env\lib\site-packages\wandb\sdk\lib\sock_client.py", line 126, in _sendall_with_error_handle
    sent = self._sock.send(data)
ConnectionResetError: [WinError 10054] Удаленный хост принудительно разорвал существующее подключение
2025-07-05 14:55:47,494 ERROR   MainThread:36952 [redirect.py:_on_write():664] [all runs] error in stderr callback
Traceback (most recent call last):
  File "C:\Users\Alex\anaconda3\envs\fd_env\lib\site-packages\wandb\sdk\lib\redirect.py", line 662, in _on_write
    cb(written_data)
  File "C:\Users\Alex\anaconda3\envs\fd_env\lib\site-packages\wandb\sdk\wandb_run.py", line 2385, in <lambda>
    lambda data: self._console_raw_callback("stderr", data),
  File "C:\Users\Alex\anaconda3\envs\fd_env\lib\site-packages\wandb\sdk\wandb_run.py", line 398, in wrapper
    return func(self, *args, **kwargs)
  File "C:\Users\Alex\anaconda3\envs\fd_env\lib\site-packages\wandb\sdk\wandb_run.py", line 456, in wrapper_fn
    return func(self, *args, **kwargs)
  File "C:\Users\Alex\anaconda3\envs\fd_env\lib\site-packages\wandb\sdk\wandb_run.py", line 1566, in _console_raw_callback
    self._backend.interface.publish_output_raw(name, data)
  File "C:\Users\Alex\anaconda3\envs\fd_env\lib\site-packages\wandb\sdk\interface\interface.py", line 771, in publish_output_raw
    self._publish_output_raw(o)
  File "C:\Users\Alex\anaconda3\envs\fd_env\lib\site-packages\wandb\sdk\interface\interface_shared.py", line 38, in _publish_output_raw
    self._publish(rec)
  File "C:\Users\Alex\anaconda3\envs\fd_env\lib\site-packages\wandb\sdk\interface\interface_sock.py", line 39, in _publish
    self._sock_client.send_record_publish(record)
  File "C:\Users\Alex\anaconda3\envs\fd_env\lib\site-packages\wandb\sdk\lib\sock_client.py", line 170, in send_record_publish
    self.send_server_request(server_req)
  File "C:\Users\Alex\anaconda3\envs\fd_env\lib\site-packages\wandb\sdk\lib\sock_client.py", line 150, in send_server_request
    self._send_message(msg)
  File "C:\Users\Alex\anaconda3\envs\fd_env\lib\site-packages\wandb\sdk\lib\sock_client.py", line 147, in _send_message
    self._sendall_with_error_handle(header + data)
  File "C:\Users\Alex\anaconda3\envs\fd_env\lib\site-packages\wandb\sdk\lib\sock_client.py", line 126, in _sendall_with_error_handle
    sent = self._sock.send(data)
ConnectionResetError: [WinError 10054] Удаленный хост принудительно разорвал существующее подключение
2025-07-05 14:55:47,495 ERROR   MainThread:36952 [redirect.py:_on_write():664] [all runs] error in stderr callback
Traceback (most recent call last):
  File "C:\Users\Alex\anaconda3\envs\fd_env\lib\site-packages\wandb\sdk\lib\redirect.py", line 662, in _on_write
    cb(written_data)
  File "C:\Users\Alex\anaconda3\envs\fd_env\lib\site-packages\wandb\sdk\wandb_run.py", line 2385, in <lambda>
    lambda data: self._console_raw_callback("stderr", data),
  File "C:\Users\Alex\anaconda3\envs\fd_env\lib\site-packages\wandb\sdk\wandb_run.py", line 398, in wrapper
    return func(self, *args, **kwargs)
  File "C:\Users\Alex\anaconda3\envs\fd_env\lib\site-packages\wandb\sdk\wandb_run.py", line 456, in wrapper_fn
    return func(self, *args, **kwargs)
  File "C:\Users\Alex\anaconda3\envs\fd_env\lib\site-packages\wandb\sdk\wandb_run.py", line 1566, in _console_raw_callback
    self._backend.interface.publish_output_raw(name, data)
  File "C:\Users\Alex\anaconda3\envs\fd_env\lib\site-packages\wandb\sdk\interface\interface.py", line 771, in publish_output_raw
    self._publish_output_raw(o)
  File "C:\Users\Alex\anaconda3\envs\fd_env\lib\site-packages\wandb\sdk\interface\interface_shared.py", line 38, in _publish_output_raw
    self._publish(rec)
  File "C:\Users\Alex\anaconda3\envs\fd_env\lib\site-packages\wandb\sdk\interface\interface_sock.py", line 39, in _publish
    self._sock_client.send_record_publish(record)
  File "C:\Users\Alex\anaconda3\envs\fd_env\lib\site-packages\wandb\sdk\lib\sock_client.py", line 170, in send_record_publish
    self.send_server_request(server_req)
  File "C:\Users\Alex\anaconda3\envs\fd_env\lib\site-packages\wandb\sdk\lib\sock_client.py", line 150, in send_server_request
    self._send_message(msg)
  File "C:\Users\Alex\anaconda3\envs\fd_env\lib\site-packages\wandb\sdk\lib\sock_client.py", line 147, in _send_message
    self._sendall_with_error_handle(header + data)
  File "C:\Users\Alex\anaconda3\envs\fd_env\lib\site-packages\wandb\sdk\lib\sock_client.py", line 126, in _sendall_with_error_handle
    sent = self._sock.send(data)
ConnectionResetError: [WinError 10054] Удаленный хост принудительно разорвал существующее подключение
2025-07-05 14:55:47,497 ERROR   MainThread:36952 [redirect.py:_on_write():664] [all runs] error in stderr callback
Traceback (most recent call last):
  File "C:\Users\Alex\anaconda3\envs\fd_env\lib\site-packages\wandb\sdk\lib\redirect.py", line 662, in _on_write
    cb(written_data)
  File "C:\Users\Alex\anaconda3\envs\fd_env\lib\site-packages\wandb\sdk\wandb_run.py", line 2385, in <lambda>
    lambda data: self._console_raw_callback("stderr", data),
  File "C:\Users\Alex\anaconda3\envs\fd_env\lib\site-packages\wandb\sdk\wandb_run.py", line 398, in wrapper
    return func(self, *args, **kwargs)
  File "C:\Users\Alex\anaconda3\envs\fd_env\lib\site-packages\wandb\sdk\wandb_run.py", line 456, in wrapper_fn
    return func(self, *args, **kwargs)
  File "C:\Users\Alex\anaconda3\envs\fd_env\lib\site-packages\wandb\sdk\wandb_run.py", line 1566, in _console_raw_callback
    self._backend.interface.publish_output_raw(name, data)
  File "C:\Users\Alex\anaconda3\envs\fd_env\lib\site-packages\wandb\sdk\interface\interface.py", line 771, in publish_output_raw
    self._publish_output_raw(o)
  File "C:\Users\Alex\anaconda3\envs\fd_env\lib\site-packages\wandb\sdk\interface\interface_shared.py", line 38, in _publish_output_raw
    self._publish(rec)
  File "C:\Users\Alex\anaconda3\envs\fd_env\lib\site-packages\wandb\sdk\interface\interface_sock.py", line 39, in _publish
    self._sock_client.send_record_publish(record)
  File "C:\Users\Alex\anaconda3\envs\fd_env\lib\site-packages\wandb\sdk\lib\sock_client.py", line 170, in send_record_publish
    self.send_server_request(server_req)
  File "C:\Users\Alex\anaconda3\envs\fd_env\lib\site-packages\wandb\sdk\lib\sock_client.py", line 150, in send_server_request
    self._send_message(msg)
  File "C:\Users\Alex\anaconda3\envs\fd_env\lib\site-packages\wandb\sdk\lib\sock_client.py", line 147, in _send_message
    self._sendall_with_error_handle(header + data)
  File "C:\Users\Alex\anaconda3\envs\fd_env\lib\site-packages\wandb\sdk\lib\sock_client.py", line 126, in _sendall_with_error_handle
    sent = self._sock.send(data)
ConnectionResetError: [WinError 10054] Удаленный хост принудительно разорвал существующее подключение
2025-07-05 14:55:47,498 ERROR   MainThread:36952 [redirect.py:_on_write():664] [all runs] error in stderr callback
Traceback (most recent call last):
  File "C:\Users\Alex\anaconda3\envs\fd_env\lib\site-packages\wandb\sdk\lib\redirect.py", line 662, in _on_write
    cb(written_data)
  File "C:\Users\Alex\anaconda3\envs\fd_env\lib\site-packages\wandb\sdk\wandb_run.py", line 2385, in <lambda>
    lambda data: self._console_raw_callback("stderr", data),
  File "C:\Users\Alex\anaconda3\envs\fd_env\lib\site-packages\wandb\sdk\wandb_run.py", line 398, in wrapper
    return func(self, *args, **kwargs)
  File "C:\Users\Alex\anaconda3\envs\fd_env\lib\site-packages\wandb\sdk\wandb_run.py", line 456, in wrapper_fn
    return func(self, *args, **kwargs)
  File "C:\Users\Alex\anaconda3\envs\fd_env\lib\site-packages\wandb\sdk\wandb_run.py", line 1566, in _console_raw_callback
    self._backend.interface.publish_output_raw(name, data)
  File "C:\Users\Alex\anaconda3\envs\fd_env\lib\site-packages\wandb\sdk\interface\interface.py", line 771, in publish_output_raw
    self._publish_output_raw(o)
  File "C:\Users\Alex\anaconda3\envs\fd_env\lib\site-packages\wandb\sdk\interface\interface_shared.py", line 38, in _publish_output_raw
    self._publish(rec)
  File "C:\Users\Alex\anaconda3\envs\fd_env\lib\site-packages\wandb\sdk\interface\interface_sock.py", line 39, in _publish
    self._sock_client.send_record_publish(record)
  File "C:\Users\Alex\anaconda3\envs\fd_env\lib\site-packages\wandb\sdk\lib\sock_client.py", line 170, in send_record_publish
    self.send_server_request(server_req)
  File "C:\Users\Alex\anaconda3\envs\fd_env\lib\site-packages\wandb\sdk\lib\sock_client.py", line 150, in send_server_request
    self._send_message(msg)
  File "C:\Users\Alex\anaconda3\envs\fd_env\lib\site-packages\wandb\sdk\lib\sock_client.py", line 147, in _send_message
    self._sendall_with_error_handle(header + data)
  File "C:\Users\Alex\anaconda3\envs\fd_env\lib\site-packages\wandb\sdk\lib\sock_client.py", line 126, in _sendall_with_error_handle
    sent = self._sock.send(data)
ConnectionResetError: [WinError 10054] Удаленный хост принудительно разорвал существующее подключение
2025-07-05 14:55:47,499 ERROR   MainThread:36952 [redirect.py:_on_write():664] [all runs] error in stderr callback
Traceback (most recent call last):
  File "C:\Users\Alex\anaconda3\envs\fd_env\lib\site-packages\wandb\sdk\lib\redirect.py", line 662, in _on_write
    cb(written_data)
  File "C:\Users\Alex\anaconda3\envs\fd_env\lib\site-packages\wandb\sdk\wandb_run.py", line 2385, in <lambda>
    lambda data: self._console_raw_callback("stderr", data),
  File "C:\Users\Alex\anaconda3\envs\fd_env\lib\site-packages\wandb\sdk\wandb_run.py", line 398, in wrapper
    return func(self, *args, **kwargs)
  File "C:\Users\Alex\anaconda3\envs\fd_env\lib\site-packages\wandb\sdk\wandb_run.py", line 456, in wrapper_fn
    return func(self, *args, **kwargs)
  File "C:\Users\Alex\anaconda3\envs\fd_env\lib\site-packages\wandb\sdk\wandb_run.py", line 1566, in _console_raw_callback
    self._backend.interface.publish_output_raw(name, data)
  File "C:\Users\Alex\anaconda3\envs\fd_env\lib\site-packages\wandb\sdk\interface\interface.py", line 771, in publish_output_raw
    self._publish_output_raw(o)
  File "C:\Users\Alex\anaconda3\envs\fd_env\lib\site-packages\wandb\sdk\interface\interface_shared.py", line 38, in _publish_output_raw
    self._publish(rec)
  File "C:\Users\Alex\anaconda3\envs\fd_env\lib\site-packages\wandb\sdk\interface\interface_sock.py", line 39, in _publish
    self._sock_client.send_record_publish(record)
  File "C:\Users\Alex\anaconda3\envs\fd_env\lib\site-packages\wandb\sdk\lib\sock_client.py", line 170, in send_record_publish
    self.send_server_request(server_req)
  File "C:\Users\Alex\anaconda3\envs\fd_env\lib\site-packages\wandb\sdk\lib\sock_client.py", line 150, in send_server_request
    self._send_message(msg)
  File "C:\Users\Alex\anaconda3\envs\fd_env\lib\site-packages\wandb\sdk\lib\sock_client.py", line 147, in _send_message
    self._sendall_with_error_handle(header + data)
  File "C:\Users\Alex\anaconda3\envs\fd_env\lib\site-packages\wandb\sdk\lib\sock_client.py", line 126, in _sendall_with_error_handle
    sent = self._sock.send(data)
ConnectionResetError: [WinError 10054] Удаленный хост принудительно разорвал существующее подключение
2025-07-05 14:55:47,501 ERROR   MainThread:36952 [redirect.py:_on_write():664] [all runs] error in stderr callback
Traceback (most recent call last):
  File "C:\Users\Alex\anaconda3\envs\fd_env\lib\site-packages\wandb\sdk\lib\redirect.py", line 662, in _on_write
    cb(written_data)
  File "C:\Users\Alex\anaconda3\envs\fd_env\lib\site-packages\wandb\sdk\wandb_run.py", line 2385, in <lambda>
    lambda data: self._console_raw_callback("stderr", data),
  File "C:\Users\Alex\anaconda3\envs\fd_env\lib\site-packages\wandb\sdk\wandb_run.py", line 398, in wrapper
    return func(self, *args, **kwargs)
  File "C:\Users\Alex\anaconda3\envs\fd_env\lib\site-packages\wandb\sdk\wandb_run.py", line 456, in wrapper_fn
    return func(self, *args, **kwargs)
  File "C:\Users\Alex\anaconda3\envs\fd_env\lib\site-packages\wandb\sdk\wandb_run.py", line 1566, in _console_raw_callback
    self._backend.interface.publish_output_raw(name, data)
  File "C:\Users\Alex\anaconda3\envs\fd_env\lib\site-packages\wandb\sdk\interface\interface.py", line 771, in publish_output_raw
    self._publish_output_raw(o)
  File "C:\Users\Alex\anaconda3\envs\fd_env\lib\site-packages\wandb\sdk\interface\interface_shared.py", line 38, in _publish_output_raw
    self._publish(rec)
  File "C:\Users\Alex\anaconda3\envs\fd_env\lib\site-packages\wandb\sdk\interface\interface_sock.py", line 39, in _publish
    self._sock_client.send_record_publish(record)
  File "C:\Users\Alex\anaconda3\envs\fd_env\lib\site-packages\wandb\sdk\lib\sock_client.py", line 170, in send_record_publish
    self.send_server_request(server_req)
  File "C:\Users\Alex\anaconda3\envs\fd_env\lib\site-packages\wandb\sdk\lib\sock_client.py", line 150, in send_server_request
    self._send_message(msg)
  File "C:\Users\Alex\anaconda3\envs\fd_env\lib\site-packages\wandb\sdk\lib\sock_client.py", line 147, in _send_message
    self._sendall_with_error_handle(header + data)
  File "C:\Users\Alex\anaconda3\envs\fd_env\lib\site-packages\wandb\sdk\lib\sock_client.py", line 126, in _sendall_with_error_handle
    sent = self._sock.send(data)
ConnectionResetError: [WinError 10054] Удаленный хост принудительно разорвал существующее подключение
2025-07-05 14:55:47,503 ERROR   MainThread:36952 [redirect.py:_on_write():664] [all runs] error in stderr callback
Traceback (most recent call last):
  File "C:\Users\Alex\anaconda3\envs\fd_env\lib\site-packages\wandb\sdk\lib\redirect.py", line 662, in _on_write
    cb(written_data)
  File "C:\Users\Alex\anaconda3\envs\fd_env\lib\site-packages\wandb\sdk\wandb_run.py", line 2385, in <lambda>
    lambda data: self._console_raw_callback("stderr", data),
  File "C:\Users\Alex\anaconda3\envs\fd_env\lib\site-packages\wandb\sdk\wandb_run.py", line 398, in wrapper
    return func(self, *args, **kwargs)
  File "C:\Users\Alex\anaconda3\envs\fd_env\lib\site-packages\wandb\sdk\wandb_run.py", line 456, in wrapper_fn
    return func(self, *args, **kwargs)
  File "C:\Users\Alex\anaconda3\envs\fd_env\lib\site-packages\wandb\sdk\wandb_run.py", line 1566, in _console_raw_callback
    self._backend.interface.publish_output_raw(name, data)
  File "C:\Users\Alex\anaconda3\envs\fd_env\lib\site-packages\wandb\sdk\interface\interface.py", line 771, in publish_output_raw
    self._publish_output_raw(o)
  File "C:\Users\Alex\anaconda3\envs\fd_env\lib\site-packages\wandb\sdk\interface\interface_shared.py", line 38, in _publish_output_raw
    self._publish(rec)
  File "C:\Users\Alex\anaconda3\envs\fd_env\lib\site-packages\wandb\sdk\interface\interface_sock.py", line 39, in _publish
    self._sock_client.send_record_publish(record)
  File "C:\Users\Alex\anaconda3\envs\fd_env\lib\site-packages\wandb\sdk\lib\sock_client.py", line 170, in send_record_publish
    self.send_server_request(server_req)
  File "C:\Users\Alex\anaconda3\envs\fd_env\lib\site-packages\wandb\sdk\lib\sock_client.py", line 150, in send_server_request
    self._send_message(msg)
  File "C:\Users\Alex\anaconda3\envs\fd_env\lib\site-packages\wandb\sdk\lib\sock_client.py", line 147, in _send_message
    self._sendall_with_error_handle(header + data)
  File "C:\Users\Alex\anaconda3\envs\fd_env\lib\site-packages\wandb\sdk\lib\sock_client.py", line 126, in _sendall_with_error_handle
    sent = self._sock.send(data)
ConnectionResetError: [WinError 10054] Удаленный хост принудительно разорвал существующее подключение
2025-07-05 14:55:47,504 ERROR   MainThread:36952 [redirect.py:_on_write():664] [all runs] error in stderr callback
Traceback (most recent call last):
  File "C:\Users\Alex\anaconda3\envs\fd_env\lib\site-packages\wandb\sdk\lib\redirect.py", line 662, in _on_write
    cb(written_data)
  File "C:\Users\Alex\anaconda3\envs\fd_env\lib\site-packages\wandb\sdk\wandb_run.py", line 2385, in <lambda>
    lambda data: self._console_raw_callback("stderr", data),
  File "C:\Users\Alex\anaconda3\envs\fd_env\lib\site-packages\wandb\sdk\wandb_run.py", line 398, in wrapper
    return func(self, *args, **kwargs)
  File "C:\Users\Alex\anaconda3\envs\fd_env\lib\site-packages\wandb\sdk\wandb_run.py", line 456, in wrapper_fn
    return func(self, *args, **kwargs)
  File "C:\Users\Alex\anaconda3\envs\fd_env\lib\site-packages\wandb\sdk\wandb_run.py", line 1566, in _console_raw_callback
    self._backend.interface.publish_output_raw(name, data)
  File "C:\Users\Alex\anaconda3\envs\fd_env\lib\site-packages\wandb\sdk\interface\interface.py", line 771, in publish_output_raw
    self._publish_output_raw(o)
  File "C:\Users\Alex\anaconda3\envs\fd_env\lib\site-packages\wandb\sdk\interface\interface_shared.py", line 38, in _publish_output_raw
    self._publish(rec)
  File "C:\Users\Alex\anaconda3\envs\fd_env\lib\site-packages\wandb\sdk\interface\interface_sock.py", line 39, in _publish
    self._sock_client.send_record_publish(record)
  File "C:\Users\Alex\anaconda3\envs\fd_env\lib\site-packages\wandb\sdk\lib\sock_client.py", line 170, in send_record_publish
    self.send_server_request(server_req)
  File "C:\Users\Alex\anaconda3\envs\fd_env\lib\site-packages\wandb\sdk\lib\sock_client.py", line 150, in send_server_request
    self._send_message(msg)
  File "C:\Users\Alex\anaconda3\envs\fd_env\lib\site-packages\wandb\sdk\lib\sock_client.py", line 147, in _send_message
    self._sendall_with_error_handle(header + data)
  File "C:\Users\Alex\anaconda3\envs\fd_env\lib\site-packages\wandb\sdk\lib\sock_client.py", line 126, in _sendall_with_error_handle
    sent = self._sock.send(data)
ConnectionResetError: [WinError 10054] Удаленный хост принудительно разорвал существующее подключение
2025-07-05 14:55:47,504 ERROR   MainThread:36952 [redirect.py:_on_write():664] [all runs] error in stderr callback
Traceback (most recent call last):
  File "C:\Users\Alex\anaconda3\envs\fd_env\lib\site-packages\wandb\sdk\lib\redirect.py", line 662, in _on_write
    cb(written_data)
  File "C:\Users\Alex\anaconda3\envs\fd_env\lib\site-packages\wandb\sdk\wandb_run.py", line 2385, in <lambda>
    lambda data: self._console_raw_callback("stderr", data),
  File "C:\Users\Alex\anaconda3\envs\fd_env\lib\site-packages\wandb\sdk\wandb_run.py", line 398, in wrapper
    return func(self, *args, **kwargs)
  File "C:\Users\Alex\anaconda3\envs\fd_env\lib\site-packages\wandb\sdk\wandb_run.py", line 456, in wrapper_fn
    return func(self, *args, **kwargs)
  File "C:\Users\Alex\anaconda3\envs\fd_env\lib\site-packages\wandb\sdk\wandb_run.py", line 1566, in _console_raw_callback
    self._backend.interface.publish_output_raw(name, data)
  File "C:\Users\Alex\anaconda3\envs\fd_env\lib\site-packages\wandb\sdk\interface\interface.py", line 771, in publish_output_raw
    self._publish_output_raw(o)
  File "C:\Users\Alex\anaconda3\envs\fd_env\lib\site-packages\wandb\sdk\interface\interface_shared.py", line 38, in _publish_output_raw
    self._publish(rec)
  File "C:\Users\Alex\anaconda3\envs\fd_env\lib\site-packages\wandb\sdk\interface\interface_sock.py", line 39, in _publish
    self._sock_client.send_record_publish(record)
  File "C:\Users\Alex\anaconda3\envs\fd_env\lib\site-packages\wandb\sdk\lib\sock_client.py", line 170, in send_record_publish
    self.send_server_request(server_req)
  File "C:\Users\Alex\anaconda3\envs\fd_env\lib\site-packages\wandb\sdk\lib\sock_client.py", line 150, in send_server_request
    self._send_message(msg)
  File "C:\Users\Alex\anaconda3\envs\fd_env\lib\site-packages\wandb\sdk\lib\sock_client.py", line 147, in _send_message
    self._sendall_with_error_handle(header + data)
  File "C:\Users\Alex\anaconda3\envs\fd_env\lib\site-packages\wandb\sdk\lib\sock_client.py", line 126, in _sendall_with_error_handle
    sent = self._sock.send(data)
ConnectionResetError: [WinError 10054] Удаленный хост принудительно разорвал существующее подключение
2025-07-05 14:55:47,505 ERROR   MainThread:36952 [redirect.py:_on_write():664] [all runs] error in stderr callback
Traceback (most recent call last):
  File "C:\Users\Alex\anaconda3\envs\fd_env\lib\site-packages\wandb\sdk\lib\redirect.py", line 662, in _on_write
    cb(written_data)
  File "C:\Users\Alex\anaconda3\envs\fd_env\lib\site-packages\wandb\sdk\wandb_run.py", line 2385, in <lambda>
    lambda data: self._console_raw_callback("stderr", data),
  File "C:\Users\Alex\anaconda3\envs\fd_env\lib\site-packages\wandb\sdk\wandb_run.py", line 398, in wrapper
    return func(self, *args, **kwargs)
  File "C:\Users\Alex\anaconda3\envs\fd_env\lib\site-packages\wandb\sdk\wandb_run.py", line 456, in wrapper_fn
    return func(self, *args, **kwargs)
  File "C:\Users\Alex\anaconda3\envs\fd_env\lib\site-packages\wandb\sdk\wandb_run.py", line 1566, in _console_raw_callback
    self._backend.interface.publish_output_raw(name, data)
  File "C:\Users\Alex\anaconda3\envs\fd_env\lib\site-packages\wandb\sdk\interface\interface.py", line 771, in publish_output_raw
    self._publish_output_raw(o)
  File "C:\Users\Alex\anaconda3\envs\fd_env\lib\site-packages\wandb\sdk\interface\interface_shared.py", line 38, in _publish_output_raw
    self._publish(rec)
  File "C:\Users\Alex\anaconda3\envs\fd_env\lib\site-packages\wandb\sdk\interface\interface_sock.py", line 39, in _publish
    self._sock_client.send_record_publish(record)
  File "C:\Users\Alex\anaconda3\envs\fd_env\lib\site-packages\wandb\sdk\lib\sock_client.py", line 170, in send_record_publish
    self.send_server_request(server_req)
  File "C:\Users\Alex\anaconda3\envs\fd_env\lib\site-packages\wandb\sdk\lib\sock_client.py", line 150, in send_server_request
    self._send_message(msg)
  File "C:\Users\Alex\anaconda3\envs\fd_env\lib\site-packages\wandb\sdk\lib\sock_client.py", line 147, in _send_message
    self._sendall_with_error_handle(header + data)
  File "C:\Users\Alex\anaconda3\envs\fd_env\lib\site-packages\wandb\sdk\lib\sock_client.py", line 126, in _sendall_with_error_handle
    sent = self._sock.send(data)
ConnectionResetError: [WinError 10054] Удаленный хост принудительно разорвал существующее подключение
2025-07-05 14:55:47,507 ERROR   MainThread:36952 [redirect.py:_on_write():664] [all runs] error in stderr callback
Traceback (most recent call last):
  File "C:\Users\Alex\anaconda3\envs\fd_env\lib\site-packages\wandb\sdk\lib\redirect.py", line 662, in _on_write
    cb(written_data)
  File "C:\Users\Alex\anaconda3\envs\fd_env\lib\site-packages\wandb\sdk\wandb_run.py", line 2385, in <lambda>
    lambda data: self._console_raw_callback("stderr", data),
  File "C:\Users\Alex\anaconda3\envs\fd_env\lib\site-packages\wandb\sdk\wandb_run.py", line 398, in wrapper
    return func(self, *args, **kwargs)
  File "C:\Users\Alex\anaconda3\envs\fd_env\lib\site-packages\wandb\sdk\wandb_run.py", line 456, in wrapper_fn
    return func(self, *args, **kwargs)
  File "C:\Users\Alex\anaconda3\envs\fd_env\lib\site-packages\wandb\sdk\wandb_run.py", line 1566, in _console_raw_callback
    self._backend.interface.publish_output_raw(name, data)
  File "C:\Users\Alex\anaconda3\envs\fd_env\lib\site-packages\wandb\sdk\interface\interface.py", line 771, in publish_output_raw
    self._publish_output_raw(o)
  File "C:\Users\Alex\anaconda3\envs\fd_env\lib\site-packages\wandb\sdk\interface\interface_shared.py", line 38, in _publish_output_raw
    self._publish(rec)
  File "C:\Users\Alex\anaconda3\envs\fd_env\lib\site-packages\wandb\sdk\interface\interface_sock.py", line 39, in _publish
    self._sock_client.send_record_publish(record)
  File "C:\Users\Alex\anaconda3\envs\fd_env\lib\site-packages\wandb\sdk\lib\sock_client.py", line 170, in send_record_publish
    self.send_server_request(server_req)
  File "C:\Users\Alex\anaconda3\envs\fd_env\lib\site-packages\wandb\sdk\lib\sock_client.py", line 150, in send_server_request
    self._send_message(msg)
  File "C:\Users\Alex\anaconda3\envs\fd_env\lib\site-packages\wandb\sdk\lib\sock_client.py", line 147, in _send_message
    self._sendall_with_error_handle(header + data)
  File "C:\Users\Alex\anaconda3\envs\fd_env\lib\site-packages\wandb\sdk\lib\sock_client.py", line 126, in _sendall_with_error_handle
    sent = self._sock.send(data)
ConnectionResetError: [WinError 10054] Удаленный хост принудительно разорвал существующее подключение
2025-07-05 14:55:47,508 ERROR   MainThread:36952 [redirect.py:_on_write():664] [all runs] error in stderr callback
Traceback (most recent call last):
  File "C:\Users\Alex\anaconda3\envs\fd_env\lib\site-packages\wandb\sdk\lib\redirect.py", line 662, in _on_write
    cb(written_data)
  File "C:\Users\Alex\anaconda3\envs\fd_env\lib\site-packages\wandb\sdk\wandb_run.py", line 2385, in <lambda>
    lambda data: self._console_raw_callback("stderr", data),
  File "C:\Users\Alex\anaconda3\envs\fd_env\lib\site-packages\wandb\sdk\wandb_run.py", line 398, in wrapper
    return func(self, *args, **kwargs)
  File "C:\Users\Alex\anaconda3\envs\fd_env\lib\site-packages\wandb\sdk\wandb_run.py", line 456, in wrapper_fn
    return func(self, *args, **kwargs)
  File "C:\Users\Alex\anaconda3\envs\fd_env\lib\site-packages\wandb\sdk\wandb_run.py", line 1566, in _console_raw_callback
    self._backend.interface.publish_output_raw(name, data)
  File "C:\Users\Alex\anaconda3\envs\fd_env\lib\site-packages\wandb\sdk\interface\interface.py", line 771, in publish_output_raw
    self._publish_output_raw(o)
  File "C:\Users\Alex\anaconda3\envs\fd_env\lib\site-packages\wandb\sdk\interface\interface_shared.py", line 38, in _publish_output_raw
    self._publish(rec)
  File "C:\Users\Alex\anaconda3\envs\fd_env\lib\site-packages\wandb\sdk\interface\interface_sock.py", line 39, in _publish
    self._sock_client.send_record_publish(record)
  File "C:\Users\Alex\anaconda3\envs\fd_env\lib\site-packages\wandb\sdk\lib\sock_client.py", line 170, in send_record_publish
    self.send_server_request(server_req)
  File "C:\Users\Alex\anaconda3\envs\fd_env\lib\site-packages\wandb\sdk\lib\sock_client.py", line 150, in send_server_request
    self._send_message(msg)
  File "C:\Users\Alex\anaconda3\envs\fd_env\lib\site-packages\wandb\sdk\lib\sock_client.py", line 147, in _send_message
    self._sendall_with_error_handle(header + data)
  File "C:\Users\Alex\anaconda3\envs\fd_env\lib\site-packages\wandb\sdk\lib\sock_client.py", line 126, in _sendall_with_error_handle
    sent = self._sock.send(data)
ConnectionResetError: [WinError 10054] Удаленный хост принудительно разорвал существующее подключение
2025-07-05 14:55:47,509 ERROR   MainThread:36952 [redirect.py:_on_write():664] [all runs] error in stderr callback
Traceback (most recent call last):
  File "C:\Users\Alex\anaconda3\envs\fd_env\lib\site-packages\wandb\sdk\lib\redirect.py", line 662, in _on_write
    cb(written_data)
  File "C:\Users\Alex\anaconda3\envs\fd_env\lib\site-packages\wandb\sdk\wandb_run.py", line 2385, in <lambda>
    lambda data: self._console_raw_callback("stderr", data),
  File "C:\Users\Alex\anaconda3\envs\fd_env\lib\site-packages\wandb\sdk\wandb_run.py", line 398, in wrapper
    return func(self, *args, **kwargs)
  File "C:\Users\Alex\anaconda3\envs\fd_env\lib\site-packages\wandb\sdk\wandb_run.py", line 456, in wrapper_fn
    return func(self, *args, **kwargs)
  File "C:\Users\Alex\anaconda3\envs\fd_env\lib\site-packages\wandb\sdk\wandb_run.py", line 1566, in _console_raw_callback
    self._backend.interface.publish_output_raw(name, data)
  File "C:\Users\Alex\anaconda3\envs\fd_env\lib\site-packages\wandb\sdk\interface\interface.py", line 771, in publish_output_raw
    self._publish_output_raw(o)
  File "C:\Users\Alex\anaconda3\envs\fd_env\lib\site-packages\wandb\sdk\interface\interface_shared.py", line 38, in _publish_output_raw
    self._publish(rec)
  File "C:\Users\Alex\anaconda3\envs\fd_env\lib\site-packages\wandb\sdk\interface\interface_sock.py", line 39, in _publish
    self._sock_client.send_record_publish(record)
  File "C:\Users\Alex\anaconda3\envs\fd_env\lib\site-packages\wandb\sdk\lib\sock_client.py", line 170, in send_record_publish
    self.send_server_request(server_req)
  File "C:\Users\Alex\anaconda3\envs\fd_env\lib\site-packages\wandb\sdk\lib\sock_client.py", line 150, in send_server_request
    self._send_message(msg)
  File "C:\Users\Alex\anaconda3\envs\fd_env\lib\site-packages\wandb\sdk\lib\sock_client.py", line 147, in _send_message
    self._sendall_with_error_handle(header + data)
  File "C:\Users\Alex\anaconda3\envs\fd_env\lib\site-packages\wandb\sdk\lib\sock_client.py", line 126, in _sendall_with_error_handle
    sent = self._sock.send(data)
ConnectionResetError: [WinError 10054] Удаленный хост принудительно разорвал существующее подключение
2025-07-05 14:55:47,510 ERROR   MainThread:36952 [redirect.py:_on_write():664] [all runs] error in stderr callback
Traceback (most recent call last):
  File "C:\Users\Alex\anaconda3\envs\fd_env\lib\site-packages\wandb\sdk\lib\redirect.py", line 662, in _on_write
    cb(written_data)
  File "C:\Users\Alex\anaconda3\envs\fd_env\lib\site-packages\wandb\sdk\wandb_run.py", line 2385, in <lambda>
    lambda data: self._console_raw_callback("stderr", data),
  File "C:\Users\Alex\anaconda3\envs\fd_env\lib\site-packages\wandb\sdk\wandb_run.py", line 398, in wrapper
    return func(self, *args, **kwargs)
  File "C:\Users\Alex\anaconda3\envs\fd_env\lib\site-packages\wandb\sdk\wandb_run.py", line 456, in wrapper_fn
    return func(self, *args, **kwargs)
  File "C:\Users\Alex\anaconda3\envs\fd_env\lib\site-packages\wandb\sdk\wandb_run.py", line 1566, in _console_raw_callback
    self._backend.interface.publish_output_raw(name, data)
  File "C:\Users\Alex\anaconda3\envs\fd_env\lib\site-packages\wandb\sdk\interface\interface.py", line 771, in publish_output_raw
    self._publish_output_raw(o)
  File "C:\Users\Alex\anaconda3\envs\fd_env\lib\site-packages\wandb\sdk\interface\interface_shared.py", line 38, in _publish_output_raw
    self._publish(rec)
  File "C:\Users\Alex\anaconda3\envs\fd_env\lib\site-packages\wandb\sdk\interface\interface_sock.py", line 39, in _publish
    self._sock_client.send_record_publish(record)
  File "C:\Users\Alex\anaconda3\envs\fd_env\lib\site-packages\wandb\sdk\lib\sock_client.py", line 170, in send_record_publish
    self.send_server_request(server_req)
  File "C:\Users\Alex\anaconda3\envs\fd_env\lib\site-packages\wandb\sdk\lib\sock_client.py", line 150, in send_server_request
    self._send_message(msg)
  File "C:\Users\Alex\anaconda3\envs\fd_env\lib\site-packages\wandb\sdk\lib\sock_client.py", line 147, in _send_message
    self._sendall_with_error_handle(header + data)
  File "C:\Users\Alex\anaconda3\envs\fd_env\lib\site-packages\wandb\sdk\lib\sock_client.py", line 126, in _sendall_with_error_handle
    sent = self._sock.send(data)
ConnectionResetError: [WinError 10054] Удаленный хост принудительно разорвал существующее подключение
2025-07-05 14:55:47,511 ERROR   MainThread:36952 [redirect.py:_on_write():664] [all runs] error in stderr callback
Traceback (most recent call last):
  File "C:\Users\Alex\anaconda3\envs\fd_env\lib\site-packages\wandb\sdk\lib\redirect.py", line 662, in _on_write
    cb(written_data)
  File "C:\Users\Alex\anaconda3\envs\fd_env\lib\site-packages\wandb\sdk\wandb_run.py", line 2385, in <lambda>
    lambda data: self._console_raw_callback("stderr", data),
  File "C:\Users\Alex\anaconda3\envs\fd_env\lib\site-packages\wandb\sdk\wandb_run.py", line 398, in wrapper
    return func(self, *args, **kwargs)
  File "C:\Users\Alex\anaconda3\envs\fd_env\lib\site-packages\wandb\sdk\wandb_run.py", line 456, in wrapper_fn
    return func(self, *args, **kwargs)
  File "C:\Users\Alex\anaconda3\envs\fd_env\lib\site-packages\wandb\sdk\wandb_run.py", line 1566, in _console_raw_callback
    self._backend.interface.publish_output_raw(name, data)
  File "C:\Users\Alex\anaconda3\envs\fd_env\lib\site-packages\wandb\sdk\interface\interface.py", line 771, in publish_output_raw
    self._publish_output_raw(o)
  File "C:\Users\Alex\anaconda3\envs\fd_env\lib\site-packages\wandb\sdk\interface\interface_shared.py", line 38, in _publish_output_raw
    self._publish(rec)
  File "C:\Users\Alex\anaconda3\envs\fd_env\lib\site-packages\wandb\sdk\interface\interface_sock.py", line 39, in _publish
    self._sock_client.send_record_publish(record)
  File "C:\Users\Alex\anaconda3\envs\fd_env\lib\site-packages\wandb\sdk\lib\sock_client.py", line 170, in send_record_publish
    self.send_server_request(server_req)
  File "C:\Users\Alex\anaconda3\envs\fd_env\lib\site-packages\wandb\sdk\lib\sock_client.py", line 150, in send_server_request
    self._send_message(msg)
  File "C:\Users\Alex\anaconda3\envs\fd_env\lib\site-packages\wandb\sdk\lib\sock_client.py", line 147, in _send_message
    self._sendall_with_error_handle(header + data)
  File "C:\Users\Alex\anaconda3\envs\fd_env\lib\site-packages\wandb\sdk\lib\sock_client.py", line 126, in _sendall_with_error_handle
    sent = self._sock.send(data)
ConnectionResetError: [WinError 10054] Удаленный хост принудительно разорвал существующее подключение
2025-07-05 14:55:47,512 ERROR   MainThread:36952 [redirect.py:_on_write():664] [all runs] error in stderr callback
Traceback (most recent call last):
  File "C:\Users\Alex\anaconda3\envs\fd_env\lib\site-packages\wandb\sdk\lib\redirect.py", line 662, in _on_write
    cb(written_data)
  File "C:\Users\Alex\anaconda3\envs\fd_env\lib\site-packages\wandb\sdk\wandb_run.py", line 2385, in <lambda>
    lambda data: self._console_raw_callback("stderr", data),
  File "C:\Users\Alex\anaconda3\envs\fd_env\lib\site-packages\wandb\sdk\wandb_run.py", line 398, in wrapper
    return func(self, *args, **kwargs)
  File "C:\Users\Alex\anaconda3\envs\fd_env\lib\site-packages\wandb\sdk\wandb_run.py", line 456, in wrapper_fn
    return func(self, *args, **kwargs)
  File "C:\Users\Alex\anaconda3\envs\fd_env\lib\site-packages\wandb\sdk\wandb_run.py", line 1566, in _console_raw_callback
    self._backend.interface.publish_output_raw(name, data)
  File "C:\Users\Alex\anaconda3\envs\fd_env\lib\site-packages\wandb\sdk\interface\interface.py", line 771, in publish_output_raw
    self._publish_output_raw(o)
  File "C:\Users\Alex\anaconda3\envs\fd_env\lib\site-packages\wandb\sdk\interface\interface_shared.py", line 38, in _publish_output_raw
    self._publish(rec)
  File "C:\Users\Alex\anaconda3\envs\fd_env\lib\site-packages\wandb\sdk\interface\interface_sock.py", line 39, in _publish
    self._sock_client.send_record_publish(record)
  File "C:\Users\Alex\anaconda3\envs\fd_env\lib\site-packages\wandb\sdk\lib\sock_client.py", line 170, in send_record_publish
    self.send_server_request(server_req)
  File "C:\Users\Alex\anaconda3\envs\fd_env\lib\site-packages\wandb\sdk\lib\sock_client.py", line 150, in send_server_request
    self._send_message(msg)
  File "C:\Users\Alex\anaconda3\envs\fd_env\lib\site-packages\wandb\sdk\lib\sock_client.py", line 147, in _send_message
    self._sendall_with_error_handle(header + data)
  File "C:\Users\Alex\anaconda3\envs\fd_env\lib\site-packages\wandb\sdk\lib\sock_client.py", line 126, in _sendall_with_error_handle
    sent = self._sock.send(data)
ConnectionResetError: [WinError 10054] Удаленный хост принудительно разорвал существующее подключение
2025-07-05 14:55:47,512 ERROR   MainThread:36952 [redirect.py:_on_write():664] [all runs] error in stderr callback
Traceback (most recent call last):
  File "C:\Users\Alex\anaconda3\envs\fd_env\lib\site-packages\wandb\sdk\lib\redirect.py", line 662, in _on_write
    cb(written_data)
  File "C:\Users\Alex\anaconda3\envs\fd_env\lib\site-packages\wandb\sdk\wandb_run.py", line 2385, in <lambda>
    lambda data: self._console_raw_callback("stderr", data),
  File "C:\Users\Alex\anaconda3\envs\fd_env\lib\site-packages\wandb\sdk\wandb_run.py", line 398, in wrapper
    return func(self, *args, **kwargs)
  File "C:\Users\Alex\anaconda3\envs\fd_env\lib\site-packages\wandb\sdk\wandb_run.py", line 456, in wrapper_fn
    return func(self, *args, **kwargs)
  File "C:\Users\Alex\anaconda3\envs\fd_env\lib\site-packages\wandb\sdk\wandb_run.py", line 1566, in _console_raw_callback
    self._backend.interface.publish_output_raw(name, data)
  File "C:\Users\Alex\anaconda3\envs\fd_env\lib\site-packages\wandb\sdk\interface\interface.py", line 771, in publish_output_raw
    self._publish_output_raw(o)
  File "C:\Users\Alex\anaconda3\envs\fd_env\lib\site-packages\wandb\sdk\interface\interface_shared.py", line 38, in _publish_output_raw
    self._publish(rec)
  File "C:\Users\Alex\anaconda3\envs\fd_env\lib\site-packages\wandb\sdk\interface\interface_sock.py", line 39, in _publish
    self._sock_client.send_record_publish(record)
  File "C:\Users\Alex\anaconda3\envs\fd_env\lib\site-packages\wandb\sdk\lib\sock_client.py", line 170, in send_record_publish
    self.send_server_request(server_req)
  File "C:\Users\Alex\anaconda3\envs\fd_env\lib\site-packages\wandb\sdk\lib\sock_client.py", line 150, in send_server_request
    self._send_message(msg)
  File "C:\Users\Alex\anaconda3\envs\fd_env\lib\site-packages\wandb\sdk\lib\sock_client.py", line 147, in _send_message
    self._sendall_with_error_handle(header + data)
  File "C:\Users\Alex\anaconda3\envs\fd_env\lib\site-packages\wandb\sdk\lib\sock_client.py", line 126, in _sendall_with_error_handle
    sent = self._sock.send(data)
ConnectionResetError: [WinError 10054] Удаленный хост принудительно разорвал существующее подключение
2025-07-05 14:55:47,514 ERROR   MainThread:36952 [redirect.py:_on_write():664] [all runs] error in stderr callback
Traceback (most recent call last):
  File "C:\Users\Alex\anaconda3\envs\fd_env\lib\site-packages\wandb\sdk\lib\redirect.py", line 662, in _on_write
    cb(written_data)
  File "C:\Users\Alex\anaconda3\envs\fd_env\lib\site-packages\wandb\sdk\wandb_run.py", line 2385, in <lambda>
    lambda data: self._console_raw_callback("stderr", data),
  File "C:\Users\Alex\anaconda3\envs\fd_env\lib\site-packages\wandb\sdk\wandb_run.py", line 398, in wrapper
    return func(self, *args, **kwargs)
  File "C:\Users\Alex\anaconda3\envs\fd_env\lib\site-packages\wandb\sdk\wandb_run.py", line 456, in wrapper_fn
    return func(self, *args, **kwargs)
  File "C:\Users\Alex\anaconda3\envs\fd_env\lib\site-packages\wandb\sdk\wandb_run.py", line 1566, in _console_raw_callback
    self._backend.interface.publish_output_raw(name, data)
  File "C:\Users\Alex\anaconda3\envs\fd_env\lib\site-packages\wandb\sdk\interface\interface.py", line 771, in publish_output_raw
    self._publish_output_raw(o)
  File "C:\Users\Alex\anaconda3\envs\fd_env\lib\site-packages\wandb\sdk\interface\interface_shared.py", line 38, in _publish_output_raw
    self._publish(rec)
  File "C:\Users\Alex\anaconda3\envs\fd_env\lib\site-packages\wandb\sdk\interface\interface_sock.py", line 39, in _publish
    self._sock_client.send_record_publish(record)
  File "C:\Users\Alex\anaconda3\envs\fd_env\lib\site-packages\wandb\sdk\lib\sock_client.py", line 170, in send_record_publish
    self.send_server_request(server_req)
  File "C:\Users\Alex\anaconda3\envs\fd_env\lib\site-packages\wandb\sdk\lib\sock_client.py", line 150, in send_server_request
    self._send_message(msg)
  File "C:\Users\Alex\anaconda3\envs\fd_env\lib\site-packages\wandb\sdk\lib\sock_client.py", line 147, in _send_message
    self._sendall_with_error_handle(header + data)
  File "C:\Users\Alex\anaconda3\envs\fd_env\lib\site-packages\wandb\sdk\lib\sock_client.py", line 126, in _sendall_with_error_handle
    sent = self._sock.send(data)
ConnectionResetError: [WinError 10054] Удаленный хост принудительно разорвал существующее подключение
2025-07-05 14:55:47,514 ERROR   MainThread:36952 [redirect.py:_on_write():664] [all runs] error in stderr callback
Traceback (most recent call last):
  File "C:\Users\Alex\anaconda3\envs\fd_env\lib\site-packages\wandb\sdk\lib\redirect.py", line 662, in _on_write
    cb(written_data)
  File "C:\Users\Alex\anaconda3\envs\fd_env\lib\site-packages\wandb\sdk\wandb_run.py", line 2385, in <lambda>
    lambda data: self._console_raw_callback("stderr", data),
  File "C:\Users\Alex\anaconda3\envs\fd_env\lib\site-packages\wandb\sdk\wandb_run.py", line 398, in wrapper
    return func(self, *args, **kwargs)
  File "C:\Users\Alex\anaconda3\envs\fd_env\lib\site-packages\wandb\sdk\wandb_run.py", line 456, in wrapper_fn
    return func(self, *args, **kwargs)
  File "C:\Users\Alex\anaconda3\envs\fd_env\lib\site-packages\wandb\sdk\wandb_run.py", line 1566, in _console_raw_callback
    self._backend.interface.publish_output_raw(name, data)
  File "C:\Users\Alex\anaconda3\envs\fd_env\lib\site-packages\wandb\sdk\interface\interface.py", line 771, in publish_output_raw
    self._publish_output_raw(o)
  File "C:\Users\Alex\anaconda3\envs\fd_env\lib\site-packages\wandb\sdk\interface\interface_shared.py", line 38, in _publish_output_raw
    self._publish(rec)
  File "C:\Users\Alex\anaconda3\envs\fd_env\lib\site-packages\wandb\sdk\interface\interface_sock.py", line 39, in _publish
    self._sock_client.send_record_publish(record)
  File "C:\Users\Alex\anaconda3\envs\fd_env\lib\site-packages\wandb\sdk\lib\sock_client.py", line 170, in send_record_publish
    self.send_server_request(server_req)
  File "C:\Users\Alex\anaconda3\envs\fd_env\lib\site-packages\wandb\sdk\lib\sock_client.py", line 150, in send_server_request
    self._send_message(msg)
  File "C:\Users\Alex\anaconda3\envs\fd_env\lib\site-packages\wandb\sdk\lib\sock_client.py", line 147, in _send_message
    self._sendall_with_error_handle(header + data)
  File "C:\Users\Alex\anaconda3\envs\fd_env\lib\site-packages\wandb\sdk\lib\sock_client.py", line 126, in _sendall_with_error_handle
    sent = self._sock.send(data)
ConnectionResetError: [WinError 10054] Удаленный хост принудительно разорвал существующее подключение
2025-07-05 14:55:47,515 ERROR   MainThread:36952 [redirect.py:_on_write():664] [all runs] error in stderr callback
Traceback (most recent call last):
  File "C:\Users\Alex\anaconda3\envs\fd_env\lib\site-packages\wandb\sdk\lib\redirect.py", line 662, in _on_write
    cb(written_data)
  File "C:\Users\Alex\anaconda3\envs\fd_env\lib\site-packages\wandb\sdk\wandb_run.py", line 2385, in <lambda>
    lambda data: self._console_raw_callback("stderr", data),
  File "C:\Users\Alex\anaconda3\envs\fd_env\lib\site-packages\wandb\sdk\wandb_run.py", line 398, in wrapper
    return func(self, *args, **kwargs)
  File "C:\Users\Alex\anaconda3\envs\fd_env\lib\site-packages\wandb\sdk\wandb_run.py", line 456, in wrapper_fn
    return func(self, *args, **kwargs)
  File "C:\Users\Alex\anaconda3\envs\fd_env\lib\site-packages\wandb\sdk\wandb_run.py", line 1566, in _console_raw_callback
    self._backend.interface.publish_output_raw(name, data)
  File "C:\Users\Alex\anaconda3\envs\fd_env\lib\site-packages\wandb\sdk\interface\interface.py", line 771, in publish_output_raw
    self._publish_output_raw(o)
  File "C:\Users\Alex\anaconda3\envs\fd_env\lib\site-packages\wandb\sdk\interface\interface_shared.py", line 38, in _publish_output_raw
    self._publish(rec)
  File "C:\Users\Alex\anaconda3\envs\fd_env\lib\site-packages\wandb\sdk\interface\interface_sock.py", line 39, in _publish
    self._sock_client.send_record_publish(record)
  File "C:\Users\Alex\anaconda3\envs\fd_env\lib\site-packages\wandb\sdk\lib\sock_client.py", line 170, in send_record_publish
    self.send_server_request(server_req)
  File "C:\Users\Alex\anaconda3\envs\fd_env\lib\site-packages\wandb\sdk\lib\sock_client.py", line 150, in send_server_request
    self._send_message(msg)
  File "C:\Users\Alex\anaconda3\envs\fd_env\lib\site-packages\wandb\sdk\lib\sock_client.py", line 147, in _send_message
    self._sendall_with_error_handle(header + data)
  File "C:\Users\Alex\anaconda3\envs\fd_env\lib\site-packages\wandb\sdk\lib\sock_client.py", line 126, in _sendall_with_error_handle
    sent = self._sock.send(data)
ConnectionResetError: [WinError 10054] Удаленный хост принудительно разорвал существующее подключение
2025-07-05 14:55:47,517 ERROR   MainThread:36952 [redirect.py:_on_write():664] [all runs] error in stderr callback
Traceback (most recent call last):
  File "C:\Users\Alex\anaconda3\envs\fd_env\lib\site-packages\wandb\sdk\lib\redirect.py", line 662, in _on_write
    cb(written_data)
  File "C:\Users\Alex\anaconda3\envs\fd_env\lib\site-packages\wandb\sdk\wandb_run.py", line 2385, in <lambda>
    lambda data: self._console_raw_callback("stderr", data),
  File "C:\Users\Alex\anaconda3\envs\fd_env\lib\site-packages\wandb\sdk\wandb_run.py", line 398, in wrapper
    return func(self, *args, **kwargs)
  File "C:\Users\Alex\anaconda3\envs\fd_env\lib\site-packages\wandb\sdk\wandb_run.py", line 456, in wrapper_fn
    return func(self, *args, **kwargs)
  File "C:\Users\Alex\anaconda3\envs\fd_env\lib\site-packages\wandb\sdk\wandb_run.py", line 1566, in _console_raw_callback
    self._backend.interface.publish_output_raw(name, data)
  File "C:\Users\Alex\anaconda3\envs\fd_env\lib\site-packages\wandb\sdk\interface\interface.py", line 771, in publish_output_raw
    self._publish_output_raw(o)
  File "C:\Users\Alex\anaconda3\envs\fd_env\lib\site-packages\wandb\sdk\interface\interface_shared.py", line 38, in _publish_output_raw
    self._publish(rec)
  File "C:\Users\Alex\anaconda3\envs\fd_env\lib\site-packages\wandb\sdk\interface\interface_sock.py", line 39, in _publish
    self._sock_client.send_record_publish(record)
  File "C:\Users\Alex\anaconda3\envs\fd_env\lib\site-packages\wandb\sdk\lib\sock_client.py", line 170, in send_record_publish
    self.send_server_request(server_req)
  File "C:\Users\Alex\anaconda3\envs\fd_env\lib\site-packages\wandb\sdk\lib\sock_client.py", line 150, in send_server_request
    self._send_message(msg)
  File "C:\Users\Alex\anaconda3\envs\fd_env\lib\site-packages\wandb\sdk\lib\sock_client.py", line 147, in _send_message
    self._sendall_with_error_handle(header + data)
  File "C:\Users\Alex\anaconda3\envs\fd_env\lib\site-packages\wandb\sdk\lib\sock_client.py", line 126, in _sendall_with_error_handle
    sent = self._sock.send(data)
ConnectionResetError: [WinError 10054] Удаленный хост принудительно разорвал существующее подключение
2025-07-05 14:55:47,517 ERROR   MainThread:36952 [redirect.py:_on_write():664] [all runs] error in stderr callback
Traceback (most recent call last):
  File "C:\Users\Alex\anaconda3\envs\fd_env\lib\site-packages\wandb\sdk\lib\redirect.py", line 662, in _on_write
    cb(written_data)
  File "C:\Users\Alex\anaconda3\envs\fd_env\lib\site-packages\wandb\sdk\wandb_run.py", line 2385, in <lambda>
    lambda data: self._console_raw_callback("stderr", data),
  File "C:\Users\Alex\anaconda3\envs\fd_env\lib\site-packages\wandb\sdk\wandb_run.py", line 398, in wrapper
    return func(self, *args, **kwargs)
  File "C:\Users\Alex\anaconda3\envs\fd_env\lib\site-packages\wandb\sdk\wandb_run.py", line 456, in wrapper_fn
    return func(self, *args, **kwargs)
  File "C:\Users\Alex\anaconda3\envs\fd_env\lib\site-packages\wandb\sdk\wandb_run.py", line 1566, in _console_raw_callback
    self._backend.interface.publish_output_raw(name, data)
  File "C:\Users\Alex\anaconda3\envs\fd_env\lib\site-packages\wandb\sdk\interface\interface.py", line 771, in publish_output_raw
    self._publish_output_raw(o)
  File "C:\Users\Alex\anaconda3\envs\fd_env\lib\site-packages\wandb\sdk\interface\interface_shared.py", line 38, in _publish_output_raw
    self._publish(rec)
  File "C:\Users\Alex\anaconda3\envs\fd_env\lib\site-packages\wandb\sdk\interface\interface_sock.py", line 39, in _publish
    self._sock_client.send_record_publish(record)
  File "C:\Users\Alex\anaconda3\envs\fd_env\lib\site-packages\wandb\sdk\lib\sock_client.py", line 170, in send_record_publish
    self.send_server_request(server_req)
  File "C:\Users\Alex\anaconda3\envs\fd_env\lib\site-packages\wandb\sdk\lib\sock_client.py", line 150, in send_server_request
    self._send_message(msg)
  File "C:\Users\Alex\anaconda3\envs\fd_env\lib\site-packages\wandb\sdk\lib\sock_client.py", line 147, in _send_message
    self._sendall_with_error_handle(header + data)
  File "C:\Users\Alex\anaconda3\envs\fd_env\lib\site-packages\wandb\sdk\lib\sock_client.py", line 126, in _sendall_with_error_handle
    sent = self._sock.send(data)
ConnectionResetError: [WinError 10054] Удаленный хост принудительно разорвал существующее подключение
2025-07-05 14:55:47,518 ERROR   MainThread:36952 [redirect.py:_on_write():664] [all runs] error in stderr callback
Traceback (most recent call last):
  File "C:\Users\Alex\anaconda3\envs\fd_env\lib\site-packages\wandb\sdk\lib\redirect.py", line 662, in _on_write
    cb(written_data)
  File "C:\Users\Alex\anaconda3\envs\fd_env\lib\site-packages\wandb\sdk\wandb_run.py", line 2385, in <lambda>
    lambda data: self._console_raw_callback("stderr", data),
  File "C:\Users\Alex\anaconda3\envs\fd_env\lib\site-packages\wandb\sdk\wandb_run.py", line 398, in wrapper
    return func(self, *args, **kwargs)
  File "C:\Users\Alex\anaconda3\envs\fd_env\lib\site-packages\wandb\sdk\wandb_run.py", line 456, in wrapper_fn
    return func(self, *args, **kwargs)
  File "C:\Users\Alex\anaconda3\envs\fd_env\lib\site-packages\wandb\sdk\wandb_run.py", line 1566, in _console_raw_callback
    self._backend.interface.publish_output_raw(name, data)
  File "C:\Users\Alex\anaconda3\envs\fd_env\lib\site-packages\wandb\sdk\interface\interface.py", line 771, in publish_output_raw
    self._publish_output_raw(o)
  File "C:\Users\Alex\anaconda3\envs\fd_env\lib\site-packages\wandb\sdk\interface\interface_shared.py", line 38, in _publish_output_raw
    self._publish(rec)
  File "C:\Users\Alex\anaconda3\envs\fd_env\lib\site-packages\wandb\sdk\interface\interface_sock.py", line 39, in _publish
    self._sock_client.send_record_publish(record)
  File "C:\Users\Alex\anaconda3\envs\fd_env\lib\site-packages\wandb\sdk\lib\sock_client.py", line 170, in send_record_publish
    self.send_server_request(server_req)
  File "C:\Users\Alex\anaconda3\envs\fd_env\lib\site-packages\wandb\sdk\lib\sock_client.py", line 150, in send_server_request
    self._send_message(msg)
  File "C:\Users\Alex\anaconda3\envs\fd_env\lib\site-packages\wandb\sdk\lib\sock_client.py", line 147, in _send_message
    self._sendall_with_error_handle(header + data)
  File "C:\Users\Alex\anaconda3\envs\fd_env\lib\site-packages\wandb\sdk\lib\sock_client.py", line 126, in _sendall_with_error_handle
    sent = self._sock.send(data)
ConnectionResetError: [WinError 10054] Удаленный хост принудительно разорвал существующее подключение
2025-07-05 14:55:47,520 ERROR   MainThread:36952 [redirect.py:_on_write():664] [all runs] error in stderr callback
Traceback (most recent call last):
  File "C:\Users\Alex\anaconda3\envs\fd_env\lib\site-packages\wandb\sdk\lib\redirect.py", line 662, in _on_write
    cb(written_data)
  File "C:\Users\Alex\anaconda3\envs\fd_env\lib\site-packages\wandb\sdk\wandb_run.py", line 2385, in <lambda>
    lambda data: self._console_raw_callback("stderr", data),
  File "C:\Users\Alex\anaconda3\envs\fd_env\lib\site-packages\wandb\sdk\wandb_run.py", line 398, in wrapper
    return func(self, *args, **kwargs)
  File "C:\Users\Alex\anaconda3\envs\fd_env\lib\site-packages\wandb\sdk\wandb_run.py", line 456, in wrapper_fn
    return func(self, *args, **kwargs)
  File "C:\Users\Alex\anaconda3\envs\fd_env\lib\site-packages\wandb\sdk\wandb_run.py", line 1566, in _console_raw_callback
    self._backend.interface.publish_output_raw(name, data)
  File "C:\Users\Alex\anaconda3\envs\fd_env\lib\site-packages\wandb\sdk\interface\interface.py", line 771, in publish_output_raw
    self._publish_output_raw(o)
  File "C:\Users\Alex\anaconda3\envs\fd_env\lib\site-packages\wandb\sdk\interface\interface_shared.py", line 38, in _publish_output_raw
    self._publish(rec)
  File "C:\Users\Alex\anaconda3\envs\fd_env\lib\site-packages\wandb\sdk\interface\interface_sock.py", line 39, in _publish
    self._sock_client.send_record_publish(record)
  File "C:\Users\Alex\anaconda3\envs\fd_env\lib\site-packages\wandb\sdk\lib\sock_client.py", line 170, in send_record_publish
    self.send_server_request(server_req)
  File "C:\Users\Alex\anaconda3\envs\fd_env\lib\site-packages\wandb\sdk\lib\sock_client.py", line 150, in send_server_request
    self._send_message(msg)
  File "C:\Users\Alex\anaconda3\envs\fd_env\lib\site-packages\wandb\sdk\lib\sock_client.py", line 147, in _send_message
    self._sendall_with_error_handle(header + data)
  File "C:\Users\Alex\anaconda3\envs\fd_env\lib\site-packages\wandb\sdk\lib\sock_client.py", line 126, in _sendall_with_error_handle
    sent = self._sock.send(data)
ConnectionResetError: [WinError 10054] Удаленный хост принудительно разорвал существующее подключение
2025-07-05 14:55:47,521 ERROR   MainThread:36952 [redirect.py:_on_write():664] [all runs] error in stderr callback
Traceback (most recent call last):
  File "C:\Users\Alex\anaconda3\envs\fd_env\lib\site-packages\wandb\sdk\lib\redirect.py", line 662, in _on_write
    cb(written_data)
  File "C:\Users\Alex\anaconda3\envs\fd_env\lib\site-packages\wandb\sdk\wandb_run.py", line 2385, in <lambda>
    lambda data: self._console_raw_callback("stderr", data),
  File "C:\Users\Alex\anaconda3\envs\fd_env\lib\site-packages\wandb\sdk\wandb_run.py", line 398, in wrapper
    return func(self, *args, **kwargs)
  File "C:\Users\Alex\anaconda3\envs\fd_env\lib\site-packages\wandb\sdk\wandb_run.py", line 456, in wrapper_fn
    return func(self, *args, **kwargs)
  File "C:\Users\Alex\anaconda3\envs\fd_env\lib\site-packages\wandb\sdk\wandb_run.py", line 1566, in _console_raw_callback
    self._backend.interface.publish_output_raw(name, data)
  File "C:\Users\Alex\anaconda3\envs\fd_env\lib\site-packages\wandb\sdk\interface\interface.py", line 771, in publish_output_raw
    self._publish_output_raw(o)
  File "C:\Users\Alex\anaconda3\envs\fd_env\lib\site-packages\wandb\sdk\interface\interface_shared.py", line 38, in _publish_output_raw
    self._publish(rec)
  File "C:\Users\Alex\anaconda3\envs\fd_env\lib\site-packages\wandb\sdk\interface\interface_sock.py", line 39, in _publish
    self._sock_client.send_record_publish(record)
  File "C:\Users\Alex\anaconda3\envs\fd_env\lib\site-packages\wandb\sdk\lib\sock_client.py", line 170, in send_record_publish
    self.send_server_request(server_req)
  File "C:\Users\Alex\anaconda3\envs\fd_env\lib\site-packages\wandb\sdk\lib\sock_client.py", line 150, in send_server_request
    self._send_message(msg)
  File "C:\Users\Alex\anaconda3\envs\fd_env\lib\site-packages\wandb\sdk\lib\sock_client.py", line 147, in _send_message
    self._sendall_with_error_handle(header + data)
  File "C:\Users\Alex\anaconda3\envs\fd_env\lib\site-packages\wandb\sdk\lib\sock_client.py", line 126, in _sendall_with_error_handle
    sent = self._sock.send(data)
ConnectionResetError: [WinError 10054] Удаленный хост принудительно разорвал существующее подключение
2025-07-05 14:55:47,521 ERROR   MainThread:36952 [redirect.py:_on_write():664] [all runs] error in stderr callback
Traceback (most recent call last):
  File "C:\Users\Alex\anaconda3\envs\fd_env\lib\site-packages\wandb\sdk\lib\redirect.py", line 662, in _on_write
    cb(written_data)
  File "C:\Users\Alex\anaconda3\envs\fd_env\lib\site-packages\wandb\sdk\wandb_run.py", line 2385, in <lambda>
    lambda data: self._console_raw_callback("stderr", data),
  File "C:\Users\Alex\anaconda3\envs\fd_env\lib\site-packages\wandb\sdk\wandb_run.py", line 398, in wrapper
    return func(self, *args, **kwargs)
  File "C:\Users\Alex\anaconda3\envs\fd_env\lib\site-packages\wandb\sdk\wandb_run.py", line 456, in wrapper_fn
    return func(self, *args, **kwargs)
  File "C:\Users\Alex\anaconda3\envs\fd_env\lib\site-packages\wandb\sdk\wandb_run.py", line 1566, in _console_raw_callback
    self._backend.interface.publish_output_raw(name, data)
  File "C:\Users\Alex\anaconda3\envs\fd_env\lib\site-packages\wandb\sdk\interface\interface.py", line 771, in publish_output_raw
    self._publish_output_raw(o)
  File "C:\Users\Alex\anaconda3\envs\fd_env\lib\site-packages\wandb\sdk\interface\interface_shared.py", line 38, in _publish_output_raw
    self._publish(rec)
  File "C:\Users\Alex\anaconda3\envs\fd_env\lib\site-packages\wandb\sdk\interface\interface_sock.py", line 39, in _publish
    self._sock_client.send_record_publish(record)
  File "C:\Users\Alex\anaconda3\envs\fd_env\lib\site-packages\wandb\sdk\lib\sock_client.py", line 170, in send_record_publish
    self.send_server_request(server_req)
  File "C:\Users\Alex\anaconda3\envs\fd_env\lib\site-packages\wandb\sdk\lib\sock_client.py", line 150, in send_server_request
    self._send_message(msg)
  File "C:\Users\Alex\anaconda3\envs\fd_env\lib\site-packages\wandb\sdk\lib\sock_client.py", line 147, in _send_message
    self._sendall_with_error_handle(header + data)
  File "C:\Users\Alex\anaconda3\envs\fd_env\lib\site-packages\wandb\sdk\lib\sock_client.py", line 126, in _sendall_with_error_handle
    sent = self._sock.send(data)
ConnectionResetError: [WinError 10054] Удаленный хост принудительно разорвал существующее подключение
2025-07-05 14:55:47,522 ERROR   MainThread:36952 [redirect.py:_on_write():664] [all runs] error in stderr callback
Traceback (most recent call last):
  File "C:\Users\Alex\anaconda3\envs\fd_env\lib\site-packages\wandb\sdk\lib\redirect.py", line 662, in _on_write
    cb(written_data)
  File "C:\Users\Alex\anaconda3\envs\fd_env\lib\site-packages\wandb\sdk\wandb_run.py", line 2385, in <lambda>
    lambda data: self._console_raw_callback("stderr", data),
  File "C:\Users\Alex\anaconda3\envs\fd_env\lib\site-packages\wandb\sdk\wandb_run.py", line 398, in wrapper
    return func(self, *args, **kwargs)
  File "C:\Users\Alex\anaconda3\envs\fd_env\lib\site-packages\wandb\sdk\wandb_run.py", line 456, in wrapper_fn
    return func(self, *args, **kwargs)
  File "C:\Users\Alex\anaconda3\envs\fd_env\lib\site-packages\wandb\sdk\wandb_run.py", line 1566, in _console_raw_callback
    self._backend.interface.publish_output_raw(name, data)
  File "C:\Users\Alex\anaconda3\envs\fd_env\lib\site-packages\wandb\sdk\interface\interface.py", line 771, in publish_output_raw
    self._publish_output_raw(o)
  File "C:\Users\Alex\anaconda3\envs\fd_env\lib\site-packages\wandb\sdk\interface\interface_shared.py", line 38, in _publish_output_raw
    self._publish(rec)
  File "C:\Users\Alex\anaconda3\envs\fd_env\lib\site-packages\wandb\sdk\interface\interface_sock.py", line 39, in _publish
    self._sock_client.send_record_publish(record)
  File "C:\Users\Alex\anaconda3\envs\fd_env\lib\site-packages\wandb\sdk\lib\sock_client.py", line 170, in send_record_publish
    self.send_server_request(server_req)
  File "C:\Users\Alex\anaconda3\envs\fd_env\lib\site-packages\wandb\sdk\lib\sock_client.py", line 150, in send_server_request
    self._send_message(msg)
  File "C:\Users\Alex\anaconda3\envs\fd_env\lib\site-packages\wandb\sdk\lib\sock_client.py", line 147, in _send_message
    self._sendall_with_error_handle(header + data)
  File "C:\Users\Alex\anaconda3\envs\fd_env\lib\site-packages\wandb\sdk\lib\sock_client.py", line 126, in _sendall_with_error_handle
    sent = self._sock.send(data)
ConnectionResetError: [WinError 10054] Удаленный хост принудительно разорвал существующее подключение
2025-07-05 14:55:47,524 ERROR   MainThread:36952 [redirect.py:_on_write():664] [all runs] error in stderr callback
Traceback (most recent call last):
  File "C:\Users\Alex\anaconda3\envs\fd_env\lib\site-packages\wandb\sdk\lib\redirect.py", line 662, in _on_write
    cb(written_data)
  File "C:\Users\Alex\anaconda3\envs\fd_env\lib\site-packages\wandb\sdk\wandb_run.py", line 2385, in <lambda>
    lambda data: self._console_raw_callback("stderr", data),
  File "C:\Users\Alex\anaconda3\envs\fd_env\lib\site-packages\wandb\sdk\wandb_run.py", line 398, in wrapper
    return func(self, *args, **kwargs)
  File "C:\Users\Alex\anaconda3\envs\fd_env\lib\site-packages\wandb\sdk\wandb_run.py", line 456, in wrapper_fn
    return func(self, *args, **kwargs)
  File "C:\Users\Alex\anaconda3\envs\fd_env\lib\site-packages\wandb\sdk\wandb_run.py", line 1566, in _console_raw_callback
    self._backend.interface.publish_output_raw(name, data)
  File "C:\Users\Alex\anaconda3\envs\fd_env\lib\site-packages\wandb\sdk\interface\interface.py", line 771, in publish_output_raw
    self._publish_output_raw(o)
  File "C:\Users\Alex\anaconda3\envs\fd_env\lib\site-packages\wandb\sdk\interface\interface_shared.py", line 38, in _publish_output_raw
    self._publish(rec)
  File "C:\Users\Alex\anaconda3\envs\fd_env\lib\site-packages\wandb\sdk\interface\interface_sock.py", line 39, in _publish
    self._sock_client.send_record_publish(record)
  File "C:\Users\Alex\anaconda3\envs\fd_env\lib\site-packages\wandb\sdk\lib\sock_client.py", line 170, in send_record_publish
    self.send_server_request(server_req)
  File "C:\Users\Alex\anaconda3\envs\fd_env\lib\site-packages\wandb\sdk\lib\sock_client.py", line 150, in send_server_request
    self._send_message(msg)
  File "C:\Users\Alex\anaconda3\envs\fd_env\lib\site-packages\wandb\sdk\lib\sock_client.py", line 147, in _send_message
    self._sendall_with_error_handle(header + data)
  File "C:\Users\Alex\anaconda3\envs\fd_env\lib\site-packages\wandb\sdk\lib\sock_client.py", line 126, in _sendall_with_error_handle
    sent = self._sock.send(data)
ConnectionResetError: [WinError 10054] Удаленный хост принудительно разорвал существующее подключение
2025-07-05 14:55:47,524 ERROR   MainThread:36952 [redirect.py:_on_write():664] [all runs] error in stderr callback
Traceback (most recent call last):
  File "C:\Users\Alex\anaconda3\envs\fd_env\lib\site-packages\wandb\sdk\lib\redirect.py", line 662, in _on_write
    cb(written_data)
  File "C:\Users\Alex\anaconda3\envs\fd_env\lib\site-packages\wandb\sdk\wandb_run.py", line 2385, in <lambda>
    lambda data: self._console_raw_callback("stderr", data),
  File "C:\Users\Alex\anaconda3\envs\fd_env\lib\site-packages\wandb\sdk\wandb_run.py", line 398, in wrapper
    return func(self, *args, **kwargs)
  File "C:\Users\Alex\anaconda3\envs\fd_env\lib\site-packages\wandb\sdk\wandb_run.py", line 456, in wrapper_fn
    return func(self, *args, **kwargs)
  File "C:\Users\Alex\anaconda3\envs\fd_env\lib\site-packages\wandb\sdk\wandb_run.py", line 1566, in _console_raw_callback
    self._backend.interface.publish_output_raw(name, data)
  File "C:\Users\Alex\anaconda3\envs\fd_env\lib\site-packages\wandb\sdk\interface\interface.py", line 771, in publish_output_raw
    self._publish_output_raw(o)
  File "C:\Users\Alex\anaconda3\envs\fd_env\lib\site-packages\wandb\sdk\interface\interface_shared.py", line 38, in _publish_output_raw
    self._publish(rec)
  File "C:\Users\Alex\anaconda3\envs\fd_env\lib\site-packages\wandb\sdk\interface\interface_sock.py", line 39, in _publish
    self._sock_client.send_record_publish(record)
  File "C:\Users\Alex\anaconda3\envs\fd_env\lib\site-packages\wandb\sdk\lib\sock_client.py", line 170, in send_record_publish
    self.send_server_request(server_req)
  File "C:\Users\Alex\anaconda3\envs\fd_env\lib\site-packages\wandb\sdk\lib\sock_client.py", line 150, in send_server_request
    self._send_message(msg)
  File "C:\Users\Alex\anaconda3\envs\fd_env\lib\site-packages\wandb\sdk\lib\sock_client.py", line 147, in _send_message
    self._sendall_with_error_handle(header + data)
  File "C:\Users\Alex\anaconda3\envs\fd_env\lib\site-packages\wandb\sdk\lib\sock_client.py", line 126, in _sendall_with_error_handle
    sent = self._sock.send(data)
ConnectionResetError: [WinError 10054] Удаленный хост принудительно разорвал существующее подключение
2025-07-05 14:55:47,525 ERROR   MainThread:36952 [redirect.py:_on_write():664] [all runs] error in stderr callback
Traceback (most recent call last):
  File "C:\Users\Alex\anaconda3\envs\fd_env\lib\site-packages\wandb\sdk\lib\redirect.py", line 662, in _on_write
    cb(written_data)
  File "C:\Users\Alex\anaconda3\envs\fd_env\lib\site-packages\wandb\sdk\wandb_run.py", line 2385, in <lambda>
    lambda data: self._console_raw_callback("stderr", data),
  File "C:\Users\Alex\anaconda3\envs\fd_env\lib\site-packages\wandb\sdk\wandb_run.py", line 398, in wrapper
    return func(self, *args, **kwargs)
  File "C:\Users\Alex\anaconda3\envs\fd_env\lib\site-packages\wandb\sdk\wandb_run.py", line 456, in wrapper_fn
    return func(self, *args, **kwargs)
  File "C:\Users\Alex\anaconda3\envs\fd_env\lib\site-packages\wandb\sdk\wandb_run.py", line 1566, in _console_raw_callback
    self._backend.interface.publish_output_raw(name, data)
  File "C:\Users\Alex\anaconda3\envs\fd_env\lib\site-packages\wandb\sdk\interface\interface.py", line 771, in publish_output_raw
    self._publish_output_raw(o)
  File "C:\Users\Alex\anaconda3\envs\fd_env\lib\site-packages\wandb\sdk\interface\interface_shared.py", line 38, in _publish_output_raw
    self._publish(rec)
  File "C:\Users\Alex\anaconda3\envs\fd_env\lib\site-packages\wandb\sdk\interface\interface_sock.py", line 39, in _publish
    self._sock_client.send_record_publish(record)
  File "C:\Users\Alex\anaconda3\envs\fd_env\lib\site-packages\wandb\sdk\lib\sock_client.py", line 170, in send_record_publish
    self.send_server_request(server_req)
  File "C:\Users\Alex\anaconda3\envs\fd_env\lib\site-packages\wandb\sdk\lib\sock_client.py", line 150, in send_server_request
    self._send_message(msg)
  File "C:\Users\Alex\anaconda3\envs\fd_env\lib\site-packages\wandb\sdk\lib\sock_client.py", line 147, in _send_message
    self._sendall_with_error_handle(header + data)
  File "C:\Users\Alex\anaconda3\envs\fd_env\lib\site-packages\wandb\sdk\lib\sock_client.py", line 126, in _sendall_with_error_handle
    sent = self._sock.send(data)
ConnectionResetError: [WinError 10054] Удаленный хост принудительно разорвал существующее подключение
2025-07-05 14:55:47,525 ERROR   MainThread:36952 [redirect.py:_on_write():664] [all runs] error in stderr callback
Traceback (most recent call last):
  File "C:\Users\Alex\anaconda3\envs\fd_env\lib\site-packages\wandb\sdk\lib\redirect.py", line 662, in _on_write
    cb(written_data)
  File "C:\Users\Alex\anaconda3\envs\fd_env\lib\site-packages\wandb\sdk\wandb_run.py", line 2385, in <lambda>
    lambda data: self._console_raw_callback("stderr", data),
  File "C:\Users\Alex\anaconda3\envs\fd_env\lib\site-packages\wandb\sdk\wandb_run.py", line 398, in wrapper
    return func(self, *args, **kwargs)
  File "C:\Users\Alex\anaconda3\envs\fd_env\lib\site-packages\wandb\sdk\wandb_run.py", line 456, in wrapper_fn
    return func(self, *args, **kwargs)
  File "C:\Users\Alex\anaconda3\envs\fd_env\lib\site-packages\wandb\sdk\wandb_run.py", line 1566, in _console_raw_callback
    self._backend.interface.publish_output_raw(name, data)
  File "C:\Users\Alex\anaconda3\envs\fd_env\lib\site-packages\wandb\sdk\interface\interface.py", line 771, in publish_output_raw
    self._publish_output_raw(o)
  File "C:\Users\Alex\anaconda3\envs\fd_env\lib\site-packages\wandb\sdk\interface\interface_shared.py", line 38, in _publish_output_raw
    self._publish(rec)
  File "C:\Users\Alex\anaconda3\envs\fd_env\lib\site-packages\wandb\sdk\interface\interface_sock.py", line 39, in _publish
    self._sock_client.send_record_publish(record)
  File "C:\Users\Alex\anaconda3\envs\fd_env\lib\site-packages\wandb\sdk\lib\sock_client.py", line 170, in send_record_publish
    self.send_server_request(server_req)
  File "C:\Users\Alex\anaconda3\envs\fd_env\lib\site-packages\wandb\sdk\lib\sock_client.py", line 150, in send_server_request
    self._send_message(msg)
  File "C:\Users\Alex\anaconda3\envs\fd_env\lib\site-packages\wandb\sdk\lib\sock_client.py", line 147, in _send_message
    self._sendall_with_error_handle(header + data)
  File "C:\Users\Alex\anaconda3\envs\fd_env\lib\site-packages\wandb\sdk\lib\sock_client.py", line 126, in _sendall_with_error_handle
    sent = self._sock.send(data)
ConnectionResetError: [WinError 10054] Удаленный хост принудительно разорвал существующее подключение
2025-07-05 14:55:47,527 ERROR   MainThread:36952 [redirect.py:_on_write():664] [all runs] error in stderr callback
Traceback (most recent call last):
  File "C:\Users\Alex\anaconda3\envs\fd_env\lib\site-packages\wandb\sdk\lib\redirect.py", line 662, in _on_write
    cb(written_data)
  File "C:\Users\Alex\anaconda3\envs\fd_env\lib\site-packages\wandb\sdk\wandb_run.py", line 2385, in <lambda>
    lambda data: self._console_raw_callback("stderr", data),
  File "C:\Users\Alex\anaconda3\envs\fd_env\lib\site-packages\wandb\sdk\wandb_run.py", line 398, in wrapper
    return func(self, *args, **kwargs)
  File "C:\Users\Alex\anaconda3\envs\fd_env\lib\site-packages\wandb\sdk\wandb_run.py", line 456, in wrapper_fn
    return func(self, *args, **kwargs)
  File "C:\Users\Alex\anaconda3\envs\fd_env\lib\site-packages\wandb\sdk\wandb_run.py", line 1566, in _console_raw_callback
    self._backend.interface.publish_output_raw(name, data)
  File "C:\Users\Alex\anaconda3\envs\fd_env\lib\site-packages\wandb\sdk\interface\interface.py", line 771, in publish_output_raw
    self._publish_output_raw(o)
  File "C:\Users\Alex\anaconda3\envs\fd_env\lib\site-packages\wandb\sdk\interface\interface_shared.py", line 38, in _publish_output_raw
    self._publish(rec)
  File "C:\Users\Alex\anaconda3\envs\fd_env\lib\site-packages\wandb\sdk\interface\interface_sock.py", line 39, in _publish
    self._sock_client.send_record_publish(record)
  File "C:\Users\Alex\anaconda3\envs\fd_env\lib\site-packages\wandb\sdk\lib\sock_client.py", line 170, in send_record_publish
    self.send_server_request(server_req)
  File "C:\Users\Alex\anaconda3\envs\fd_env\lib\site-packages\wandb\sdk\lib\sock_client.py", line 150, in send_server_request
    self._send_message(msg)
  File "C:\Users\Alex\anaconda3\envs\fd_env\lib\site-packages\wandb\sdk\lib\sock_client.py", line 147, in _send_message
    self._sendall_with_error_handle(header + data)
  File "C:\Users\Alex\anaconda3\envs\fd_env\lib\site-packages\wandb\sdk\lib\sock_client.py", line 126, in _sendall_with_error_handle
    sent = self._sock.send(data)
ConnectionResetError: [WinError 10054] Удаленный хост принудительно разорвал существующее подключение
2025-07-05 14:55:47,527 ERROR   MainThread:36952 [redirect.py:_on_write():664] [all runs] error in stderr callback
Traceback (most recent call last):
  File "C:\Users\Alex\anaconda3\envs\fd_env\lib\site-packages\wandb\sdk\lib\redirect.py", line 662, in _on_write
    cb(written_data)
  File "C:\Users\Alex\anaconda3\envs\fd_env\lib\site-packages\wandb\sdk\wandb_run.py", line 2385, in <lambda>
    lambda data: self._console_raw_callback("stderr", data),
  File "C:\Users\Alex\anaconda3\envs\fd_env\lib\site-packages\wandb\sdk\wandb_run.py", line 398, in wrapper
    return func(self, *args, **kwargs)
  File "C:\Users\Alex\anaconda3\envs\fd_env\lib\site-packages\wandb\sdk\wandb_run.py", line 456, in wrapper_fn
    return func(self, *args, **kwargs)
  File "C:\Users\Alex\anaconda3\envs\fd_env\lib\site-packages\wandb\sdk\wandb_run.py", line 1566, in _console_raw_callback
    self._backend.interface.publish_output_raw(name, data)
  File "C:\Users\Alex\anaconda3\envs\fd_env\lib\site-packages\wandb\sdk\interface\interface.py", line 771, in publish_output_raw
    self._publish_output_raw(o)
  File "C:\Users\Alex\anaconda3\envs\fd_env\lib\site-packages\wandb\sdk\interface\interface_shared.py", line 38, in _publish_output_raw
    self._publish(rec)
  File "C:\Users\Alex\anaconda3\envs\fd_env\lib\site-packages\wandb\sdk\interface\interface_sock.py", line 39, in _publish
    self._sock_client.send_record_publish(record)
  File "C:\Users\Alex\anaconda3\envs\fd_env\lib\site-packages\wandb\sdk\lib\sock_client.py", line 170, in send_record_publish
    self.send_server_request(server_req)
  File "C:\Users\Alex\anaconda3\envs\fd_env\lib\site-packages\wandb\sdk\lib\sock_client.py", line 150, in send_server_request
    self._send_message(msg)
  File "C:\Users\Alex\anaconda3\envs\fd_env\lib\site-packages\wandb\sdk\lib\sock_client.py", line 147, in _send_message
    self._sendall_with_error_handle(header + data)
  File "C:\Users\Alex\anaconda3\envs\fd_env\lib\site-packages\wandb\sdk\lib\sock_client.py", line 126, in _sendall_with_error_handle
    sent = self._sock.send(data)
ConnectionResetError: [WinError 10054] Удаленный хост принудительно разорвал существующее подключение
2025-07-05 14:55:47,528 ERROR   MainThread:36952 [redirect.py:_on_write():664] [all runs] error in stderr callback
Traceback (most recent call last):
  File "C:\Users\Alex\anaconda3\envs\fd_env\lib\site-packages\wandb\sdk\lib\redirect.py", line 662, in _on_write
    cb(written_data)
  File "C:\Users\Alex\anaconda3\envs\fd_env\lib\site-packages\wandb\sdk\wandb_run.py", line 2385, in <lambda>
    lambda data: self._console_raw_callback("stderr", data),
  File "C:\Users\Alex\anaconda3\envs\fd_env\lib\site-packages\wandb\sdk\wandb_run.py", line 398, in wrapper
    return func(self, *args, **kwargs)
  File "C:\Users\Alex\anaconda3\envs\fd_env\lib\site-packages\wandb\sdk\wandb_run.py", line 456, in wrapper_fn
    return func(self, *args, **kwargs)
  File "C:\Users\Alex\anaconda3\envs\fd_env\lib\site-packages\wandb\sdk\wandb_run.py", line 1566, in _console_raw_callback
    self._backend.interface.publish_output_raw(name, data)
  File "C:\Users\Alex\anaconda3\envs\fd_env\lib\site-packages\wandb\sdk\interface\interface.py", line 771, in publish_output_raw
    self._publish_output_raw(o)
  File "C:\Users\Alex\anaconda3\envs\fd_env\lib\site-packages\wandb\sdk\interface\interface_shared.py", line 38, in _publish_output_raw
    self._publish(rec)
  File "C:\Users\Alex\anaconda3\envs\fd_env\lib\site-packages\wandb\sdk\interface\interface_sock.py", line 39, in _publish
    self._sock_client.send_record_publish(record)
  File "C:\Users\Alex\anaconda3\envs\fd_env\lib\site-packages\wandb\sdk\lib\sock_client.py", line 170, in send_record_publish
    self.send_server_request(server_req)
  File "C:\Users\Alex\anaconda3\envs\fd_env\lib\site-packages\wandb\sdk\lib\sock_client.py", line 150, in send_server_request
    self._send_message(msg)
  File "C:\Users\Alex\anaconda3\envs\fd_env\lib\site-packages\wandb\sdk\lib\sock_client.py", line 147, in _send_message
    self._sendall_with_error_handle(header + data)
  File "C:\Users\Alex\anaconda3\envs\fd_env\lib\site-packages\wandb\sdk\lib\sock_client.py", line 126, in _sendall_with_error_handle
    sent = self._sock.send(data)
ConnectionResetError: [WinError 10054] Удаленный хост принудительно разорвал существующее подключение
2025-07-05 14:55:47,529 ERROR   MainThread:36952 [redirect.py:_on_write():664] [all runs] error in stderr callback
Traceback (most recent call last):
  File "C:\Users\Alex\anaconda3\envs\fd_env\lib\site-packages\wandb\sdk\lib\redirect.py", line 662, in _on_write
    cb(written_data)
  File "C:\Users\Alex\anaconda3\envs\fd_env\lib\site-packages\wandb\sdk\wandb_run.py", line 2385, in <lambda>
    lambda data: self._console_raw_callback("stderr", data),
  File "C:\Users\Alex\anaconda3\envs\fd_env\lib\site-packages\wandb\sdk\wandb_run.py", line 398, in wrapper
    return func(self, *args, **kwargs)
  File "C:\Users\Alex\anaconda3\envs\fd_env\lib\site-packages\wandb\sdk\wandb_run.py", line 456, in wrapper_fn
    return func(self, *args, **kwargs)
  File "C:\Users\Alex\anaconda3\envs\fd_env\lib\site-packages\wandb\sdk\wandb_run.py", line 1566, in _console_raw_callback
    self._backend.interface.publish_output_raw(name, data)
  File "C:\Users\Alex\anaconda3\envs\fd_env\lib\site-packages\wandb\sdk\interface\interface.py", line 771, in publish_output_raw
    self._publish_output_raw(o)
  File "C:\Users\Alex\anaconda3\envs\fd_env\lib\site-packages\wandb\sdk\interface\interface_shared.py", line 38, in _publish_output_raw
    self._publish(rec)
  File "C:\Users\Alex\anaconda3\envs\fd_env\lib\site-packages\wandb\sdk\interface\interface_sock.py", line 39, in _publish
    self._sock_client.send_record_publish(record)
  File "C:\Users\Alex\anaconda3\envs\fd_env\lib\site-packages\wandb\sdk\lib\sock_client.py", line 170, in send_record_publish
    self.send_server_request(server_req)
  File "C:\Users\Alex\anaconda3\envs\fd_env\lib\site-packages\wandb\sdk\lib\sock_client.py", line 150, in send_server_request
    self._send_message(msg)
  File "C:\Users\Alex\anaconda3\envs\fd_env\lib\site-packages\wandb\sdk\lib\sock_client.py", line 147, in _send_message
    self._sendall_with_error_handle(header + data)
  File "C:\Users\Alex\anaconda3\envs\fd_env\lib\site-packages\wandb\sdk\lib\sock_client.py", line 126, in _sendall_with_error_handle
    sent = self._sock.send(data)
ConnectionResetError: [WinError 10054] Удаленный хост принудительно разорвал существующее подключение
2025-07-05 14:55:47,529 ERROR   MainThread:36952 [redirect.py:_on_write():664] [all runs] error in stderr callback
Traceback (most recent call last):
  File "C:\Users\Alex\anaconda3\envs\fd_env\lib\site-packages\wandb\sdk\lib\redirect.py", line 662, in _on_write
    cb(written_data)
  File "C:\Users\Alex\anaconda3\envs\fd_env\lib\site-packages\wandb\sdk\wandb_run.py", line 2385, in <lambda>
    lambda data: self._console_raw_callback("stderr", data),
  File "C:\Users\Alex\anaconda3\envs\fd_env\lib\site-packages\wandb\sdk\wandb_run.py", line 398, in wrapper
    return func(self, *args, **kwargs)
  File "C:\Users\Alex\anaconda3\envs\fd_env\lib\site-packages\wandb\sdk\wandb_run.py", line 456, in wrapper_fn
    return func(self, *args, **kwargs)
  File "C:\Users\Alex\anaconda3\envs\fd_env\lib\site-packages\wandb\sdk\wandb_run.py", line 1566, in _console_raw_callback
    self._backend.interface.publish_output_raw(name, data)
  File "C:\Users\Alex\anaconda3\envs\fd_env\lib\site-packages\wandb\sdk\interface\interface.py", line 771, in publish_output_raw
    self._publish_output_raw(o)
  File "C:\Users\Alex\anaconda3\envs\fd_env\lib\site-packages\wandb\sdk\interface\interface_shared.py", line 38, in _publish_output_raw
    self._publish(rec)
  File "C:\Users\Alex\anaconda3\envs\fd_env\lib\site-packages\wandb\sdk\interface\interface_sock.py", line 39, in _publish
    self._sock_client.send_record_publish(record)
  File "C:\Users\Alex\anaconda3\envs\fd_env\lib\site-packages\wandb\sdk\lib\sock_client.py", line 170, in send_record_publish
    self.send_server_request(server_req)
  File "C:\Users\Alex\anaconda3\envs\fd_env\lib\site-packages\wandb\sdk\lib\sock_client.py", line 150, in send_server_request
    self._send_message(msg)
  File "C:\Users\Alex\anaconda3\envs\fd_env\lib\site-packages\wandb\sdk\lib\sock_client.py", line 147, in _send_message
    self._sendall_with_error_handle(header + data)
  File "C:\Users\Alex\anaconda3\envs\fd_env\lib\site-packages\wandb\sdk\lib\sock_client.py", line 126, in _sendall_with_error_handle
    sent = self._sock.send(data)
ConnectionResetError: [WinError 10054] Удаленный хост принудительно разорвал существующее подключение
2025-07-05 14:55:47,530 ERROR   MainThread:36952 [redirect.py:_on_write():664] [all runs] error in stderr callback
Traceback (most recent call last):
  File "C:\Users\Alex\anaconda3\envs\fd_env\lib\site-packages\wandb\sdk\lib\redirect.py", line 662, in _on_write
    cb(written_data)
  File "C:\Users\Alex\anaconda3\envs\fd_env\lib\site-packages\wandb\sdk\wandb_run.py", line 2385, in <lambda>
    lambda data: self._console_raw_callback("stderr", data),
  File "C:\Users\Alex\anaconda3\envs\fd_env\lib\site-packages\wandb\sdk\wandb_run.py", line 398, in wrapper
    return func(self, *args, **kwargs)
  File "C:\Users\Alex\anaconda3\envs\fd_env\lib\site-packages\wandb\sdk\wandb_run.py", line 456, in wrapper_fn
    return func(self, *args, **kwargs)
  File "C:\Users\Alex\anaconda3\envs\fd_env\lib\site-packages\wandb\sdk\wandb_run.py", line 1566, in _console_raw_callback
    self._backend.interface.publish_output_raw(name, data)
  File "C:\Users\Alex\anaconda3\envs\fd_env\lib\site-packages\wandb\sdk\interface\interface.py", line 771, in publish_output_raw
    self._publish_output_raw(o)
  File "C:\Users\Alex\anaconda3\envs\fd_env\lib\site-packages\wandb\sdk\interface\interface_shared.py", line 38, in _publish_output_raw
    self._publish(rec)
  File "C:\Users\Alex\anaconda3\envs\fd_env\lib\site-packages\wandb\sdk\interface\interface_sock.py", line 39, in _publish
    self._sock_client.send_record_publish(record)
  File "C:\Users\Alex\anaconda3\envs\fd_env\lib\site-packages\wandb\sdk\lib\sock_client.py", line 170, in send_record_publish
    self.send_server_request(server_req)
  File "C:\Users\Alex\anaconda3\envs\fd_env\lib\site-packages\wandb\sdk\lib\sock_client.py", line 150, in send_server_request
    self._send_message(msg)
  File "C:\Users\Alex\anaconda3\envs\fd_env\lib\site-packages\wandb\sdk\lib\sock_client.py", line 147, in _send_message
    self._sendall_with_error_handle(header + data)
  File "C:\Users\Alex\anaconda3\envs\fd_env\lib\site-packages\wandb\sdk\lib\sock_client.py", line 126, in _sendall_with_error_handle
    sent = self._sock.send(data)
ConnectionResetError: [WinError 10054] Удаленный хост принудительно разорвал существующее подключение
2025-07-05 14:55:47,532 ERROR   MainThread:36952 [redirect.py:_on_write():664] [all runs] error in stderr callback
Traceback (most recent call last):
  File "C:\Users\Alex\anaconda3\envs\fd_env\lib\site-packages\wandb\sdk\lib\redirect.py", line 662, in _on_write
    cb(written_data)
  File "C:\Users\Alex\anaconda3\envs\fd_env\lib\site-packages\wandb\sdk\wandb_run.py", line 2385, in <lambda>
    lambda data: self._console_raw_callback("stderr", data),
  File "C:\Users\Alex\anaconda3\envs\fd_env\lib\site-packages\wandb\sdk\wandb_run.py", line 398, in wrapper
    return func(self, *args, **kwargs)
  File "C:\Users\Alex\anaconda3\envs\fd_env\lib\site-packages\wandb\sdk\wandb_run.py", line 456, in wrapper_fn
    return func(self, *args, **kwargs)
  File "C:\Users\Alex\anaconda3\envs\fd_env\lib\site-packages\wandb\sdk\wandb_run.py", line 1566, in _console_raw_callback
    self._backend.interface.publish_output_raw(name, data)
  File "C:\Users\Alex\anaconda3\envs\fd_env\lib\site-packages\wandb\sdk\interface\interface.py", line 771, in publish_output_raw
    self._publish_output_raw(o)
  File "C:\Users\Alex\anaconda3\envs\fd_env\lib\site-packages\wandb\sdk\interface\interface_shared.py", line 38, in _publish_output_raw
    self._publish(rec)
  File "C:\Users\Alex\anaconda3\envs\fd_env\lib\site-packages\wandb\sdk\interface\interface_sock.py", line 39, in _publish
    self._sock_client.send_record_publish(record)
  File "C:\Users\Alex\anaconda3\envs\fd_env\lib\site-packages\wandb\sdk\lib\sock_client.py", line 170, in send_record_publish
    self.send_server_request(server_req)
  File "C:\Users\Alex\anaconda3\envs\fd_env\lib\site-packages\wandb\sdk\lib\sock_client.py", line 150, in send_server_request
    self._send_message(msg)
  File "C:\Users\Alex\anaconda3\envs\fd_env\lib\site-packages\wandb\sdk\lib\sock_client.py", line 147, in _send_message
    self._sendall_with_error_handle(header + data)
  File "C:\Users\Alex\anaconda3\envs\fd_env\lib\site-packages\wandb\sdk\lib\sock_client.py", line 126, in _sendall_with_error_handle
    sent = self._sock.send(data)
ConnectionResetError: [WinError 10054] Удаленный хост принудительно разорвал существующее подключение
2025-07-05 14:55:47,532 ERROR   MainThread:36952 [redirect.py:_on_write():664] [all runs] error in stderr callback
Traceback (most recent call last):
  File "C:\Users\Alex\anaconda3\envs\fd_env\lib\site-packages\wandb\sdk\lib\redirect.py", line 662, in _on_write
    cb(written_data)
  File "C:\Users\Alex\anaconda3\envs\fd_env\lib\site-packages\wandb\sdk\wandb_run.py", line 2385, in <lambda>
    lambda data: self._console_raw_callback("stderr", data),
  File "C:\Users\Alex\anaconda3\envs\fd_env\lib\site-packages\wandb\sdk\wandb_run.py", line 398, in wrapper
    return func(self, *args, **kwargs)
  File "C:\Users\Alex\anaconda3\envs\fd_env\lib\site-packages\wandb\sdk\wandb_run.py", line 456, in wrapper_fn
    return func(self, *args, **kwargs)
  File "C:\Users\Alex\anaconda3\envs\fd_env\lib\site-packages\wandb\sdk\wandb_run.py", line 1566, in _console_raw_callback
    self._backend.interface.publish_output_raw(name, data)
  File "C:\Users\Alex\anaconda3\envs\fd_env\lib\site-packages\wandb\sdk\interface\interface.py", line 771, in publish_output_raw
    self._publish_output_raw(o)
  File "C:\Users\Alex\anaconda3\envs\fd_env\lib\site-packages\wandb\sdk\interface\interface_shared.py", line 38, in _publish_output_raw
    self._publish(rec)
  File "C:\Users\Alex\anaconda3\envs\fd_env\lib\site-packages\wandb\sdk\interface\interface_sock.py", line 39, in _publish
    self._sock_client.send_record_publish(record)
  File "C:\Users\Alex\anaconda3\envs\fd_env\lib\site-packages\wandb\sdk\lib\sock_client.py", line 170, in send_record_publish
    self.send_server_request(server_req)
  File "C:\Users\Alex\anaconda3\envs\fd_env\lib\site-packages\wandb\sdk\lib\sock_client.py", line 150, in send_server_request
    self._send_message(msg)
  File "C:\Users\Alex\anaconda3\envs\fd_env\lib\site-packages\wandb\sdk\lib\sock_client.py", line 147, in _send_message
    self._sendall_with_error_handle(header + data)
  File "C:\Users\Alex\anaconda3\envs\fd_env\lib\site-packages\wandb\sdk\lib\sock_client.py", line 126, in _sendall_with_error_handle
    sent = self._sock.send(data)
ConnectionResetError: [WinError 10054] Удаленный хост принудительно разорвал существующее подключение
2025-07-05 14:55:47,533 ERROR   MainThread:36952 [redirect.py:_on_write():664] [all runs] error in stderr callback
Traceback (most recent call last):
  File "C:\Users\Alex\anaconda3\envs\fd_env\lib\site-packages\wandb\sdk\lib\redirect.py", line 662, in _on_write
    cb(written_data)
  File "C:\Users\Alex\anaconda3\envs\fd_env\lib\site-packages\wandb\sdk\wandb_run.py", line 2385, in <lambda>
    lambda data: self._console_raw_callback("stderr", data),
  File "C:\Users\Alex\anaconda3\envs\fd_env\lib\site-packages\wandb\sdk\wandb_run.py", line 398, in wrapper
    return func(self, *args, **kwargs)
  File "C:\Users\Alex\anaconda3\envs\fd_env\lib\site-packages\wandb\sdk\wandb_run.py", line 456, in wrapper_fn
    return func(self, *args, **kwargs)
  File "C:\Users\Alex\anaconda3\envs\fd_env\lib\site-packages\wandb\sdk\wandb_run.py", line 1566, in _console_raw_callback
    self._backend.interface.publish_output_raw(name, data)
  File "C:\Users\Alex\anaconda3\envs\fd_env\lib\site-packages\wandb\sdk\interface\interface.py", line 771, in publish_output_raw
    self._publish_output_raw(o)
  File "C:\Users\Alex\anaconda3\envs\fd_env\lib\site-packages\wandb\sdk\interface\interface_shared.py", line 38, in _publish_output_raw
    self._publish(rec)
  File "C:\Users\Alex\anaconda3\envs\fd_env\lib\site-packages\wandb\sdk\interface\interface_sock.py", line 39, in _publish
    self._sock_client.send_record_publish(record)
  File "C:\Users\Alex\anaconda3\envs\fd_env\lib\site-packages\wandb\sdk\lib\sock_client.py", line 170, in send_record_publish
    self.send_server_request(server_req)
  File "C:\Users\Alex\anaconda3\envs\fd_env\lib\site-packages\wandb\sdk\lib\sock_client.py", line 150, in send_server_request
    self._send_message(msg)
  File "C:\Users\Alex\anaconda3\envs\fd_env\lib\site-packages\wandb\sdk\lib\sock_client.py", line 147, in _send_message
    self._sendall_with_error_handle(header + data)
  File "C:\Users\Alex\anaconda3\envs\fd_env\lib\site-packages\wandb\sdk\lib\sock_client.py", line 126, in _sendall_with_error_handle
    sent = self._sock.send(data)
ConnectionResetError: [WinError 10054] Удаленный хост принудительно разорвал существующее подключение
2025-07-05 14:55:47,534 ERROR   MainThread:36952 [redirect.py:_on_write():664] [all runs] error in stderr callback
Traceback (most recent call last):
  File "C:\Users\Alex\anaconda3\envs\fd_env\lib\site-packages\wandb\sdk\lib\redirect.py", line 662, in _on_write
    cb(written_data)
  File "C:\Users\Alex\anaconda3\envs\fd_env\lib\site-packages\wandb\sdk\wandb_run.py", line 2385, in <lambda>
    lambda data: self._console_raw_callback("stderr", data),
  File "C:\Users\Alex\anaconda3\envs\fd_env\lib\site-packages\wandb\sdk\wandb_run.py", line 398, in wrapper
    return func(self, *args, **kwargs)
  File "C:\Users\Alex\anaconda3\envs\fd_env\lib\site-packages\wandb\sdk\wandb_run.py", line 456, in wrapper_fn
    return func(self, *args, **kwargs)
  File "C:\Users\Alex\anaconda3\envs\fd_env\lib\site-packages\wandb\sdk\wandb_run.py", line 1566, in _console_raw_callback
    self._backend.interface.publish_output_raw(name, data)
  File "C:\Users\Alex\anaconda3\envs\fd_env\lib\site-packages\wandb\sdk\interface\interface.py", line 771, in publish_output_raw
    self._publish_output_raw(o)
  File "C:\Users\Alex\anaconda3\envs\fd_env\lib\site-packages\wandb\sdk\interface\interface_shared.py", line 38, in _publish_output_raw
    self._publish(rec)
  File "C:\Users\Alex\anaconda3\envs\fd_env\lib\site-packages\wandb\sdk\interface\interface_sock.py", line 39, in _publish
    self._sock_client.send_record_publish(record)
  File "C:\Users\Alex\anaconda3\envs\fd_env\lib\site-packages\wandb\sdk\lib\sock_client.py", line 170, in send_record_publish
    self.send_server_request(server_req)
  File "C:\Users\Alex\anaconda3\envs\fd_env\lib\site-packages\wandb\sdk\lib\sock_client.py", line 150, in send_server_request
    self._send_message(msg)
  File "C:\Users\Alex\anaconda3\envs\fd_env\lib\site-packages\wandb\sdk\lib\sock_client.py", line 147, in _send_message
    self._sendall_with_error_handle(header + data)
  File "C:\Users\Alex\anaconda3\envs\fd_env\lib\site-packages\wandb\sdk\lib\sock_client.py", line 126, in _sendall_with_error_handle
    sent = self._sock.send(data)
ConnectionResetError: [WinError 10054] Удаленный хост принудительно разорвал существующее подключение
2025-07-05 14:55:47,535 ERROR   MainThread:36952 [redirect.py:_on_write():664] [all runs] error in stderr callback
Traceback (most recent call last):
  File "C:\Users\Alex\anaconda3\envs\fd_env\lib\site-packages\wandb\sdk\lib\redirect.py", line 662, in _on_write
    cb(written_data)
  File "C:\Users\Alex\anaconda3\envs\fd_env\lib\site-packages\wandb\sdk\wandb_run.py", line 2385, in <lambda>
    lambda data: self._console_raw_callback("stderr", data),
  File "C:\Users\Alex\anaconda3\envs\fd_env\lib\site-packages\wandb\sdk\wandb_run.py", line 398, in wrapper
    return func(self, *args, **kwargs)
  File "C:\Users\Alex\anaconda3\envs\fd_env\lib\site-packages\wandb\sdk\wandb_run.py", line 456, in wrapper_fn
    return func(self, *args, **kwargs)
  File "C:\Users\Alex\anaconda3\envs\fd_env\lib\site-packages\wandb\sdk\wandb_run.py", line 1566, in _console_raw_callback
    self._backend.interface.publish_output_raw(name, data)
  File "C:\Users\Alex\anaconda3\envs\fd_env\lib\site-packages\wandb\sdk\interface\interface.py", line 771, in publish_output_raw
    self._publish_output_raw(o)
  File "C:\Users\Alex\anaconda3\envs\fd_env\lib\site-packages\wandb\sdk\interface\interface_shared.py", line 38, in _publish_output_raw
    self._publish(rec)
  File "C:\Users\Alex\anaconda3\envs\fd_env\lib\site-packages\wandb\sdk\interface\interface_sock.py", line 39, in _publish
    self._sock_client.send_record_publish(record)
  File "C:\Users\Alex\anaconda3\envs\fd_env\lib\site-packages\wandb\sdk\lib\sock_client.py", line 170, in send_record_publish
    self.send_server_request(server_req)
  File "C:\Users\Alex\anaconda3\envs\fd_env\lib\site-packages\wandb\sdk\lib\sock_client.py", line 150, in send_server_request
    self._send_message(msg)
  File "C:\Users\Alex\anaconda3\envs\fd_env\lib\site-packages\wandb\sdk\lib\sock_client.py", line 147, in _send_message
    self._sendall_with_error_handle(header + data)
  File "C:\Users\Alex\anaconda3\envs\fd_env\lib\site-packages\wandb\sdk\lib\sock_client.py", line 126, in _sendall_with_error_handle
    sent = self._sock.send(data)
ConnectionResetError: [WinError 10054] Удаленный хост принудительно разорвал существующее подключение
2025-07-05 14:55:47,536 ERROR   MainThread:36952 [redirect.py:_on_write():664] [all runs] error in stderr callback
Traceback (most recent call last):
  File "C:\Users\Alex\anaconda3\envs\fd_env\lib\site-packages\wandb\sdk\lib\redirect.py", line 662, in _on_write
    cb(written_data)
  File "C:\Users\Alex\anaconda3\envs\fd_env\lib\site-packages\wandb\sdk\wandb_run.py", line 2385, in <lambda>
    lambda data: self._console_raw_callback("stderr", data),
  File "C:\Users\Alex\anaconda3\envs\fd_env\lib\site-packages\wandb\sdk\wandb_run.py", line 398, in wrapper
    return func(self, *args, **kwargs)
  File "C:\Users\Alex\anaconda3\envs\fd_env\lib\site-packages\wandb\sdk\wandb_run.py", line 456, in wrapper_fn
    return func(self, *args, **kwargs)
  File "C:\Users\Alex\anaconda3\envs\fd_env\lib\site-packages\wandb\sdk\wandb_run.py", line 1566, in _console_raw_callback
    self._backend.interface.publish_output_raw(name, data)
  File "C:\Users\Alex\anaconda3\envs\fd_env\lib\site-packages\wandb\sdk\interface\interface.py", line 771, in publish_output_raw
    self._publish_output_raw(o)
  File "C:\Users\Alex\anaconda3\envs\fd_env\lib\site-packages\wandb\sdk\interface\interface_shared.py", line 38, in _publish_output_raw
    self._publish(rec)
  File "C:\Users\Alex\anaconda3\envs\fd_env\lib\site-packages\wandb\sdk\interface\interface_sock.py", line 39, in _publish
    self._sock_client.send_record_publish(record)
  File "C:\Users\Alex\anaconda3\envs\fd_env\lib\site-packages\wandb\sdk\lib\sock_client.py", line 170, in send_record_publish
    self.send_server_request(server_req)
  File "C:\Users\Alex\anaconda3\envs\fd_env\lib\site-packages\wandb\sdk\lib\sock_client.py", line 150, in send_server_request
    self._send_message(msg)
  File "C:\Users\Alex\anaconda3\envs\fd_env\lib\site-packages\wandb\sdk\lib\sock_client.py", line 147, in _send_message
    self._sendall_with_error_handle(header + data)
  File "C:\Users\Alex\anaconda3\envs\fd_env\lib\site-packages\wandb\sdk\lib\sock_client.py", line 126, in _sendall_with_error_handle
    sent = self._sock.send(data)
ConnectionResetError: [WinError 10054] Удаленный хост принудительно разорвал существующее подключение
2025-07-05 14:55:47,538 ERROR   MainThread:36952 [redirect.py:_on_write():664] [all runs] error in stderr callback
Traceback (most recent call last):
  File "C:\Users\Alex\anaconda3\envs\fd_env\lib\site-packages\wandb\sdk\lib\redirect.py", line 662, in _on_write
    cb(written_data)
  File "C:\Users\Alex\anaconda3\envs\fd_env\lib\site-packages\wandb\sdk\wandb_run.py", line 2385, in <lambda>
    lambda data: self._console_raw_callback("stderr", data),
  File "C:\Users\Alex\anaconda3\envs\fd_env\lib\site-packages\wandb\sdk\wandb_run.py", line 398, in wrapper
    return func(self, *args, **kwargs)
  File "C:\Users\Alex\anaconda3\envs\fd_env\lib\site-packages\wandb\sdk\wandb_run.py", line 456, in wrapper_fn
    return func(self, *args, **kwargs)
  File "C:\Users\Alex\anaconda3\envs\fd_env\lib\site-packages\wandb\sdk\wandb_run.py", line 1566, in _console_raw_callback
    self._backend.interface.publish_output_raw(name, data)
  File "C:\Users\Alex\anaconda3\envs\fd_env\lib\site-packages\wandb\sdk\interface\interface.py", line 771, in publish_output_raw
    self._publish_output_raw(o)
  File "C:\Users\Alex\anaconda3\envs\fd_env\lib\site-packages\wandb\sdk\interface\interface_shared.py", line 38, in _publish_output_raw
    self._publish(rec)
  File "C:\Users\Alex\anaconda3\envs\fd_env\lib\site-packages\wandb\sdk\interface\interface_sock.py", line 39, in _publish
    self._sock_client.send_record_publish(record)
  File "C:\Users\Alex\anaconda3\envs\fd_env\lib\site-packages\wandb\sdk\lib\sock_client.py", line 170, in send_record_publish
    self.send_server_request(server_req)
  File "C:\Users\Alex\anaconda3\envs\fd_env\lib\site-packages\wandb\sdk\lib\sock_client.py", line 150, in send_server_request
    self._send_message(msg)
  File "C:\Users\Alex\anaconda3\envs\fd_env\lib\site-packages\wandb\sdk\lib\sock_client.py", line 147, in _send_message
    self._sendall_with_error_handle(header + data)
  File "C:\Users\Alex\anaconda3\envs\fd_env\lib\site-packages\wandb\sdk\lib\sock_client.py", line 126, in _sendall_with_error_handle
    sent = self._sock.send(data)
ConnectionResetError: [WinError 10054] Удаленный хост принудительно разорвал существующее подключение
2025-07-05 14:55:47,539 ERROR   MainThread:36952 [redirect.py:_on_write():664] [all runs] error in stderr callback
Traceback (most recent call last):
  File "C:\Users\Alex\anaconda3\envs\fd_env\lib\site-packages\wandb\sdk\lib\redirect.py", line 662, in _on_write
    cb(written_data)
  File "C:\Users\Alex\anaconda3\envs\fd_env\lib\site-packages\wandb\sdk\wandb_run.py", line 2385, in <lambda>
    lambda data: self._console_raw_callback("stderr", data),
  File "C:\Users\Alex\anaconda3\envs\fd_env\lib\site-packages\wandb\sdk\wandb_run.py", line 398, in wrapper
    return func(self, *args, **kwargs)
  File "C:\Users\Alex\anaconda3\envs\fd_env\lib\site-packages\wandb\sdk\wandb_run.py", line 456, in wrapper_fn
    return func(self, *args, **kwargs)
  File "C:\Users\Alex\anaconda3\envs\fd_env\lib\site-packages\wandb\sdk\wandb_run.py", line 1566, in _console_raw_callback
    self._backend.interface.publish_output_raw(name, data)
  File "C:\Users\Alex\anaconda3\envs\fd_env\lib\site-packages\wandb\sdk\interface\interface.py", line 771, in publish_output_raw
    self._publish_output_raw(o)
  File "C:\Users\Alex\anaconda3\envs\fd_env\lib\site-packages\wandb\sdk\interface\interface_shared.py", line 38, in _publish_output_raw
    self._publish(rec)
  File "C:\Users\Alex\anaconda3\envs\fd_env\lib\site-packages\wandb\sdk\interface\interface_sock.py", line 39, in _publish
    self._sock_client.send_record_publish(record)
  File "C:\Users\Alex\anaconda3\envs\fd_env\lib\site-packages\wandb\sdk\lib\sock_client.py", line 170, in send_record_publish
    self.send_server_request(server_req)
  File "C:\Users\Alex\anaconda3\envs\fd_env\lib\site-packages\wandb\sdk\lib\sock_client.py", line 150, in send_server_request
    self._send_message(msg)
  File "C:\Users\Alex\anaconda3\envs\fd_env\lib\site-packages\wandb\sdk\lib\sock_client.py", line 147, in _send_message
    self._sendall_with_error_handle(header + data)
  File "C:\Users\Alex\anaconda3\envs\fd_env\lib\site-packages\wandb\sdk\lib\sock_client.py", line 126, in _sendall_with_error_handle
    sent = self._sock.send(data)
ConnectionResetError: [WinError 10054] Удаленный хост принудительно разорвал существующее подключение
2025-07-05 14:55:47,540 ERROR   MainThread:36952 [redirect.py:_on_write():664] [all runs] error in stderr callback
Traceback (most recent call last):
  File "C:\Users\Alex\anaconda3\envs\fd_env\lib\site-packages\wandb\sdk\lib\redirect.py", line 662, in _on_write
    cb(written_data)
  File "C:\Users\Alex\anaconda3\envs\fd_env\lib\site-packages\wandb\sdk\wandb_run.py", line 2385, in <lambda>
    lambda data: self._console_raw_callback("stderr", data),
  File "C:\Users\Alex\anaconda3\envs\fd_env\lib\site-packages\wandb\sdk\wandb_run.py", line 398, in wrapper
    return func(self, *args, **kwargs)
  File "C:\Users\Alex\anaconda3\envs\fd_env\lib\site-packages\wandb\sdk\wandb_run.py", line 456, in wrapper_fn
    return func(self, *args, **kwargs)
  File "C:\Users\Alex\anaconda3\envs\fd_env\lib\site-packages\wandb\sdk\wandb_run.py", line 1566, in _console_raw_callback
    self._backend.interface.publish_output_raw(name, data)
  File "C:\Users\Alex\anaconda3\envs\fd_env\lib\site-packages\wandb\sdk\interface\interface.py", line 771, in publish_output_raw
    self._publish_output_raw(o)
  File "C:\Users\Alex\anaconda3\envs\fd_env\lib\site-packages\wandb\sdk\interface\interface_shared.py", line 38, in _publish_output_raw
    self._publish(rec)
  File "C:\Users\Alex\anaconda3\envs\fd_env\lib\site-packages\wandb\sdk\interface\interface_sock.py", line 39, in _publish
    self._sock_client.send_record_publish(record)
  File "C:\Users\Alex\anaconda3\envs\fd_env\lib\site-packages\wandb\sdk\lib\sock_client.py", line 170, in send_record_publish
    self.send_server_request(server_req)
  File "C:\Users\Alex\anaconda3\envs\fd_env\lib\site-packages\wandb\sdk\lib\sock_client.py", line 150, in send_server_request
    self._send_message(msg)
  File "C:\Users\Alex\anaconda3\envs\fd_env\lib\site-packages\wandb\sdk\lib\sock_client.py", line 147, in _send_message
    self._sendall_with_error_handle(header + data)
  File "C:\Users\Alex\anaconda3\envs\fd_env\lib\site-packages\wandb\sdk\lib\sock_client.py", line 126, in _sendall_with_error_handle
    sent = self._sock.send(data)
ConnectionResetError: [WinError 10054] Удаленный хост принудительно разорвал существующее подключение
2025-07-05 14:55:47,541 ERROR   MainThread:36952 [redirect.py:_on_write():664] [all runs] error in stderr callback
Traceback (most recent call last):
  File "C:\Users\Alex\anaconda3\envs\fd_env\lib\site-packages\wandb\sdk\lib\redirect.py", line 662, in _on_write
    cb(written_data)
  File "C:\Users\Alex\anaconda3\envs\fd_env\lib\site-packages\wandb\sdk\wandb_run.py", line 2385, in <lambda>
    lambda data: self._console_raw_callback("stderr", data),
  File "C:\Users\Alex\anaconda3\envs\fd_env\lib\site-packages\wandb\sdk\wandb_run.py", line 398, in wrapper
    return func(self, *args, **kwargs)
  File "C:\Users\Alex\anaconda3\envs\fd_env\lib\site-packages\wandb\sdk\wandb_run.py", line 456, in wrapper_fn
    return func(self, *args, **kwargs)
  File "C:\Users\Alex\anaconda3\envs\fd_env\lib\site-packages\wandb\sdk\wandb_run.py", line 1566, in _console_raw_callback
    self._backend.interface.publish_output_raw(name, data)
  File "C:\Users\Alex\anaconda3\envs\fd_env\lib\site-packages\wandb\sdk\interface\interface.py", line 771, in publish_output_raw
    self._publish_output_raw(o)
  File "C:\Users\Alex\anaconda3\envs\fd_env\lib\site-packages\wandb\sdk\interface\interface_shared.py", line 38, in _publish_output_raw
    self._publish(rec)
  File "C:\Users\Alex\anaconda3\envs\fd_env\lib\site-packages\wandb\sdk\interface\interface_sock.py", line 39, in _publish
    self._sock_client.send_record_publish(record)
  File "C:\Users\Alex\anaconda3\envs\fd_env\lib\site-packages\wandb\sdk\lib\sock_client.py", line 170, in send_record_publish
    self.send_server_request(server_req)
  File "C:\Users\Alex\anaconda3\envs\fd_env\lib\site-packages\wandb\sdk\lib\sock_client.py", line 150, in send_server_request
    self._send_message(msg)
  File "C:\Users\Alex\anaconda3\envs\fd_env\lib\site-packages\wandb\sdk\lib\sock_client.py", line 147, in _send_message
    self._sendall_with_error_handle(header + data)
  File "C:\Users\Alex\anaconda3\envs\fd_env\lib\site-packages\wandb\sdk\lib\sock_client.py", line 126, in _sendall_with_error_handle
    sent = self._sock.send(data)
ConnectionResetError: [WinError 10054] Удаленный хост принудительно разорвал существующее подключение
2025-07-05 14:55:47,544 ERROR   MainThread:36952 [redirect.py:_on_write():664] [all runs] error in stderr callback
Traceback (most recent call last):
  File "C:\Users\Alex\anaconda3\envs\fd_env\lib\site-packages\wandb\sdk\lib\redirect.py", line 662, in _on_write
    cb(written_data)
  File "C:\Users\Alex\anaconda3\envs\fd_env\lib\site-packages\wandb\sdk\wandb_run.py", line 2385, in <lambda>
    lambda data: self._console_raw_callback("stderr", data),
  File "C:\Users\Alex\anaconda3\envs\fd_env\lib\site-packages\wandb\sdk\wandb_run.py", line 398, in wrapper
    return func(self, *args, **kwargs)
  File "C:\Users\Alex\anaconda3\envs\fd_env\lib\site-packages\wandb\sdk\wandb_run.py", line 456, in wrapper_fn
    return func(self, *args, **kwargs)
  File "C:\Users\Alex\anaconda3\envs\fd_env\lib\site-packages\wandb\sdk\wandb_run.py", line 1566, in _console_raw_callback
    self._backend.interface.publish_output_raw(name, data)
  File "C:\Users\Alex\anaconda3\envs\fd_env\lib\site-packages\wandb\sdk\interface\interface.py", line 771, in publish_output_raw
    self._publish_output_raw(o)
  File "C:\Users\Alex\anaconda3\envs\fd_env\lib\site-packages\wandb\sdk\interface\interface_shared.py", line 38, in _publish_output_raw
    self._publish(rec)
  File "C:\Users\Alex\anaconda3\envs\fd_env\lib\site-packages\wandb\sdk\interface\interface_sock.py", line 39, in _publish
    self._sock_client.send_record_publish(record)
  File "C:\Users\Alex\anaconda3\envs\fd_env\lib\site-packages\wandb\sdk\lib\sock_client.py", line 170, in send_record_publish
    self.send_server_request(server_req)
  File "C:\Users\Alex\anaconda3\envs\fd_env\lib\site-packages\wandb\sdk\lib\sock_client.py", line 150, in send_server_request
    self._send_message(msg)
  File "C:\Users\Alex\anaconda3\envs\fd_env\lib\site-packages\wandb\sdk\lib\sock_client.py", line 147, in _send_message
    self._sendall_with_error_handle(header + data)
  File "C:\Users\Alex\anaconda3\envs\fd_env\lib\site-packages\wandb\sdk\lib\sock_client.py", line 126, in _sendall_with_error_handle
    sent = self._sock.send(data)
ConnectionResetError: [WinError 10054] Удаленный хост принудительно разорвал существующее подключение
2025-07-05 14:55:47,546 ERROR   MainThread:36952 [redirect.py:_on_write():664] [all runs] error in stderr callback
Traceback (most recent call last):
  File "C:\Users\Alex\anaconda3\envs\fd_env\lib\site-packages\wandb\sdk\lib\redirect.py", line 662, in _on_write
    cb(written_data)
  File "C:\Users\Alex\anaconda3\envs\fd_env\lib\site-packages\wandb\sdk\wandb_run.py", line 2385, in <lambda>
    lambda data: self._console_raw_callback("stderr", data),
  File "C:\Users\Alex\anaconda3\envs\fd_env\lib\site-packages\wandb\sdk\wandb_run.py", line 398, in wrapper
    return func(self, *args, **kwargs)
  File "C:\Users\Alex\anaconda3\envs\fd_env\lib\site-packages\wandb\sdk\wandb_run.py", line 456, in wrapper_fn
    return func(self, *args, **kwargs)
  File "C:\Users\Alex\anaconda3\envs\fd_env\lib\site-packages\wandb\sdk\wandb_run.py", line 1566, in _console_raw_callback
    self._backend.interface.publish_output_raw(name, data)
  File "C:\Users\Alex\anaconda3\envs\fd_env\lib\site-packages\wandb\sdk\interface\interface.py", line 771, in publish_output_raw
    self._publish_output_raw(o)
  File "C:\Users\Alex\anaconda3\envs\fd_env\lib\site-packages\wandb\sdk\interface\interface_shared.py", line 38, in _publish_output_raw
    self._publish(rec)
  File "C:\Users\Alex\anaconda3\envs\fd_env\lib\site-packages\wandb\sdk\interface\interface_sock.py", line 39, in _publish
    self._sock_client.send_record_publish(record)
  File "C:\Users\Alex\anaconda3\envs\fd_env\lib\site-packages\wandb\sdk\lib\sock_client.py", line 170, in send_record_publish
    self.send_server_request(server_req)
  File "C:\Users\Alex\anaconda3\envs\fd_env\lib\site-packages\wandb\sdk\lib\sock_client.py", line 150, in send_server_request
    self._send_message(msg)
  File "C:\Users\Alex\anaconda3\envs\fd_env\lib\site-packages\wandb\sdk\lib\sock_client.py", line 147, in _send_message
    self._sendall_with_error_handle(header + data)
  File "C:\Users\Alex\anaconda3\envs\fd_env\lib\site-packages\wandb\sdk\lib\sock_client.py", line 126, in _sendall_with_error_handle
    sent = self._sock.send(data)
ConnectionResetError: [WinError 10054] Удаленный хост принудительно разорвал существующее подключение
2025-07-05 14:55:47,547 ERROR   MainThread:36952 [redirect.py:_on_write():664] [all runs] error in stderr callback
Traceback (most recent call last):
  File "C:\Users\Alex\anaconda3\envs\fd_env\lib\site-packages\wandb\sdk\lib\redirect.py", line 662, in _on_write
    cb(written_data)
  File "C:\Users\Alex\anaconda3\envs\fd_env\lib\site-packages\wandb\sdk\wandb_run.py", line 2385, in <lambda>
    lambda data: self._console_raw_callback("stderr", data),
  File "C:\Users\Alex\anaconda3\envs\fd_env\lib\site-packages\wandb\sdk\wandb_run.py", line 398, in wrapper
    return func(self, *args, **kwargs)
  File "C:\Users\Alex\anaconda3\envs\fd_env\lib\site-packages\wandb\sdk\wandb_run.py", line 456, in wrapper_fn
    return func(self, *args, **kwargs)
  File "C:\Users\Alex\anaconda3\envs\fd_env\lib\site-packages\wandb\sdk\wandb_run.py", line 1566, in _console_raw_callback
    self._backend.interface.publish_output_raw(name, data)
  File "C:\Users\Alex\anaconda3\envs\fd_env\lib\site-packages\wandb\sdk\interface\interface.py", line 771, in publish_output_raw
    self._publish_output_raw(o)
  File "C:\Users\Alex\anaconda3\envs\fd_env\lib\site-packages\wandb\sdk\interface\interface_shared.py", line 38, in _publish_output_raw
    self._publish(rec)
  File "C:\Users\Alex\anaconda3\envs\fd_env\lib\site-packages\wandb\sdk\interface\interface_sock.py", line 39, in _publish
    self._sock_client.send_record_publish(record)
  File "C:\Users\Alex\anaconda3\envs\fd_env\lib\site-packages\wandb\sdk\lib\sock_client.py", line 170, in send_record_publish
    self.send_server_request(server_req)
  File "C:\Users\Alex\anaconda3\envs\fd_env\lib\site-packages\wandb\sdk\lib\sock_client.py", line 150, in send_server_request
    self._send_message(msg)
  File "C:\Users\Alex\anaconda3\envs\fd_env\lib\site-packages\wandb\sdk\lib\sock_client.py", line 147, in _send_message
    self._sendall_with_error_handle(header + data)
  File "C:\Users\Alex\anaconda3\envs\fd_env\lib\site-packages\wandb\sdk\lib\sock_client.py", line 126, in _sendall_with_error_handle
    sent = self._sock.send(data)
ConnectionResetError: [WinError 10054] Удаленный хост принудительно разорвал существующее подключение
2025-07-05 14:55:47,549 ERROR   MainThread:36952 [redirect.py:_on_write():664] [all runs] error in stderr callback
Traceback (most recent call last):
  File "C:\Users\Alex\anaconda3\envs\fd_env\lib\site-packages\wandb\sdk\lib\redirect.py", line 662, in _on_write
    cb(written_data)
  File "C:\Users\Alex\anaconda3\envs\fd_env\lib\site-packages\wandb\sdk\wandb_run.py", line 2385, in <lambda>
    lambda data: self._console_raw_callback("stderr", data),
  File "C:\Users\Alex\anaconda3\envs\fd_env\lib\site-packages\wandb\sdk\wandb_run.py", line 398, in wrapper
    return func(self, *args, **kwargs)
  File "C:\Users\Alex\anaconda3\envs\fd_env\lib\site-packages\wandb\sdk\wandb_run.py", line 456, in wrapper_fn
    return func(self, *args, **kwargs)
  File "C:\Users\Alex\anaconda3\envs\fd_env\lib\site-packages\wandb\sdk\wandb_run.py", line 1566, in _console_raw_callback
    self._backend.interface.publish_output_raw(name, data)
  File "C:\Users\Alex\anaconda3\envs\fd_env\lib\site-packages\wandb\sdk\interface\interface.py", line 771, in publish_output_raw
    self._publish_output_raw(o)
  File "C:\Users\Alex\anaconda3\envs\fd_env\lib\site-packages\wandb\sdk\interface\interface_shared.py", line 38, in _publish_output_raw
    self._publish(rec)
  File "C:\Users\Alex\anaconda3\envs\fd_env\lib\site-packages\wandb\sdk\interface\interface_sock.py", line 39, in _publish
    self._sock_client.send_record_publish(record)
  File "C:\Users\Alex\anaconda3\envs\fd_env\lib\site-packages\wandb\sdk\lib\sock_client.py", line 170, in send_record_publish
    self.send_server_request(server_req)
  File "C:\Users\Alex\anaconda3\envs\fd_env\lib\site-packages\wandb\sdk\lib\sock_client.py", line 150, in send_server_request
    self._send_message(msg)
  File "C:\Users\Alex\anaconda3\envs\fd_env\lib\site-packages\wandb\sdk\lib\sock_client.py", line 147, in _send_message
    self._sendall_with_error_handle(header + data)
  File "C:\Users\Alex\anaconda3\envs\fd_env\lib\site-packages\wandb\sdk\lib\sock_client.py", line 126, in _sendall_with_error_handle
    sent = self._sock.send(data)
ConnectionResetError: [WinError 10054] Удаленный хост принудительно разорвал существующее подключение
2025-07-05 14:55:47,550 ERROR   MainThread:36952 [redirect.py:_on_write():664] [all runs] error in stderr callback
Traceback (most recent call last):
  File "C:\Users\Alex\anaconda3\envs\fd_env\lib\site-packages\wandb\sdk\lib\redirect.py", line 662, in _on_write
    cb(written_data)
  File "C:\Users\Alex\anaconda3\envs\fd_env\lib\site-packages\wandb\sdk\wandb_run.py", line 2385, in <lambda>
    lambda data: self._console_raw_callback("stderr", data),
  File "C:\Users\Alex\anaconda3\envs\fd_env\lib\site-packages\wandb\sdk\wandb_run.py", line 398, in wrapper
    return func(self, *args, **kwargs)
  File "C:\Users\Alex\anaconda3\envs\fd_env\lib\site-packages\wandb\sdk\wandb_run.py", line 456, in wrapper_fn
    return func(self, *args, **kwargs)
  File "C:\Users\Alex\anaconda3\envs\fd_env\lib\site-packages\wandb\sdk\wandb_run.py", line 1566, in _console_raw_callback
    self._backend.interface.publish_output_raw(name, data)
  File "C:\Users\Alex\anaconda3\envs\fd_env\lib\site-packages\wandb\sdk\interface\interface.py", line 771, in publish_output_raw
    self._publish_output_raw(o)
  File "C:\Users\Alex\anaconda3\envs\fd_env\lib\site-packages\wandb\sdk\interface\interface_shared.py", line 38, in _publish_output_raw
    self._publish(rec)
  File "C:\Users\Alex\anaconda3\envs\fd_env\lib\site-packages\wandb\sdk\interface\interface_sock.py", line 39, in _publish
    self._sock_client.send_record_publish(record)
  File "C:\Users\Alex\anaconda3\envs\fd_env\lib\site-packages\wandb\sdk\lib\sock_client.py", line 170, in send_record_publish
    self.send_server_request(server_req)
  File "C:\Users\Alex\anaconda3\envs\fd_env\lib\site-packages\wandb\sdk\lib\sock_client.py", line 150, in send_server_request
    self._send_message(msg)
  File "C:\Users\Alex\anaconda3\envs\fd_env\lib\site-packages\wandb\sdk\lib\sock_client.py", line 147, in _send_message
    self._sendall_with_error_handle(header + data)
  File "C:\Users\Alex\anaconda3\envs\fd_env\lib\site-packages\wandb\sdk\lib\sock_client.py", line 126, in _sendall_with_error_handle
    sent = self._sock.send(data)
ConnectionResetError: [WinError 10054] Удаленный хост принудительно разорвал существующее подключение
2025-07-05 14:55:47,551 ERROR   MainThread:36952 [redirect.py:_on_write():664] [all runs] error in stderr callback
Traceback (most recent call last):
  File "C:\Users\Alex\anaconda3\envs\fd_env\lib\site-packages\wandb\sdk\lib\redirect.py", line 662, in _on_write
    cb(written_data)
  File "C:\Users\Alex\anaconda3\envs\fd_env\lib\site-packages\wandb\sdk\wandb_run.py", line 2385, in <lambda>
    lambda data: self._console_raw_callback("stderr", data),
  File "C:\Users\Alex\anaconda3\envs\fd_env\lib\site-packages\wandb\sdk\wandb_run.py", line 398, in wrapper
    return func(self, *args, **kwargs)
  File "C:\Users\Alex\anaconda3\envs\fd_env\lib\site-packages\wandb\sdk\wandb_run.py", line 456, in wrapper_fn
    return func(self, *args, **kwargs)
  File "C:\Users\Alex\anaconda3\envs\fd_env\lib\site-packages\wandb\sdk\wandb_run.py", line 1566, in _console_raw_callback
    self._backend.interface.publish_output_raw(name, data)
  File "C:\Users\Alex\anaconda3\envs\fd_env\lib\site-packages\wandb\sdk\interface\interface.py", line 771, in publish_output_raw
    self._publish_output_raw(o)
  File "C:\Users\Alex\anaconda3\envs\fd_env\lib\site-packages\wandb\sdk\interface\interface_shared.py", line 38, in _publish_output_raw
    self._publish(rec)
  File "C:\Users\Alex\anaconda3\envs\fd_env\lib\site-packages\wandb\sdk\interface\interface_sock.py", line 39, in _publish
    self._sock_client.send_record_publish(record)
  File "C:\Users\Alex\anaconda3\envs\fd_env\lib\site-packages\wandb\sdk\lib\sock_client.py", line 170, in send_record_publish
    self.send_server_request(server_req)
  File "C:\Users\Alex\anaconda3\envs\fd_env\lib\site-packages\wandb\sdk\lib\sock_client.py", line 150, in send_server_request
    self._send_message(msg)
  File "C:\Users\Alex\anaconda3\envs\fd_env\lib\site-packages\wandb\sdk\lib\sock_client.py", line 147, in _send_message
    self._sendall_with_error_handle(header + data)
  File "C:\Users\Alex\anaconda3\envs\fd_env\lib\site-packages\wandb\sdk\lib\sock_client.py", line 126, in _sendall_with_error_handle
    sent = self._sock.send(data)
ConnectionResetError: [WinError 10054] Удаленный хост принудительно разорвал существующее подключение
2025-07-05 14:55:47,552 ERROR   MainThread:36952 [redirect.py:_on_write():664] [all runs] error in stderr callback
Traceback (most recent call last):
  File "C:\Users\Alex\anaconda3\envs\fd_env\lib\site-packages\wandb\sdk\lib\redirect.py", line 662, in _on_write
    cb(written_data)
  File "C:\Users\Alex\anaconda3\envs\fd_env\lib\site-packages\wandb\sdk\wandb_run.py", line 2385, in <lambda>
    lambda data: self._console_raw_callback("stderr", data),
  File "C:\Users\Alex\anaconda3\envs\fd_env\lib\site-packages\wandb\sdk\wandb_run.py", line 398, in wrapper
    return func(self, *args, **kwargs)
  File "C:\Users\Alex\anaconda3\envs\fd_env\lib\site-packages\wandb\sdk\wandb_run.py", line 456, in wrapper_fn
    return func(self, *args, **kwargs)
  File "C:\Users\Alex\anaconda3\envs\fd_env\lib\site-packages\wandb\sdk\wandb_run.py", line 1566, in _console_raw_callback
    self._backend.interface.publish_output_raw(name, data)
  File "C:\Users\Alex\anaconda3\envs\fd_env\lib\site-packages\wandb\sdk\interface\interface.py", line 771, in publish_output_raw
    self._publish_output_raw(o)
  File "C:\Users\Alex\anaconda3\envs\fd_env\lib\site-packages\wandb\sdk\interface\interface_shared.py", line 38, in _publish_output_raw
    self._publish(rec)
  File "C:\Users\Alex\anaconda3\envs\fd_env\lib\site-packages\wandb\sdk\interface\interface_sock.py", line 39, in _publish
    self._sock_client.send_record_publish(record)
  File "C:\Users\Alex\anaconda3\envs\fd_env\lib\site-packages\wandb\sdk\lib\sock_client.py", line 170, in send_record_publish
    self.send_server_request(server_req)
  File "C:\Users\Alex\anaconda3\envs\fd_env\lib\site-packages\wandb\sdk\lib\sock_client.py", line 150, in send_server_request
    self._send_message(msg)
  File "C:\Users\Alex\anaconda3\envs\fd_env\lib\site-packages\wandb\sdk\lib\sock_client.py", line 147, in _send_message
    self._sendall_with_error_handle(header + data)
  File "C:\Users\Alex\anaconda3\envs\fd_env\lib\site-packages\wandb\sdk\lib\sock_client.py", line 126, in _sendall_with_error_handle
    sent = self._sock.send(data)
ConnectionResetError: [WinError 10054] Удаленный хост принудительно разорвал существующее подключение
2025-07-05 14:55:47,553 ERROR   MainThread:36952 [redirect.py:_on_write():664] [all runs] error in stderr callback
Traceback (most recent call last):
  File "C:\Users\Alex\anaconda3\envs\fd_env\lib\site-packages\wandb\sdk\lib\redirect.py", line 662, in _on_write
    cb(written_data)
  File "C:\Users\Alex\anaconda3\envs\fd_env\lib\site-packages\wandb\sdk\wandb_run.py", line 2385, in <lambda>
    lambda data: self._console_raw_callback("stderr", data),
  File "C:\Users\Alex\anaconda3\envs\fd_env\lib\site-packages\wandb\sdk\wandb_run.py", line 398, in wrapper
    return func(self, *args, **kwargs)
  File "C:\Users\Alex\anaconda3\envs\fd_env\lib\site-packages\wandb\sdk\wandb_run.py", line 456, in wrapper_fn
    return func(self, *args, **kwargs)
  File "C:\Users\Alex\anaconda3\envs\fd_env\lib\site-packages\wandb\sdk\wandb_run.py", line 1566, in _console_raw_callback
    self._backend.interface.publish_output_raw(name, data)
  File "C:\Users\Alex\anaconda3\envs\fd_env\lib\site-packages\wandb\sdk\interface\interface.py", line 771, in publish_output_raw
    self._publish_output_raw(o)
  File "C:\Users\Alex\anaconda3\envs\fd_env\lib\site-packages\wandb\sdk\interface\interface_shared.py", line 38, in _publish_output_raw
    self._publish(rec)
  File "C:\Users\Alex\anaconda3\envs\fd_env\lib\site-packages\wandb\sdk\interface\interface_sock.py", line 39, in _publish
    self._sock_client.send_record_publish(record)
  File "C:\Users\Alex\anaconda3\envs\fd_env\lib\site-packages\wandb\sdk\lib\sock_client.py", line 170, in send_record_publish
    self.send_server_request(server_req)
  File "C:\Users\Alex\anaconda3\envs\fd_env\lib\site-packages\wandb\sdk\lib\sock_client.py", line 150, in send_server_request
    self._send_message(msg)
  File "C:\Users\Alex\anaconda3\envs\fd_env\lib\site-packages\wandb\sdk\lib\sock_client.py", line 147, in _send_message
    self._sendall_with_error_handle(header + data)
  File "C:\Users\Alex\anaconda3\envs\fd_env\lib\site-packages\wandb\sdk\lib\sock_client.py", line 126, in _sendall_with_error_handle
    sent = self._sock.send(data)
ConnectionResetError: [WinError 10054] Удаленный хост принудительно разорвал существующее подключение
2025-07-05 14:55:47,554 ERROR   MainThread:36952 [redirect.py:_on_write():664] [all runs] error in stderr callback
Traceback (most recent call last):
  File "C:\Users\Alex\anaconda3\envs\fd_env\lib\site-packages\wandb\sdk\lib\redirect.py", line 662, in _on_write
    cb(written_data)
  File "C:\Users\Alex\anaconda3\envs\fd_env\lib\site-packages\wandb\sdk\wandb_run.py", line 2385, in <lambda>
    lambda data: self._console_raw_callback("stderr", data),
  File "C:\Users\Alex\anaconda3\envs\fd_env\lib\site-packages\wandb\sdk\wandb_run.py", line 398, in wrapper
    return func(self, *args, **kwargs)
  File "C:\Users\Alex\anaconda3\envs\fd_env\lib\site-packages\wandb\sdk\wandb_run.py", line 456, in wrapper_fn
    return func(self, *args, **kwargs)
  File "C:\Users\Alex\anaconda3\envs\fd_env\lib\site-packages\wandb\sdk\wandb_run.py", line 1566, in _console_raw_callback
    self._backend.interface.publish_output_raw(name, data)
  File "C:\Users\Alex\anaconda3\envs\fd_env\lib\site-packages\wandb\sdk\interface\interface.py", line 771, in publish_output_raw
    self._publish_output_raw(o)
  File "C:\Users\Alex\anaconda3\envs\fd_env\lib\site-packages\wandb\sdk\interface\interface_shared.py", line 38, in _publish_output_raw
    self._publish(rec)
  File "C:\Users\Alex\anaconda3\envs\fd_env\lib\site-packages\wandb\sdk\interface\interface_sock.py", line 39, in _publish
    self._sock_client.send_record_publish(record)
  File "C:\Users\Alex\anaconda3\envs\fd_env\lib\site-packages\wandb\sdk\lib\sock_client.py", line 170, in send_record_publish
    self.send_server_request(server_req)
  File "C:\Users\Alex\anaconda3\envs\fd_env\lib\site-packages\wandb\sdk\lib\sock_client.py", line 150, in send_server_request
    self._send_message(msg)
  File "C:\Users\Alex\anaconda3\envs\fd_env\lib\site-packages\wandb\sdk\lib\sock_client.py", line 147, in _send_message
    self._sendall_with_error_handle(header + data)
  File "C:\Users\Alex\anaconda3\envs\fd_env\lib\site-packages\wandb\sdk\lib\sock_client.py", line 126, in _sendall_with_error_handle
    sent = self._sock.send(data)
ConnectionResetError: [WinError 10054] Удаленный хост принудительно разорвал существующее подключение
2025-07-05 14:55:47,554 ERROR   MainThread:36952 [redirect.py:_on_write():664] [all runs] error in stderr callback
Traceback (most recent call last):
  File "C:\Users\Alex\anaconda3\envs\fd_env\lib\site-packages\wandb\sdk\lib\redirect.py", line 662, in _on_write
    cb(written_data)
  File "C:\Users\Alex\anaconda3\envs\fd_env\lib\site-packages\wandb\sdk\wandb_run.py", line 2385, in <lambda>
    lambda data: self._console_raw_callback("stderr", data),
  File "C:\Users\Alex\anaconda3\envs\fd_env\lib\site-packages\wandb\sdk\wandb_run.py", line 398, in wrapper
    return func(self, *args, **kwargs)
  File "C:\Users\Alex\anaconda3\envs\fd_env\lib\site-packages\wandb\sdk\wandb_run.py", line 456, in wrapper_fn
    return func(self, *args, **kwargs)
  File "C:\Users\Alex\anaconda3\envs\fd_env\lib\site-packages\wandb\sdk\wandb_run.py", line 1566, in _console_raw_callback
    self._backend.interface.publish_output_raw(name, data)
  File "C:\Users\Alex\anaconda3\envs\fd_env\lib\site-packages\wandb\sdk\interface\interface.py", line 771, in publish_output_raw
    self._publish_output_raw(o)
  File "C:\Users\Alex\anaconda3\envs\fd_env\lib\site-packages\wandb\sdk\interface\interface_shared.py", line 38, in _publish_output_raw
    self._publish(rec)
  File "C:\Users\Alex\anaconda3\envs\fd_env\lib\site-packages\wandb\sdk\interface\interface_sock.py", line 39, in _publish
    self._sock_client.send_record_publish(record)
  File "C:\Users\Alex\anaconda3\envs\fd_env\lib\site-packages\wandb\sdk\lib\sock_client.py", line 170, in send_record_publish
    self.send_server_request(server_req)
  File "C:\Users\Alex\anaconda3\envs\fd_env\lib\site-packages\wandb\sdk\lib\sock_client.py", line 150, in send_server_request
    self._send_message(msg)
  File "C:\Users\Alex\anaconda3\envs\fd_env\lib\site-packages\wandb\sdk\lib\sock_client.py", line 147, in _send_message
    self._sendall_with_error_handle(header + data)
  File "C:\Users\Alex\anaconda3\envs\fd_env\lib\site-packages\wandb\sdk\lib\sock_client.py", line 126, in _sendall_with_error_handle
    sent = self._sock.send(data)
ConnectionResetError: [WinError 10054] Удаленный хост принудительно разорвал существующее подключение
2025-07-05 14:55:47,555 ERROR   MainThread:36952 [redirect.py:_on_write():664] [all runs] error in stderr callback
Traceback (most recent call last):
  File "C:\Users\Alex\anaconda3\envs\fd_env\lib\site-packages\wandb\sdk\lib\redirect.py", line 662, in _on_write
    cb(written_data)
  File "C:\Users\Alex\anaconda3\envs\fd_env\lib\site-packages\wandb\sdk\wandb_run.py", line 2385, in <lambda>
    lambda data: self._console_raw_callback("stderr", data),
  File "C:\Users\Alex\anaconda3\envs\fd_env\lib\site-packages\wandb\sdk\wandb_run.py", line 398, in wrapper
    return func(self, *args, **kwargs)
  File "C:\Users\Alex\anaconda3\envs\fd_env\lib\site-packages\wandb\sdk\wandb_run.py", line 456, in wrapper_fn
    return func(self, *args, **kwargs)
  File "C:\Users\Alex\anaconda3\envs\fd_env\lib\site-packages\wandb\sdk\wandb_run.py", line 1566, in _console_raw_callback
    self._backend.interface.publish_output_raw(name, data)
  File "C:\Users\Alex\anaconda3\envs\fd_env\lib\site-packages\wandb\sdk\interface\interface.py", line 771, in publish_output_raw
    self._publish_output_raw(o)
  File "C:\Users\Alex\anaconda3\envs\fd_env\lib\site-packages\wandb\sdk\interface\interface_shared.py", line 38, in _publish_output_raw
    self._publish(rec)
  File "C:\Users\Alex\anaconda3\envs\fd_env\lib\site-packages\wandb\sdk\interface\interface_sock.py", line 39, in _publish
    self._sock_client.send_record_publish(record)
  File "C:\Users\Alex\anaconda3\envs\fd_env\lib\site-packages\wandb\sdk\lib\sock_client.py", line 170, in send_record_publish
    self.send_server_request(server_req)
  File "C:\Users\Alex\anaconda3\envs\fd_env\lib\site-packages\wandb\sdk\lib\sock_client.py", line 150, in send_server_request
    self._send_message(msg)
  File "C:\Users\Alex\anaconda3\envs\fd_env\lib\site-packages\wandb\sdk\lib\sock_client.py", line 147, in _send_message
    self._sendall_with_error_handle(header + data)
  File "C:\Users\Alex\anaconda3\envs\fd_env\lib\site-packages\wandb\sdk\lib\sock_client.py", line 126, in _sendall_with_error_handle
    sent = self._sock.send(data)
ConnectionResetError: [WinError 10054] Удаленный хост принудительно разорвал существующее подключение
2025-07-05 14:55:47,555 ERROR   MainThread:36952 [redirect.py:_on_write():664] [all runs] error in stderr callback
Traceback (most recent call last):
  File "C:\Users\Alex\anaconda3\envs\fd_env\lib\site-packages\wandb\sdk\lib\redirect.py", line 662, in _on_write
    cb(written_data)
  File "C:\Users\Alex\anaconda3\envs\fd_env\lib\site-packages\wandb\sdk\wandb_run.py", line 2385, in <lambda>
    lambda data: self._console_raw_callback("stderr", data),
  File "C:\Users\Alex\anaconda3\envs\fd_env\lib\site-packages\wandb\sdk\wandb_run.py", line 398, in wrapper
    return func(self, *args, **kwargs)
  File "C:\Users\Alex\anaconda3\envs\fd_env\lib\site-packages\wandb\sdk\wandb_run.py", line 456, in wrapper_fn
    return func(self, *args, **kwargs)
  File "C:\Users\Alex\anaconda3\envs\fd_env\lib\site-packages\wandb\sdk\wandb_run.py", line 1566, in _console_raw_callback
    self._backend.interface.publish_output_raw(name, data)
  File "C:\Users\Alex\anaconda3\envs\fd_env\lib\site-packages\wandb\sdk\interface\interface.py", line 771, in publish_output_raw
    self._publish_output_raw(o)
  File "C:\Users\Alex\anaconda3\envs\fd_env\lib\site-packages\wandb\sdk\interface\interface_shared.py", line 38, in _publish_output_raw
    self._publish(rec)
  File "C:\Users\Alex\anaconda3\envs\fd_env\lib\site-packages\wandb\sdk\interface\interface_sock.py", line 39, in _publish
    self._sock_client.send_record_publish(record)
  File "C:\Users\Alex\anaconda3\envs\fd_env\lib\site-packages\wandb\sdk\lib\sock_client.py", line 170, in send_record_publish
    self.send_server_request(server_req)
  File "C:\Users\Alex\anaconda3\envs\fd_env\lib\site-packages\wandb\sdk\lib\sock_client.py", line 150, in send_server_request
    self._send_message(msg)
  File "C:\Users\Alex\anaconda3\envs\fd_env\lib\site-packages\wandb\sdk\lib\sock_client.py", line 147, in _send_message
    self._sendall_with_error_handle(header + data)
  File "C:\Users\Alex\anaconda3\envs\fd_env\lib\site-packages\wandb\sdk\lib\sock_client.py", line 126, in _sendall_with_error_handle
    sent = self._sock.send(data)
ConnectionResetError: [WinError 10054] Удаленный хост принудительно разорвал существующее подключение
2025-07-05 14:55:47,556 ERROR   MainThread:36952 [redirect.py:_on_write():664] [all runs] error in stderr callback
Traceback (most recent call last):
  File "C:\Users\Alex\anaconda3\envs\fd_env\lib\site-packages\wandb\sdk\lib\redirect.py", line 662, in _on_write
    cb(written_data)
  File "C:\Users\Alex\anaconda3\envs\fd_env\lib\site-packages\wandb\sdk\wandb_run.py", line 2385, in <lambda>
    lambda data: self._console_raw_callback("stderr", data),
  File "C:\Users\Alex\anaconda3\envs\fd_env\lib\site-packages\wandb\sdk\wandb_run.py", line 398, in wrapper
    return func(self, *args, **kwargs)
  File "C:\Users\Alex\anaconda3\envs\fd_env\lib\site-packages\wandb\sdk\wandb_run.py", line 456, in wrapper_fn
    return func(self, *args, **kwargs)
  File "C:\Users\Alex\anaconda3\envs\fd_env\lib\site-packages\wandb\sdk\wandb_run.py", line 1566, in _console_raw_callback
    self._backend.interface.publish_output_raw(name, data)
  File "C:\Users\Alex\anaconda3\envs\fd_env\lib\site-packages\wandb\sdk\interface\interface.py", line 771, in publish_output_raw
    self._publish_output_raw(o)
  File "C:\Users\Alex\anaconda3\envs\fd_env\lib\site-packages\wandb\sdk\interface\interface_shared.py", line 38, in _publish_output_raw
    self._publish(rec)
  File "C:\Users\Alex\anaconda3\envs\fd_env\lib\site-packages\wandb\sdk\interface\interface_sock.py", line 39, in _publish
    self._sock_client.send_record_publish(record)
  File "C:\Users\Alex\anaconda3\envs\fd_env\lib\site-packages\wandb\sdk\lib\sock_client.py", line 170, in send_record_publish
    self.send_server_request(server_req)
  File "C:\Users\Alex\anaconda3\envs\fd_env\lib\site-packages\wandb\sdk\lib\sock_client.py", line 150, in send_server_request
    self._send_message(msg)
  File "C:\Users\Alex\anaconda3\envs\fd_env\lib\site-packages\wandb\sdk\lib\sock_client.py", line 147, in _send_message
    self._sendall_with_error_handle(header + data)
  File "C:\Users\Alex\anaconda3\envs\fd_env\lib\site-packages\wandb\sdk\lib\sock_client.py", line 126, in _sendall_with_error_handle
    sent = self._sock.send(data)
ConnectionResetError: [WinError 10054] Удаленный хост принудительно разорвал существующее подключение
2025-07-05 14:55:47,558 ERROR   MainThread:36952 [redirect.py:_on_write():664] [all runs] error in stderr callback
Traceback (most recent call last):
  File "C:\Users\Alex\anaconda3\envs\fd_env\lib\site-packages\wandb\sdk\lib\redirect.py", line 662, in _on_write
    cb(written_data)
  File "C:\Users\Alex\anaconda3\envs\fd_env\lib\site-packages\wandb\sdk\wandb_run.py", line 2385, in <lambda>
    lambda data: self._console_raw_callback("stderr", data),
  File "C:\Users\Alex\anaconda3\envs\fd_env\lib\site-packages\wandb\sdk\wandb_run.py", line 398, in wrapper
    return func(self, *args, **kwargs)
  File "C:\Users\Alex\anaconda3\envs\fd_env\lib\site-packages\wandb\sdk\wandb_run.py", line 456, in wrapper_fn
    return func(self, *args, **kwargs)
  File "C:\Users\Alex\anaconda3\envs\fd_env\lib\site-packages\wandb\sdk\wandb_run.py", line 1566, in _console_raw_callback
    self._backend.interface.publish_output_raw(name, data)
  File "C:\Users\Alex\anaconda3\envs\fd_env\lib\site-packages\wandb\sdk\interface\interface.py", line 771, in publish_output_raw
    self._publish_output_raw(o)
  File "C:\Users\Alex\anaconda3\envs\fd_env\lib\site-packages\wandb\sdk\interface\interface_shared.py", line 38, in _publish_output_raw
    self._publish(rec)
  File "C:\Users\Alex\anaconda3\envs\fd_env\lib\site-packages\wandb\sdk\interface\interface_sock.py", line 39, in _publish
    self._sock_client.send_record_publish(record)
  File "C:\Users\Alex\anaconda3\envs\fd_env\lib\site-packages\wandb\sdk\lib\sock_client.py", line 170, in send_record_publish
    self.send_server_request(server_req)
  File "C:\Users\Alex\anaconda3\envs\fd_env\lib\site-packages\wandb\sdk\lib\sock_client.py", line 150, in send_server_request
    self._send_message(msg)
  File "C:\Users\Alex\anaconda3\envs\fd_env\lib\site-packages\wandb\sdk\lib\sock_client.py", line 147, in _send_message
    self._sendall_with_error_handle(header + data)
  File "C:\Users\Alex\anaconda3\envs\fd_env\lib\site-packages\wandb\sdk\lib\sock_client.py", line 126, in _sendall_with_error_handle
    sent = self._sock.send(data)
ConnectionResetError: [WinError 10054] Удаленный хост принудительно разорвал существующее подключение
2025-07-05 14:55:47,887 ERROR   MainThread:36952 [redirect.py:_on_write():664] [all runs] error in stdout callback
Traceback (most recent call last):
  File "C:\Users\Alex\anaconda3\envs\fd_env\lib\site-packages\wandb\sdk\lib\redirect.py", line 662, in _on_write
    cb(written_data)
  File "C:\Users\Alex\anaconda3\envs\fd_env\lib\site-packages\wandb\sdk\wandb_run.py", line 2379, in <lambda>
    lambda data: self._console_raw_callback("stdout", data),
  File "C:\Users\Alex\anaconda3\envs\fd_env\lib\site-packages\wandb\sdk\wandb_run.py", line 398, in wrapper
    return func(self, *args, **kwargs)
  File "C:\Users\Alex\anaconda3\envs\fd_env\lib\site-packages\wandb\sdk\wandb_run.py", line 456, in wrapper_fn
    return func(self, *args, **kwargs)
  File "C:\Users\Alex\anaconda3\envs\fd_env\lib\site-packages\wandb\sdk\wandb_run.py", line 1566, in _console_raw_callback
    self._backend.interface.publish_output_raw(name, data)
  File "C:\Users\Alex\anaconda3\envs\fd_env\lib\site-packages\wandb\sdk\interface\interface.py", line 771, in publish_output_raw
    self._publish_output_raw(o)
  File "C:\Users\Alex\anaconda3\envs\fd_env\lib\site-packages\wandb\sdk\interface\interface_shared.py", line 38, in _publish_output_raw
    self._publish(rec)
  File "C:\Users\Alex\anaconda3\envs\fd_env\lib\site-packages\wandb\sdk\interface\interface_sock.py", line 39, in _publish
    self._sock_client.send_record_publish(record)
  File "C:\Users\Alex\anaconda3\envs\fd_env\lib\site-packages\wandb\sdk\lib\sock_client.py", line 170, in send_record_publish
    self.send_server_request(server_req)
  File "C:\Users\Alex\anaconda3\envs\fd_env\lib\site-packages\wandb\sdk\lib\sock_client.py", line 150, in send_server_request
    self._send_message(msg)
  File "C:\Users\Alex\anaconda3\envs\fd_env\lib\site-packages\wandb\sdk\lib\sock_client.py", line 147, in _send_message
    self._sendall_with_error_handle(header + data)
  File "C:\Users\Alex\anaconda3\envs\fd_env\lib\site-packages\wandb\sdk\lib\sock_client.py", line 126, in _sendall_with_error_handle
    sent = self._sock.send(data)
ConnectionResetError: [WinError 10054] Удаленный хост принудительно разорвал существующее подключение
